/scratch/cnt0024/hmg2840/albert7a/anaconda3/lib/python3.7/site-packages/dask/config.py:168: YAMLLoadWarning: calling yaml.load() without Loader=... is deprecated, as the default Loader is unsafe. Please read https://msg.pyyaml.org/load for full details.
  data = yaml.load(f.read()) or {}
/scratch/cnt0024/hmg2840/albert7a/anaconda3/lib/python3.7/site-packages/distributed/utils.py:136: RuntimeWarning: Couldn't detect a suitable IP address for reaching '8.8.8.8', defaulting to '127.0.0.1': [Errno 101] Network is unreachable
  RuntimeWarning,
distributed.nanny - INFO -         Start Nanny at: 'tcp://172.30.6.161:33479'
distributed.nanny - INFO -         Start Nanny at: 'tcp://172.30.6.161:34269'
distributed.nanny - INFO -         Start Nanny at: 'tcp://172.30.6.161:35116'
distributed.nanny - INFO -         Start Nanny at: 'tcp://172.30.6.161:45583'
distributed.nanny - INFO -         Start Nanny at: 'tcp://172.30.6.161:43509'
distributed.nanny - INFO -         Start Nanny at: 'tcp://172.30.6.161:40222'
distributed.nanny - INFO -         Start Nanny at: 'tcp://172.30.6.161:34452'
distributed.nanny - INFO -         Start Nanny at: 'tcp://172.30.6.161:34724'
distributed.nanny - INFO -         Start Nanny at: 'tcp://172.30.6.161:36736'
distributed.nanny - INFO -         Start Nanny at: 'tcp://172.30.6.161:46498'
distributed.nanny - INFO -         Start Nanny at: 'tcp://172.30.6.161:36084'
distributed.nanny - INFO -         Start Nanny at: 'tcp://172.30.6.161:46241'
distributed.nanny - INFO -         Start Nanny at: 'tcp://172.30.6.161:39858'
distributed.nanny - INFO -         Start Nanny at: 'tcp://172.30.6.161:46060'
distributed.nanny - INFO -         Start Nanny at: 'tcp://172.30.6.161:37110'
distributed.nanny - INFO -         Start Nanny at: 'tcp://172.30.6.161:33209'
distributed.nanny - INFO -         Start Nanny at: 'tcp://172.30.6.161:38443'
distributed.nanny - INFO -         Start Nanny at: 'tcp://172.30.6.161:36431'
distributed.nanny - INFO -         Start Nanny at: 'tcp://172.30.6.161:42262'
distributed.nanny - INFO -         Start Nanny at: 'tcp://172.30.6.161:43513'
distributed.nanny - INFO -         Start Nanny at: 'tcp://172.30.6.161:44605'
distributed.nanny - INFO -         Start Nanny at: 'tcp://172.30.6.161:34750'
distributed.nanny - INFO -         Start Nanny at: 'tcp://172.30.6.161:37750'
distributed.nanny - INFO -         Start Nanny at: 'tcp://172.30.6.161:37836'
distributed.nanny - INFO -         Start Nanny at: 'tcp://172.30.6.161:35340'
distributed.nanny - INFO -         Start Nanny at: 'tcp://172.30.6.161:36365'
distributed.nanny - INFO -         Start Nanny at: 'tcp://172.30.6.161:41607'
distributed.nanny - INFO -         Start Nanny at: 'tcp://172.30.6.161:40182'
/scratch/cnt0024/hmg2840/albert7a/anaconda3/lib/python3.7/site-packages/dask/config.py:168: YAMLLoadWarning: calling yaml.load() without Loader=... is deprecated, as the default Loader is unsafe. Please read https://msg.pyyaml.org/load for full details.
  data = yaml.load(f.read()) or {}
/scratch/cnt0024/hmg2840/albert7a/anaconda3/lib/python3.7/site-packages/distributed/utils.py:136: RuntimeWarning: Couldn't detect a suitable IP address for reaching '8.8.8.8', defaulting to '127.0.0.1': [Errno 101] Network is unreachable
  RuntimeWarning,
distributed.worker - INFO -       Start worker at:   tcp://172.30.6.161:39291
distributed.worker - INFO -          Listening to:   tcp://172.30.6.161:39291
/scratch/cnt0024/hmg2840/albert7a/anaconda3/lib/python3.7/site-packages/dask/config.py:168: YAMLLoadWarning: calling yaml.load() without Loader=... is deprecated, as the default Loader is unsafe. Please read https://msg.pyyaml.org/load for full details.
  data = yaml.load(f.read()) or {}
/scratch/cnt0024/hmg2840/albert7a/anaconda3/lib/python3.7/site-packages/distributed/utils.py:136: RuntimeWarning: Couldn't detect a suitable IP address for reaching '8.8.8.8', defaulting to '127.0.0.1': [Errno 101] Network is unreachable
  RuntimeWarning,
distributed.worker - INFO -       Start worker at:   tcp://172.30.6.161:44269
distributed.worker - INFO -              nanny at:         172.30.6.161:46060
distributed.worker - INFO -              bokeh at:         172.30.6.161:34530
distributed.worker - INFO -          Listening to:   tcp://172.30.6.161:44269
/scratch/cnt0024/hmg2840/albert7a/anaconda3/lib/python3.7/site-packages/dask/config.py:168: YAMLLoadWarning: calling yaml.load() without Loader=... is deprecated, as the default Loader is unsafe. Please read https://msg.pyyaml.org/load for full details.
  data = yaml.load(f.read()) or {}
/scratch/cnt0024/hmg2840/albert7a/anaconda3/lib/python3.7/site-packages/distributed/utils.py:136: RuntimeWarning: Couldn't detect a suitable IP address for reaching '8.8.8.8', defaulting to '127.0.0.1': [Errno 101] Network is unreachable
  RuntimeWarning,
distributed.worker - INFO -       Start worker at:   tcp://172.30.6.161:41028
/scratch/cnt0024/hmg2840/albert7a/anaconda3/lib/python3.7/site-packages/dask/config.py:168: YAMLLoadWarning: calling yaml.load() without Loader=... is deprecated, as the default Loader is unsafe. Please read https://msg.pyyaml.org/load for full details.
  data = yaml.load(f.read()) or {}
/scratch/cnt0024/hmg2840/albert7a/anaconda3/lib/python3.7/site-packages/distributed/utils.py:136: RuntimeWarning: Couldn't detect a suitable IP address for reaching '8.8.8.8', defaulting to '127.0.0.1': [Errno 101] Network is unreachable
  RuntimeWarning,
distributed.worker - INFO -       Start worker at:   tcp://172.30.6.161:39987
distributed.worker - INFO - Waiting to connect to:   tcp://172.30.100.1:39168
distributed.worker - INFO - -------------------------------------------------
distributed.worker - INFO -              nanny at:         172.30.6.161:37110
distributed.worker - INFO -          Listening to:   tcp://172.30.6.161:41028
distributed.worker - INFO -              nanny at:         172.30.6.161:33209
distributed.worker - INFO -              bokeh at:         172.30.6.161:43693
distributed.worker - INFO -               Threads:                          1
distributed.worker - INFO -          Listening to:   tcp://172.30.6.161:39987
distributed.worker - INFO - Waiting to connect to:   tcp://172.30.100.1:39168
distributed.worker - INFO -                Memory:                    4.29 GB
distributed.worker - INFO -              nanny at:         172.30.6.161:40222
distributed.worker - INFO - -------------------------------------------------
distributed.worker - INFO -       Local Directory: /scratch/cnt0024/hmg2840/albert7a/daskjobqueue/worker-7e6g4ipb
distributed.worker - INFO -              bokeh at:         172.30.6.161:46680
distributed.worker - INFO - -------------------------------------------------
distributed.worker - INFO -              bokeh at:         172.30.6.161:38156
distributed.worker - INFO - Waiting to connect to:   tcp://172.30.100.1:39168
distributed.worker - INFO - Waiting to connect to:   tcp://172.30.100.1:39168
distributed.worker - INFO - -------------------------------------------------
distributed.worker - INFO - -------------------------------------------------
distributed.worker - INFO -               Threads:                          1
distributed.worker - INFO -               Threads:                          1
distributed.worker - INFO -               Threads:                          1
distributed.worker - INFO -                Memory:                    4.29 GB
distributed.worker - INFO -                Memory:                    4.29 GB
distributed.worker - INFO -                Memory:                    4.29 GB
distributed.worker - INFO -       Local Directory: /scratch/cnt0024/hmg2840/albert7a/daskjobqueue/worker-fb0_29ai
distributed.worker - INFO -       Local Directory: /scratch/cnt0024/hmg2840/albert7a/daskjobqueue/worker-es2th_d2
distributed.worker - INFO -       Local Directory: /scratch/cnt0024/hmg2840/albert7a/daskjobqueue/worker-fcute4h6
distributed.worker - INFO - -------------------------------------------------
distributed.worker - INFO - -------------------------------------------------
distributed.worker - INFO - -------------------------------------------------
/scratch/cnt0024/hmg2840/albert7a/anaconda3/lib/python3.7/site-packages/dask/config.py:168: YAMLLoadWarning: calling yaml.load() without Loader=... is deprecated, as the default Loader is unsafe. Please read https://msg.pyyaml.org/load for full details.
  data = yaml.load(f.read()) or {}
/scratch/cnt0024/hmg2840/albert7a/anaconda3/lib/python3.7/site-packages/distributed/utils.py:136: RuntimeWarning: Couldn't detect a suitable IP address for reaching '8.8.8.8', defaulting to '127.0.0.1': [Errno 101] Network is unreachable
  RuntimeWarning,
distributed.worker - INFO -       Start worker at:   tcp://172.30.6.161:38258
distributed.worker - INFO -          Listening to:   tcp://172.30.6.161:38258
distributed.worker - INFO -              nanny at:         172.30.6.161:35116
distributed.worker - INFO -              bokeh at:         172.30.6.161:45939
distributed.worker - INFO - Waiting to connect to:   tcp://172.30.100.1:39168
distributed.worker - INFO - -------------------------------------------------
distributed.worker - INFO -               Threads:                          1
distributed.worker - INFO -                Memory:                    4.29 GB
distributed.worker - INFO -       Local Directory: /scratch/cnt0024/hmg2840/albert7a/daskjobqueue/worker-d7wznqnr
distributed.worker - INFO - -------------------------------------------------
/scratch/cnt0024/hmg2840/albert7a/anaconda3/lib/python3.7/site-packages/dask/config.py:168: YAMLLoadWarning: calling yaml.load() without Loader=... is deprecated, as the default Loader is unsafe. Please read https://msg.pyyaml.org/load for full details.
  data = yaml.load(f.read()) or {}
/scratch/cnt0024/hmg2840/albert7a/anaconda3/lib/python3.7/site-packages/distributed/utils.py:136: RuntimeWarning: Couldn't detect a suitable IP address for reaching '8.8.8.8', defaulting to '127.0.0.1': [Errno 101] Network is unreachable
  RuntimeWarning,
distributed.worker - INFO -       Start worker at:   tcp://172.30.6.161:34478
distributed.worker - INFO -          Listening to:   tcp://172.30.6.161:34478
distributed.worker - INFO -              nanny at:         172.30.6.161:35340
distributed.worker - INFO -              bokeh at:         172.30.6.161:35818
distributed.worker - INFO - Waiting to connect to:   tcp://172.30.100.1:39168
distributed.worker - INFO - -------------------------------------------------
distributed.worker - INFO -               Threads:                          1
distributed.worker - INFO -                Memory:                    4.29 GB
distributed.worker - INFO -       Local Directory: /scratch/cnt0024/hmg2840/albert7a/daskjobqueue/worker-0ws0w6ps
distributed.worker - INFO - -------------------------------------------------
/scratch/cnt0024/hmg2840/albert7a/anaconda3/lib/python3.7/site-packages/dask/config.py:168: YAMLLoadWarning: calling yaml.load() without Loader=... is deprecated, as the default Loader is unsafe. Please read https://msg.pyyaml.org/load for full details.
  data = yaml.load(f.read()) or {}
/scratch/cnt0024/hmg2840/albert7a/anaconda3/lib/python3.7/site-packages/distributed/utils.py:136: RuntimeWarning: Couldn't detect a suitable IP address for reaching '8.8.8.8', defaulting to '127.0.0.1': [Errno 101] Network is unreachable
  RuntimeWarning,
distributed.worker - INFO -       Start worker at:   tcp://172.30.6.161:33642
distributed.worker - INFO -          Listening to:   tcp://172.30.6.161:33642
distributed.worker - INFO -              nanny at:         172.30.6.161:41607
distributed.worker - INFO -              bokeh at:         172.30.6.161:37250
distributed.worker - INFO - Waiting to connect to:   tcp://172.30.100.1:39168
distributed.worker - INFO - -------------------------------------------------
distributed.worker - INFO -               Threads:                          1
distributed.worker - INFO -                Memory:                    4.29 GB
distributed.worker - INFO -       Local Directory: /scratch/cnt0024/hmg2840/albert7a/daskjobqueue/worker-nl1iwztc
distributed.worker - INFO - -------------------------------------------------
/scratch/cnt0024/hmg2840/albert7a/anaconda3/lib/python3.7/site-packages/dask/config.py:168: YAMLLoadWarning: calling yaml.load() without Loader=... is deprecated, as the default Loader is unsafe. Please read https://msg.pyyaml.org/load for full details.
  data = yaml.load(f.read()) or {}
/scratch/cnt0024/hmg2840/albert7a/anaconda3/lib/python3.7/site-packages/distributed/utils.py:136: RuntimeWarning: Couldn't detect a suitable IP address for reaching '8.8.8.8', defaulting to '127.0.0.1': [Errno 101] Network is unreachable
  RuntimeWarning,
distributed.worker - INFO -       Start worker at:   tcp://172.30.6.161:44589
distributed.worker - INFO -          Listening to:   tcp://172.30.6.161:44589
distributed.worker - INFO -              nanny at:         172.30.6.161:45583
distributed.worker - INFO -              bokeh at:         172.30.6.161:33588
/scratch/cnt0024/hmg2840/albert7a/anaconda3/lib/python3.7/site-packages/dask/config.py:168: YAMLLoadWarning: calling yaml.load() without Loader=... is deprecated, as the default Loader is unsafe. Please read https://msg.pyyaml.org/load for full details.
  data = yaml.load(f.read()) or {}
/scratch/cnt0024/hmg2840/albert7a/anaconda3/lib/python3.7/site-packages/distributed/utils.py:136: RuntimeWarning: Couldn't detect a suitable IP address for reaching '8.8.8.8', defaulting to '127.0.0.1': [Errno 101] Network is unreachable
  RuntimeWarning,
distributed.worker - INFO -       Start worker at:   tcp://172.30.6.161:35869
distributed.worker - INFO - Waiting to connect to:   tcp://172.30.100.1:39168
distributed.worker - INFO -          Listening to:   tcp://172.30.6.161:35869
distributed.worker - INFO - -------------------------------------------------
distributed.worker - INFO -              nanny at:         172.30.6.161:36736
distributed.worker - INFO -              bokeh at:         172.30.6.161:37951
distributed.worker - INFO -               Threads:                          1
distributed.worker - INFO - Waiting to connect to:   tcp://172.30.100.1:39168
distributed.worker - INFO - -------------------------------------------------
distributed.worker - INFO -                Memory:                    4.29 GB
distributed.worker - INFO -       Local Directory: /scratch/cnt0024/hmg2840/albert7a/daskjobqueue/worker-vyhphmtp
distributed.worker - INFO -               Threads:                          1
distributed.worker - INFO -                Memory:                    4.29 GB
distributed.worker - INFO - -------------------------------------------------
distributed.worker - INFO -       Local Directory: /scratch/cnt0024/hmg2840/albert7a/daskjobqueue/worker-sg0f7jz9
distributed.worker - INFO - -------------------------------------------------
/scratch/cnt0024/hmg2840/albert7a/anaconda3/lib/python3.7/site-packages/dask/config.py:168: YAMLLoadWarning: calling yaml.load() without Loader=... is deprecated, as the default Loader is unsafe. Please read https://msg.pyyaml.org/load for full details.
  data = yaml.load(f.read()) or {}
/scratch/cnt0024/hmg2840/albert7a/anaconda3/lib/python3.7/site-packages/distributed/utils.py:136: RuntimeWarning: Couldn't detect a suitable IP address for reaching '8.8.8.8', defaulting to '127.0.0.1': [Errno 101] Network is unreachable
  RuntimeWarning,
distributed.worker - INFO -       Start worker at:   tcp://172.30.6.161:42037
distributed.worker - INFO -          Listening to:   tcp://172.30.6.161:42037
distributed.worker - INFO -              nanny at:         172.30.6.161:43513
distributed.worker - INFO -              bokeh at:         172.30.6.161:43570
distributed.worker - INFO - Waiting to connect to:   tcp://172.30.100.1:39168
distributed.worker - INFO - -------------------------------------------------
/scratch/cnt0024/hmg2840/albert7a/anaconda3/lib/python3.7/site-packages/dask/config.py:168: YAMLLoadWarning: calling yaml.load() without Loader=... is deprecated, as the default Loader is unsafe. Please read https://msg.pyyaml.org/load for full details.
  data = yaml.load(f.read()) or {}
/scratch/cnt0024/hmg2840/albert7a/anaconda3/lib/python3.7/site-packages/distributed/utils.py:136: RuntimeWarning: Couldn't detect a suitable IP address for reaching '8.8.8.8', defaulting to '127.0.0.1': [Errno 101] Network is unreachable
  RuntimeWarning,
distributed.worker - INFO -       Start worker at:   tcp://172.30.6.161:45426
distributed.worker - INFO -               Threads:                          1
distributed.worker - INFO -          Listening to:   tcp://172.30.6.161:45426
distributed.worker - INFO -                Memory:                    4.29 GB
distributed.worker - INFO -              nanny at:         172.30.6.161:33479
distributed.worker - INFO -       Local Directory: /scratch/cnt0024/hmg2840/albert7a/daskjobqueue/worker-jkd29ib8
distributed.worker - INFO -              bokeh at:         172.30.6.161:35002
distributed.worker - INFO - -------------------------------------------------
distributed.worker - INFO - Waiting to connect to:   tcp://172.30.100.1:39168
distributed.worker - INFO - -------------------------------------------------
distributed.worker - INFO -               Threads:                          1
distributed.worker - INFO -                Memory:                    4.29 GB
distributed.worker - INFO -       Local Directory: /scratch/cnt0024/hmg2840/albert7a/daskjobqueue/worker-mip0txw0
distributed.worker - INFO - -------------------------------------------------
/scratch/cnt0024/hmg2840/albert7a/anaconda3/lib/python3.7/site-packages/dask/config.py:168: YAMLLoadWarning: calling yaml.load() without Loader=... is deprecated, as the default Loader is unsafe. Please read https://msg.pyyaml.org/load for full details.
  data = yaml.load(f.read()) or {}
/scratch/cnt0024/hmg2840/albert7a/anaconda3/lib/python3.7/site-packages/distributed/utils.py:136: RuntimeWarning: Couldn't detect a suitable IP address for reaching '8.8.8.8', defaulting to '127.0.0.1': [Errno 101] Network is unreachable
  RuntimeWarning,
distributed.worker - INFO -       Start worker at:   tcp://172.30.6.161:38483
distributed.worker - INFO -          Listening to:   tcp://172.30.6.161:38483
distributed.worker - INFO -              nanny at:         172.30.6.161:36431
distributed.worker - INFO -              bokeh at:         172.30.6.161:39877
distributed.worker - INFO - Waiting to connect to:   tcp://172.30.100.1:39168
distributed.worker - INFO - -------------------------------------------------
distributed.worker - INFO -               Threads:                          1
distributed.worker - INFO -                Memory:                    4.29 GB
distributed.worker - INFO -       Local Directory: /scratch/cnt0024/hmg2840/albert7a/daskjobqueue/worker-nr33w7bg
distributed.worker - INFO - -------------------------------------------------
/scratch/cnt0024/hmg2840/albert7a/anaconda3/lib/python3.7/site-packages/dask/config.py:168: YAMLLoadWarning: calling yaml.load() without Loader=... is deprecated, as the default Loader is unsafe. Please read https://msg.pyyaml.org/load for full details.
  data = yaml.load(f.read()) or {}
/scratch/cnt0024/hmg2840/albert7a/anaconda3/lib/python3.7/site-packages/distributed/utils.py:136: RuntimeWarning: Couldn't detect a suitable IP address for reaching '8.8.8.8', defaulting to '127.0.0.1': [Errno 101] Network is unreachable
  RuntimeWarning,
distributed.worker - INFO -       Start worker at:   tcp://172.30.6.161:43533
/scratch/cnt0024/hmg2840/albert7a/anaconda3/lib/python3.7/site-packages/dask/config.py:168: YAMLLoadWarning: calling yaml.load() without Loader=... is deprecated, as the default Loader is unsafe. Please read https://msg.pyyaml.org/load for full details.
  data = yaml.load(f.read()) or {}
/scratch/cnt0024/hmg2840/albert7a/anaconda3/lib/python3.7/site-packages/distributed/utils.py:136: RuntimeWarning: Couldn't detect a suitable IP address for reaching '8.8.8.8', defaulting to '127.0.0.1': [Errno 101] Network is unreachable
  RuntimeWarning,
distributed.worker - INFO -       Start worker at:   tcp://172.30.6.161:40828
distributed.worker - INFO -          Listening to:   tcp://172.30.6.161:43533
distributed.worker - INFO -          Listening to:   tcp://172.30.6.161:40828
distributed.worker - INFO -              nanny at:         172.30.6.161:44605
distributed.worker - INFO -              nanny at:         172.30.6.161:36084
distributed.worker - INFO -              bokeh at:         172.30.6.161:42895
distributed.worker - INFO -              bokeh at:         172.30.6.161:37727
distributed.worker - INFO - Waiting to connect to:   tcp://172.30.100.1:39168
distributed.worker - INFO - Waiting to connect to:   tcp://172.30.100.1:39168
distributed.worker - INFO - -------------------------------------------------
distributed.worker - INFO - -------------------------------------------------
distributed.worker - INFO -               Threads:                          1
distributed.worker - INFO -                Memory:                    4.29 GB
distributed.worker - INFO -               Threads:                          1
distributed.worker - INFO -       Local Directory: /scratch/cnt0024/hmg2840/albert7a/daskjobqueue/worker-c81t33ma
distributed.worker - INFO - -------------------------------------------------
distributed.worker - INFO -                Memory:                    4.29 GB
distributed.worker - INFO -       Local Directory: /scratch/cnt0024/hmg2840/albert7a/daskjobqueue/worker-_7v0vsa3
distributed.worker - INFO - -------------------------------------------------
/scratch/cnt0024/hmg2840/albert7a/anaconda3/lib/python3.7/site-packages/dask/config.py:168: YAMLLoadWarning: calling yaml.load() without Loader=... is deprecated, as the default Loader is unsafe. Please read https://msg.pyyaml.org/load for full details.
  data = yaml.load(f.read()) or {}
/scratch/cnt0024/hmg2840/albert7a/anaconda3/lib/python3.7/site-packages/distributed/utils.py:136: RuntimeWarning: Couldn't detect a suitable IP address for reaching '8.8.8.8', defaulting to '127.0.0.1': [Errno 101] Network is unreachable
  RuntimeWarning,
distributed.worker - INFO -       Start worker at:   tcp://172.30.6.161:46646
distributed.worker - INFO -          Listening to:   tcp://172.30.6.161:46646
/scratch/cnt0024/hmg2840/albert7a/anaconda3/lib/python3.7/site-packages/dask/config.py:168: YAMLLoadWarning: calling yaml.load() without Loader=... is deprecated, as the default Loader is unsafe. Please read https://msg.pyyaml.org/load for full details.
  data = yaml.load(f.read()) or {}
/scratch/cnt0024/hmg2840/albert7a/anaconda3/lib/python3.7/site-packages/distributed/utils.py:136: RuntimeWarning: Couldn't detect a suitable IP address for reaching '8.8.8.8', defaulting to '127.0.0.1': [Errno 101] Network is unreachable
  RuntimeWarning,
distributed.worker - INFO -       Start worker at:   tcp://172.30.6.161:37297
distributed.worker - INFO -              nanny at:         172.30.6.161:34269
distributed.worker - INFO -          Listening to:   tcp://172.30.6.161:37297
distributed.worker - INFO -              bokeh at:         172.30.6.161:41084
distributed.worker - INFO -              nanny at:         172.30.6.161:40182
distributed.worker - INFO - Waiting to connect to:   tcp://172.30.100.1:39168
distributed.worker - INFO -              bokeh at:         172.30.6.161:33064
distributed.worker - INFO - -------------------------------------------------
distributed.worker - INFO - Waiting to connect to:   tcp://172.30.100.1:39168
distributed.worker - INFO - -------------------------------------------------
distributed.worker - INFO -               Threads:                          1
distributed.worker - INFO -               Threads:                          1
distributed.worker - INFO -                Memory:                    4.29 GB
distributed.worker - INFO -                Memory:                    4.29 GB
distributed.worker - INFO -       Local Directory: /scratch/cnt0024/hmg2840/albert7a/daskjobqueue/worker-pdqxfgoh
distributed.worker - INFO -       Local Directory: /scratch/cnt0024/hmg2840/albert7a/daskjobqueue/worker-4m_m_no9
distributed.worker - INFO - -------------------------------------------------
distributed.worker - INFO - -------------------------------------------------
/scratch/cnt0024/hmg2840/albert7a/anaconda3/lib/python3.7/site-packages/dask/config.py:168: YAMLLoadWarning: calling yaml.load() without Loader=... is deprecated, as the default Loader is unsafe. Please read https://msg.pyyaml.org/load for full details.
  data = yaml.load(f.read()) or {}
/scratch/cnt0024/hmg2840/albert7a/anaconda3/lib/python3.7/site-packages/distributed/utils.py:136: RuntimeWarning: Couldn't detect a suitable IP address for reaching '8.8.8.8', defaulting to '127.0.0.1': [Errno 101] Network is unreachable
  RuntimeWarning,
distributed.worker - INFO -       Start worker at:   tcp://172.30.6.161:39387
distributed.worker - INFO -          Listening to:   tcp://172.30.6.161:39387
distributed.worker - INFO -              nanny at:         172.30.6.161:46498
distributed.worker - INFO -              bokeh at:         172.30.6.161:44812
distributed.worker - INFO - Waiting to connect to:   tcp://172.30.100.1:39168
/scratch/cnt0024/hmg2840/albert7a/anaconda3/lib/python3.7/site-packages/dask/config.py:168: YAMLLoadWarning: calling yaml.load() without Loader=... is deprecated, as the default Loader is unsafe. Please read https://msg.pyyaml.org/load for full details.
  data = yaml.load(f.read()) or {}
/scratch/cnt0024/hmg2840/albert7a/anaconda3/lib/python3.7/site-packages/distributed/utils.py:136: RuntimeWarning: Couldn't detect a suitable IP address for reaching '8.8.8.8', defaulting to '127.0.0.1': [Errno 101] Network is unreachable
  RuntimeWarning,
distributed.worker - INFO -       Start worker at:   tcp://172.30.6.161:41337
distributed.worker - INFO - -------------------------------------------------
distributed.worker - INFO -          Listening to:   tcp://172.30.6.161:41337
distributed.worker - INFO -              nanny at:         172.30.6.161:34452
distributed.worker - INFO -              bokeh at:         172.30.6.161:46860
distributed.worker - INFO - Waiting to connect to:   tcp://172.30.100.1:39168
distributed.worker - INFO -               Threads:                          1
distributed.worker - INFO - -------------------------------------------------
distributed.worker - INFO -                Memory:                    4.29 GB
distributed.worker - INFO -               Threads:                          1
distributed.worker - INFO -       Local Directory: /scratch/cnt0024/hmg2840/albert7a/daskjobqueue/worker-s1ungkto
distributed.worker - INFO -                Memory:                    4.29 GB
distributed.worker - INFO -       Local Directory: /scratch/cnt0024/hmg2840/albert7a/daskjobqueue/worker-v62ndzym
distributed.worker - INFO - -------------------------------------------------
distributed.worker - INFO - -------------------------------------------------
/scratch/cnt0024/hmg2840/albert7a/anaconda3/lib/python3.7/site-packages/dask/config.py:168: YAMLLoadWarning: calling yaml.load() without Loader=... is deprecated, as the default Loader is unsafe. Please read https://msg.pyyaml.org/load for full details.
  data = yaml.load(f.read()) or {}
/scratch/cnt0024/hmg2840/albert7a/anaconda3/lib/python3.7/site-packages/distributed/utils.py:136: RuntimeWarning: Couldn't detect a suitable IP address for reaching '8.8.8.8', defaulting to '127.0.0.1': [Errno 101] Network is unreachable
  RuntimeWarning,
distributed.worker - INFO -       Start worker at:   tcp://172.30.6.161:34634
distributed.worker - INFO -          Listening to:   tcp://172.30.6.161:34634
distributed.worker - INFO -              nanny at:         172.30.6.161:46241
distributed.worker - INFO -              bokeh at:         172.30.6.161:35413
distributed.worker - INFO - Waiting to connect to:   tcp://172.30.100.1:39168
distributed.worker - INFO - -------------------------------------------------
distributed.worker - INFO -               Threads:                          1
distributed.worker - INFO -                Memory:                    4.29 GB
distributed.worker - INFO -       Local Directory: /scratch/cnt0024/hmg2840/albert7a/daskjobqueue/worker-ybsbznvo
distributed.worker - INFO - -------------------------------------------------
/scratch/cnt0024/hmg2840/albert7a/anaconda3/lib/python3.7/site-packages/dask/config.py:168: YAMLLoadWarning: calling yaml.load() without Loader=... is deprecated, as the default Loader is unsafe. Please read https://msg.pyyaml.org/load for full details.
  data = yaml.load(f.read()) or {}
/scratch/cnt0024/hmg2840/albert7a/anaconda3/lib/python3.7/site-packages/distributed/utils.py:136: RuntimeWarning: Couldn't detect a suitable IP address for reaching '8.8.8.8', defaulting to '127.0.0.1': [Errno 101] Network is unreachable
  RuntimeWarning,
distributed.worker - INFO -       Start worker at:   tcp://172.30.6.161:45083
distributed.worker - INFO -          Listening to:   tcp://172.30.6.161:45083
distributed.worker - INFO -              nanny at:         172.30.6.161:34724
distributed.worker - INFO -              bokeh at:         172.30.6.161:37728
distributed.worker - INFO - Waiting to connect to:   tcp://172.30.100.1:39168
distributed.worker - INFO - -------------------------------------------------
distributed.worker - INFO -               Threads:                          1
distributed.worker - INFO -                Memory:                    4.29 GB
distributed.worker - INFO -       Local Directory: /scratch/cnt0024/hmg2840/albert7a/daskjobqueue/worker-kmui2j1x
distributed.worker - INFO - -------------------------------------------------
/scratch/cnt0024/hmg2840/albert7a/anaconda3/lib/python3.7/site-packages/dask/config.py:168: YAMLLoadWarning: calling yaml.load() without Loader=... is deprecated, as the default Loader is unsafe. Please read https://msg.pyyaml.org/load for full details.
  data = yaml.load(f.read()) or {}
/scratch/cnt0024/hmg2840/albert7a/anaconda3/lib/python3.7/site-packages/distributed/utils.py:136: RuntimeWarning: Couldn't detect a suitable IP address for reaching '8.8.8.8', defaulting to '127.0.0.1': [Errno 101] Network is unreachable
  RuntimeWarning,
distributed.worker - INFO -       Start worker at:   tcp://172.30.6.161:42855
distributed.worker - INFO -          Listening to:   tcp://172.30.6.161:42855
distributed.worker - INFO -              nanny at:         172.30.6.161:39858
/scratch/cnt0024/hmg2840/albert7a/anaconda3/lib/python3.7/site-packages/dask/config.py:168: YAMLLoadWarning: calling yaml.load() without Loader=... is deprecated, as the default Loader is unsafe. Please read https://msg.pyyaml.org/load for full details.
  data = yaml.load(f.read()) or {}
/scratch/cnt0024/hmg2840/albert7a/anaconda3/lib/python3.7/site-packages/distributed/utils.py:136: RuntimeWarning: Couldn't detect a suitable IP address for reaching '8.8.8.8', defaulting to '127.0.0.1': [Errno 101] Network is unreachable
  RuntimeWarning,
distributed.worker - INFO -       Start worker at:   tcp://172.30.6.161:35610
distributed.worker - INFO -              bokeh at:         172.30.6.161:43527
distributed.worker - INFO - Waiting to connect to:   tcp://172.30.100.1:39168
distributed.worker - INFO -          Listening to:   tcp://172.30.6.161:35610
distributed.worker - INFO - -------------------------------------------------
distributed.worker - INFO -              nanny at:         172.30.6.161:37750
distributed.worker - INFO -              bokeh at:         172.30.6.161:34411
distributed.worker - INFO -               Threads:                          1
distributed.worker - INFO - Waiting to connect to:   tcp://172.30.100.1:39168
distributed.worker - INFO -                Memory:                    4.29 GB
distributed.worker - INFO - -------------------------------------------------
distributed.worker - INFO -       Local Directory: /scratch/cnt0024/hmg2840/albert7a/daskjobqueue/worker-vsd1bke5
distributed.worker - INFO - -------------------------------------------------
distributed.worker - INFO -               Threads:                          1
distributed.worker - INFO -                Memory:                    4.29 GB
distributed.worker - INFO -       Local Directory: /scratch/cnt0024/hmg2840/albert7a/daskjobqueue/worker-g45pauwk
/scratch/cnt0024/hmg2840/albert7a/anaconda3/lib/python3.7/site-packages/dask/config.py:168: YAMLLoadWarning: calling yaml.load() without Loader=... is deprecated, as the default Loader is unsafe. Please read https://msg.pyyaml.org/load for full details.
  data = yaml.load(f.read()) or {}
/scratch/cnt0024/hmg2840/albert7a/anaconda3/lib/python3.7/site-packages/distributed/utils.py:136: RuntimeWarning: Couldn't detect a suitable IP address for reaching '8.8.8.8', defaulting to '127.0.0.1': [Errno 101] Network is unreachable
  RuntimeWarning,
distributed.worker - INFO -       Start worker at:   tcp://172.30.6.161:38872
distributed.worker - INFO - -------------------------------------------------
distributed.worker - INFO -          Listening to:   tcp://172.30.6.161:38872
distributed.worker - INFO -              nanny at:         172.30.6.161:37836
distributed.worker - INFO -              bokeh at:         172.30.6.161:33849
distributed.worker - INFO - Waiting to connect to:   tcp://172.30.100.1:39168
distributed.worker - INFO - -------------------------------------------------
distributed.worker - INFO -               Threads:                          1
distributed.worker - INFO -                Memory:                    4.29 GB
distributed.worker - INFO -       Local Directory: /scratch/cnt0024/hmg2840/albert7a/daskjobqueue/worker-u3ytsker
distributed.worker - INFO - -------------------------------------------------
/scratch/cnt0024/hmg2840/albert7a/anaconda3/lib/python3.7/site-packages/dask/config.py:168: YAMLLoadWarning: calling yaml.load() without Loader=... is deprecated, as the default Loader is unsafe. Please read https://msg.pyyaml.org/load for full details.
  data = yaml.load(f.read()) or {}
/scratch/cnt0024/hmg2840/albert7a/anaconda3/lib/python3.7/site-packages/distributed/utils.py:136: RuntimeWarning: Couldn't detect a suitable IP address for reaching '8.8.8.8', defaulting to '127.0.0.1': [Errno 101] Network is unreachable
  RuntimeWarning,
distributed.worker - INFO -       Start worker at:   tcp://172.30.6.161:40803
/scratch/cnt0024/hmg2840/albert7a/anaconda3/lib/python3.7/site-packages/dask/config.py:168: YAMLLoadWarning: calling yaml.load() without Loader=... is deprecated, as the default Loader is unsafe. Please read https://msg.pyyaml.org/load for full details.
  data = yaml.load(f.read()) or {}
/scratch/cnt0024/hmg2840/albert7a/anaconda3/lib/python3.7/site-packages/distributed/utils.py:136: RuntimeWarning: Couldn't detect a suitable IP address for reaching '8.8.8.8', defaulting to '127.0.0.1': [Errno 101] Network is unreachable
  RuntimeWarning,
distributed.worker - INFO -       Start worker at:   tcp://172.30.6.161:37722
distributed.worker - INFO -          Listening to:   tcp://172.30.6.161:40803
distributed.worker - INFO -          Listening to:   tcp://172.30.6.161:37722
distributed.worker - INFO -              nanny at:         172.30.6.161:34750
distributed.worker - INFO -              nanny at:         172.30.6.161:43509
distributed.worker - INFO -              bokeh at:         172.30.6.161:35800
distributed.worker - INFO -              bokeh at:         172.30.6.161:33157
/scratch/cnt0024/hmg2840/albert7a/anaconda3/lib/python3.7/site-packages/dask/config.py:168: YAMLLoadWarning: calling yaml.load() without Loader=... is deprecated, as the default Loader is unsafe. Please read https://msg.pyyaml.org/load for full details.
  data = yaml.load(f.read()) or {}
/scratch/cnt0024/hmg2840/albert7a/anaconda3/lib/python3.7/site-packages/distributed/utils.py:136: RuntimeWarning: Couldn't detect a suitable IP address for reaching '8.8.8.8', defaulting to '127.0.0.1': [Errno 101] Network is unreachable
  RuntimeWarning,
distributed.worker - INFO -       Start worker at:   tcp://172.30.6.161:36542
distributed.worker - INFO - Waiting to connect to:   tcp://172.30.100.1:39168
distributed.worker - INFO - Waiting to connect to:   tcp://172.30.100.1:39168
distributed.worker - INFO - -------------------------------------------------
distributed.worker - INFO -          Listening to:   tcp://172.30.6.161:36542
distributed.worker - INFO - -------------------------------------------------
distributed.worker - INFO -              nanny at:         172.30.6.161:42262
distributed.worker - INFO -               Threads:                          1
distributed.worker - INFO -               Threads:                          1
distributed.worker - INFO -                Memory:                    4.29 GB
distributed.worker - INFO -       Local Directory: /scratch/cnt0024/hmg2840/albert7a/daskjobqueue/worker-lib1r84_
distributed.worker - INFO -                Memory:                    4.29 GB
distributed.worker - INFO - -------------------------------------------------
distributed.worker - INFO -       Local Directory: /scratch/cnt0024/hmg2840/albert7a/daskjobqueue/worker-79dmxb6y
distributed.worker - INFO -              bokeh at:         172.30.6.161:44011
distributed.worker - INFO - -------------------------------------------------
distributed.worker - INFO - Waiting to connect to:   tcp://172.30.100.1:39168
distributed.worker - INFO - -------------------------------------------------
distributed.worker - INFO -               Threads:                          1
distributed.worker - INFO -                Memory:                    4.29 GB
distributed.worker - INFO -       Local Directory: /scratch/cnt0024/hmg2840/albert7a/daskjobqueue/worker-1xeoouhu
distributed.worker - INFO - -------------------------------------------------
/scratch/cnt0024/hmg2840/albert7a/anaconda3/lib/python3.7/site-packages/dask/config.py:168: YAMLLoadWarning: calling yaml.load() without Loader=... is deprecated, as the default Loader is unsafe. Please read https://msg.pyyaml.org/load for full details.
  data = yaml.load(f.read()) or {}
/scratch/cnt0024/hmg2840/albert7a/anaconda3/lib/python3.7/site-packages/distributed/utils.py:136: RuntimeWarning: Couldn't detect a suitable IP address for reaching '8.8.8.8', defaulting to '127.0.0.1': [Errno 101] Network is unreachable
  RuntimeWarning,
distributed.worker - INFO -       Start worker at:   tcp://172.30.6.161:36673
distributed.worker - INFO -          Listening to:   tcp://172.30.6.161:36673
distributed.worker - INFO -              nanny at:         172.30.6.161:36365
distributed.worker - INFO -              bokeh at:         172.30.6.161:33518
distributed.worker - INFO - Waiting to connect to:   tcp://172.30.100.1:39168
distributed.worker - INFO - -------------------------------------------------
distributed.worker - INFO -               Threads:                          1
distributed.worker - INFO -                Memory:                    4.29 GB
distributed.worker - INFO -       Local Directory: /scratch/cnt0024/hmg2840/albert7a/daskjobqueue/worker-xh232841
distributed.worker - INFO - -------------------------------------------------
distributed.worker - INFO -         Registered to:   tcp://172.30.100.1:39168
distributed.worker - INFO -         Registered to:   tcp://172.30.100.1:39168
distributed.worker - INFO - -------------------------------------------------
distributed.worker - INFO -         Registered to:   tcp://172.30.100.1:39168
distributed.worker - INFO -         Registered to:   tcp://172.30.100.1:39168
distributed.worker - INFO - -------------------------------------------------
distributed.worker - INFO -         Registered to:   tcp://172.30.100.1:39168
distributed.worker - INFO -         Registered to:   tcp://172.30.100.1:39168
distributed.worker - INFO -         Registered to:   tcp://172.30.100.1:39168
distributed.worker - INFO - -------------------------------------------------
distributed.worker - INFO - -------------------------------------------------
distributed.worker - INFO -         Registered to:   tcp://172.30.100.1:39168
distributed.worker - INFO -         Registered to:   tcp://172.30.100.1:39168
distributed.worker - INFO -         Registered to:   tcp://172.30.100.1:39168
distributed.worker - INFO - -------------------------------------------------
distributed.worker - INFO - -------------------------------------------------
distributed.worker - INFO -         Registered to:   tcp://172.30.100.1:39168
distributed.worker - INFO - -------------------------------------------------
distributed.core - INFO - Starting established connection
distributed.worker - INFO - -------------------------------------------------
distributed.worker - INFO - -------------------------------------------------
distributed.core - INFO - Starting established connection
distributed.worker - INFO - -------------------------------------------------
distributed.worker - INFO -         Registered to:   tcp://172.30.100.1:39168
distributed.worker - INFO - -------------------------------------------------
distributed.worker - INFO -         Registered to:   tcp://172.30.100.1:39168
distributed.core - INFO - Starting established connection
distributed.worker - INFO -         Registered to:   tcp://172.30.100.1:39168
distributed.worker - INFO -         Registered to:   tcp://172.30.100.1:39168
distributed.core - INFO - Starting established connection
distributed.worker - INFO -         Registered to:   tcp://172.30.100.1:39168
distributed.worker - INFO - -------------------------------------------------
distributed.core - INFO - Starting established connection
distributed.worker - INFO -         Registered to:   tcp://172.30.100.1:39168
distributed.worker - INFO -         Registered to:   tcp://172.30.100.1:39168
distributed.worker - INFO - -------------------------------------------------
distributed.worker - INFO -         Registered to:   tcp://172.30.100.1:39168
distributed.core - INFO - Starting established connection
distributed.core - INFO - Starting established connection
distributed.worker - INFO - -------------------------------------------------
distributed.worker - INFO -         Registered to:   tcp://172.30.100.1:39168
distributed.core - INFO - Starting established connection
distributed.worker - INFO - -------------------------------------------------
distributed.core - INFO - Starting established connection
distributed.core - INFO - Starting established connection
distributed.core - INFO - Starting established connection
distributed.worker - INFO -         Registered to:   tcp://172.30.100.1:39168
distributed.worker - INFO - -------------------------------------------------
distributed.worker - INFO - -------------------------------------------------
distributed.worker - INFO -         Registered to:   tcp://172.30.100.1:39168
distributed.worker - INFO - -------------------------------------------------
distributed.worker - INFO - -------------------------------------------------
distributed.worker - INFO -         Registered to:   tcp://172.30.100.1:39168
distributed.worker - INFO -         Registered to:   tcp://172.30.100.1:39168
distributed.core - INFO - Starting established connection
distributed.worker - INFO - -------------------------------------------------
distributed.worker - INFO -         Registered to:   tcp://172.30.100.1:39168
distributed.worker - INFO -         Registered to:   tcp://172.30.100.1:39168
distributed.core - INFO - Starting established connection
distributed.worker - INFO - -------------------------------------------------
distributed.worker - INFO -         Registered to:   tcp://172.30.100.1:39168
distributed.core - INFO - Starting established connection
distributed.core - INFO - Starting established connection
distributed.worker - INFO - -------------------------------------------------
distributed.worker - INFO - -------------------------------------------------
distributed.worker - INFO - -------------------------------------------------
distributed.core - INFO - Starting established connection
distributed.core - INFO - Starting established connection
distributed.core - INFO - Starting established connection
distributed.worker - INFO - -------------------------------------------------
distributed.worker - INFO - -------------------------------------------------
distributed.core - INFO - Starting established connection
distributed.worker - INFO - -------------------------------------------------
distributed.core - INFO - Starting established connection
distributed.core - INFO - Starting established connection
distributed.core - INFO - Starting established connection
distributed.core - INFO - Starting established connection
distributed.core - INFO - Starting established connection
distributed.core - INFO - Starting established connection
distributed.core - INFO - Starting established connection
distributed.core - INFO - Starting established connection
/scratch/cnt0024/hmg2840/albert7a/anaconda3/lib/python3.7/site-packages/dask/config.py:168: YAMLLoadWarning: calling yaml.load() without Loader=... is deprecated, as the default Loader is unsafe. Please read https://msg.pyyaml.org/load for full details.
  data = yaml.load(f.read()) or {}
/scratch/cnt0024/hmg2840/albert7a/anaconda3/lib/python3.7/site-packages/distributed/utils.py:136: RuntimeWarning: Couldn't detect a suitable IP address for reaching '8.8.8.8', defaulting to '127.0.0.1': [Errno 101] Network is unreachable
  RuntimeWarning,
/scratch/cnt0024/hmg2840/albert7a/anaconda3/lib/python3.7/contextlib.py:119: UserWarning: Creating scratch directories is taking a surprisingly long time. This is often due to running workers on a network file system. Consider specifying a local-directory to point workers to write scratch data to a local disk.
  next(self.gen)
distributed.worker - INFO -       Start worker at:   tcp://172.30.6.161:42713
distributed.worker - INFO -          Listening to:   tcp://172.30.6.161:42713
distributed.worker - INFO -              nanny at:         172.30.6.161:38443
distributed.worker - INFO -              bokeh at:         172.30.6.161:45926
distributed.worker - INFO - Waiting to connect to:   tcp://172.30.100.1:39168
distributed.worker - INFO - -------------------------------------------------
distributed.worker - INFO -               Threads:                          1
distributed.worker - INFO -                Memory:                    4.29 GB
distributed.worker - INFO -       Local Directory: /scratch/cnt0024/hmg2840/albert7a/daskjobqueue/worker-vtrqr_t6
distributed.worker - INFO - -------------------------------------------------
distributed.worker - INFO -         Registered to:   tcp://172.30.100.1:39168
distributed.worker - INFO - -------------------------------------------------
distributed.core - INFO - Starting established connection
tornado.application - ERROR - Exception in callback functools.partial(<bound method IOLoop._discard_future_result of <tornado.platform.asyncio.AsyncIOLoop object at 0x2ba6398a6208>>, <Future finished exception=OSError("Timed out trying to connect to 'tcp://172.30.100.1:39168' after 10 s: connect() didn't finish in time")>)
Traceback (most recent call last):
  File "/scratch/cnt0024/hmg2840/albert7a/anaconda3/lib/python3.7/site-packages/distributed/comm/core.py", line 218, in connect
    quiet_exceptions=EnvironmentError,
  File "/scratch/cnt0024/hmg2840/albert7a/anaconda3/lib/python3.7/site-packages/tornado/gen.py", line 735, in run
    value = future.result()
tornado.util.TimeoutError: Timeout

During handling of the above exception, another exception occurred:

Traceback (most recent call last):
  File "/scratch/cnt0024/hmg2840/albert7a/anaconda3/lib/python3.7/site-packages/tornado/ioloop.py", line 743, in _run_callback
    ret = callback()
  File "/scratch/cnt0024/hmg2840/albert7a/anaconda3/lib/python3.7/site-packages/tornado/ioloop.py", line 767, in _discard_future_result
    future.result()
  File "/scratch/cnt0024/hmg2840/albert7a/anaconda3/lib/python3.7/site-packages/tornado/gen.py", line 742, in run
    yielded = self.gen.throw(*exc_info)  # type: ignore
  File "/scratch/cnt0024/hmg2840/albert7a/anaconda3/lib/python3.7/site-packages/distributed/worker.py", line 748, in heartbeat
    address=self.contact_address, now=time(), metrics=self.get_metrics()
  File "/scratch/cnt0024/hmg2840/albert7a/anaconda3/lib/python3.7/site-packages/tornado/gen.py", line 735, in run
    value = future.result()
  File "/scratch/cnt0024/hmg2840/albert7a/anaconda3/lib/python3.7/site-packages/tornado/gen.py", line 742, in run
    yielded = self.gen.throw(*exc_info)  # type: ignore
  File "/scratch/cnt0024/hmg2840/albert7a/anaconda3/lib/python3.7/site-packages/distributed/core.py", line 736, in send_recv_from_rpc
    comm = yield self.pool.connect(self.addr)
  File "/scratch/cnt0024/hmg2840/albert7a/anaconda3/lib/python3.7/site-packages/tornado/gen.py", line 735, in run
    value = future.result()
  File "/scratch/cnt0024/hmg2840/albert7a/anaconda3/lib/python3.7/site-packages/tornado/gen.py", line 742, in run
    yielded = self.gen.throw(*exc_info)  # type: ignore
  File "/scratch/cnt0024/hmg2840/albert7a/anaconda3/lib/python3.7/site-packages/distributed/core.py", line 864, in connect
    connection_args=self.connection_args,
  File "/scratch/cnt0024/hmg2840/albert7a/anaconda3/lib/python3.7/site-packages/tornado/gen.py", line 735, in run
    value = future.result()
  File "/scratch/cnt0024/hmg2840/albert7a/anaconda3/lib/python3.7/site-packages/tornado/gen.py", line 742, in run
    yielded = self.gen.throw(*exc_info)  # type: ignore
  File "/scratch/cnt0024/hmg2840/albert7a/anaconda3/lib/python3.7/site-packages/distributed/comm/core.py", line 230, in connect
    _raise(error)
  File "/scratch/cnt0024/hmg2840/albert7a/anaconda3/lib/python3.7/site-packages/distributed/comm/core.py", line 207, in _raise
    raise IOError(msg)
OSError: Timed out trying to connect to 'tcp://172.30.100.1:39168' after 10 s: connect() didn't finish in time
tornado.application - ERROR - Exception in callback functools.partial(<bound method IOLoop._discard_future_result of <tornado.platform.asyncio.AsyncIOLoop object at 0x2ba6398a6208>>, <Future finished exception=OSError("Timed out trying to connect to 'tcp://172.30.100.1:39168' after 10 s: connect() didn't finish in time")>)
Traceback (most recent call last):
  File "/scratch/cnt0024/hmg2840/albert7a/anaconda3/lib/python3.7/site-packages/distributed/comm/core.py", line 218, in connect
    quiet_exceptions=EnvironmentError,
  File "/scratch/cnt0024/hmg2840/albert7a/anaconda3/lib/python3.7/site-packages/tornado/gen.py", line 735, in run
    value = future.result()
tornado.util.TimeoutError: Timeout

During handling of the above exception, another exception occurred:

Traceback (most recent call last):
  File "/scratch/cnt0024/hmg2840/albert7a/anaconda3/lib/python3.7/site-packages/tornado/ioloop.py", line 743, in _run_callback
    ret = callback()
  File "/scratch/cnt0024/hmg2840/albert7a/anaconda3/lib/python3.7/site-packages/tornado/ioloop.py", line 767, in _discard_future_result
    future.result()
  File "/scratch/cnt0024/hmg2840/albert7a/anaconda3/lib/python3.7/site-packages/tornado/gen.py", line 742, in run
    yielded = self.gen.throw(*exc_info)  # type: ignore
  File "/scratch/cnt0024/hmg2840/albert7a/anaconda3/lib/python3.7/site-packages/distributed/worker.py", line 748, in heartbeat
    address=self.contact_address, now=time(), metrics=self.get_metrics()
  File "/scratch/cnt0024/hmg2840/albert7a/anaconda3/lib/python3.7/site-packages/tornado/gen.py", line 735, in run
    value = future.result()
  File "/scratch/cnt0024/hmg2840/albert7a/anaconda3/lib/python3.7/site-packages/tornado/gen.py", line 742, in run
    yielded = self.gen.throw(*exc_info)  # type: ignore
  File "/scratch/cnt0024/hmg2840/albert7a/anaconda3/lib/python3.7/site-packages/distributed/core.py", line 736, in send_recv_from_rpc
    comm = yield self.pool.connect(self.addr)
  File "/scratch/cnt0024/hmg2840/albert7a/anaconda3/lib/python3.7/site-packages/tornado/gen.py", line 735, in run
    value = future.result()
  File "/scratch/cnt0024/hmg2840/albert7a/anaconda3/lib/python3.7/site-packages/tornado/gen.py", line 742, in run
    yielded = self.gen.throw(*exc_info)  # type: ignore
  File "/scratch/cnt0024/hmg2840/albert7a/anaconda3/lib/python3.7/site-packages/distributed/core.py", line 864, in connect
    connection_args=self.connection_args,
  File "/scratch/cnt0024/hmg2840/albert7a/anaconda3/lib/python3.7/site-packages/tornado/gen.py", line 735, in run
    value = future.result()
  File "/scratch/cnt0024/hmg2840/albert7a/anaconda3/lib/python3.7/site-packages/tornado/gen.py", line 742, in run
    yielded = self.gen.throw(*exc_info)  # type: ignore
  File "/scratch/cnt0024/hmg2840/albert7a/anaconda3/lib/python3.7/site-packages/distributed/comm/core.py", line 230, in connect
    _raise(error)
  File "/scratch/cnt0024/hmg2840/albert7a/anaconda3/lib/python3.7/site-packages/distributed/comm/core.py", line 207, in _raise
    raise IOError(msg)
OSError: Timed out trying to connect to 'tcp://172.30.100.1:39168' after 10 s: connect() didn't finish in time
tornado.application - ERROR - Exception in callback functools.partial(<bound method IOLoop._discard_future_result of <tornado.platform.asyncio.AsyncIOLoop object at 0x2ba6398a6208>>, <Future finished exception=OSError("Timed out trying to connect to 'tcp://172.30.100.1:39168' after 10 s: connect() didn't finish in time")>)
Traceback (most recent call last):
  File "/scratch/cnt0024/hmg2840/albert7a/anaconda3/lib/python3.7/site-packages/distributed/comm/core.py", line 218, in connect
    quiet_exceptions=EnvironmentError,
  File "/scratch/cnt0024/hmg2840/albert7a/anaconda3/lib/python3.7/site-packages/tornado/gen.py", line 735, in run
    value = future.result()
tornado.util.TimeoutError: Timeout

During handling of the above exception, another exception occurred:

Traceback (most recent call last):
  File "/scratch/cnt0024/hmg2840/albert7a/anaconda3/lib/python3.7/site-packages/tornado/ioloop.py", line 743, in _run_callback
    ret = callback()
  File "/scratch/cnt0024/hmg2840/albert7a/anaconda3/lib/python3.7/site-packages/tornado/ioloop.py", line 767, in _discard_future_result
    future.result()
  File "/scratch/cnt0024/hmg2840/albert7a/anaconda3/lib/python3.7/site-packages/tornado/gen.py", line 742, in run
    yielded = self.gen.throw(*exc_info)  # type: ignore
  File "/scratch/cnt0024/hmg2840/albert7a/anaconda3/lib/python3.7/site-packages/distributed/worker.py", line 748, in heartbeat
    address=self.contact_address, now=time(), metrics=self.get_metrics()
  File "/scratch/cnt0024/hmg2840/albert7a/anaconda3/lib/python3.7/site-packages/tornado/gen.py", line 735, in run
    value = future.result()
  File "/scratch/cnt0024/hmg2840/albert7a/anaconda3/lib/python3.7/site-packages/tornado/gen.py", line 742, in run
    yielded = self.gen.throw(*exc_info)  # type: ignore
  File "/scratch/cnt0024/hmg2840/albert7a/anaconda3/lib/python3.7/site-packages/distributed/core.py", line 736, in send_recv_from_rpc
    comm = yield self.pool.connect(self.addr)
  File "/scratch/cnt0024/hmg2840/albert7a/anaconda3/lib/python3.7/site-packages/tornado/gen.py", line 735, in run
    value = future.result()
  File "/scratch/cnt0024/hmg2840/albert7a/anaconda3/lib/python3.7/site-packages/tornado/gen.py", line 742, in run
    yielded = self.gen.throw(*exc_info)  # type: ignore
  File "/scratch/cnt0024/hmg2840/albert7a/anaconda3/lib/python3.7/site-packages/distributed/core.py", line 864, in connect
    connection_args=self.connection_args,
  File "/scratch/cnt0024/hmg2840/albert7a/anaconda3/lib/python3.7/site-packages/tornado/gen.py", line 735, in run
    value = future.result()
  File "/scratch/cnt0024/hmg2840/albert7a/anaconda3/lib/python3.7/site-packages/tornado/gen.py", line 742, in run
    yielded = self.gen.throw(*exc_info)  # type: ignore
  File "/scratch/cnt0024/hmg2840/albert7a/anaconda3/lib/python3.7/site-packages/distributed/comm/core.py", line 230, in connect
    _raise(error)
  File "/scratch/cnt0024/hmg2840/albert7a/anaconda3/lib/python3.7/site-packages/distributed/comm/core.py", line 207, in _raise
    raise IOError(msg)
OSError: Timed out trying to connect to 'tcp://172.30.100.1:39168' after 10 s: connect() didn't finish in time
tornado.application - ERROR - Exception in callback functools.partial(<bound method IOLoop._discard_future_result of <tornado.platform.asyncio.AsyncIOLoop object at 0x2ba6398a6208>>, <Future finished exception=OSError("Timed out trying to connect to 'tcp://172.30.100.1:39168' after 10 s: connect() didn't finish in time")>)
Traceback (most recent call last):
  File "/scratch/cnt0024/hmg2840/albert7a/anaconda3/lib/python3.7/site-packages/distributed/comm/core.py", line 218, in connect
    quiet_exceptions=EnvironmentError,
  File "/scratch/cnt0024/hmg2840/albert7a/anaconda3/lib/python3.7/site-packages/tornado/gen.py", line 735, in run
    value = future.result()
tornado.util.TimeoutError: Timeout

During handling of the above exception, another exception occurred:

Traceback (most recent call last):
  File "/scratch/cnt0024/hmg2840/albert7a/anaconda3/lib/python3.7/site-packages/tornado/ioloop.py", line 743, in _run_callback
    ret = callback()
  File "/scratch/cnt0024/hmg2840/albert7a/anaconda3/lib/python3.7/site-packages/tornado/ioloop.py", line 767, in _discard_future_result
    future.result()
  File "/scratch/cnt0024/hmg2840/albert7a/anaconda3/lib/python3.7/site-packages/tornado/gen.py", line 742, in run
    yielded = self.gen.throw(*exc_info)  # type: ignore
  File "/scratch/cnt0024/hmg2840/albert7a/anaconda3/lib/python3.7/site-packages/distributed/worker.py", line 748, in heartbeat
    address=self.contact_address, now=time(), metrics=self.get_metrics()
  File "/scratch/cnt0024/hmg2840/albert7a/anaconda3/lib/python3.7/site-packages/tornado/gen.py", line 735, in run
    value = future.result()
  File "/scratch/cnt0024/hmg2840/albert7a/anaconda3/lib/python3.7/site-packages/tornado/gen.py", line 742, in run
    yielded = self.gen.throw(*exc_info)  # type: ignore
  File "/scratch/cnt0024/hmg2840/albert7a/anaconda3/lib/python3.7/site-packages/distributed/core.py", line 736, in send_recv_from_rpc
    comm = yield self.pool.connect(self.addr)
  File "/scratch/cnt0024/hmg2840/albert7a/anaconda3/lib/python3.7/site-packages/tornado/gen.py", line 735, in run
    value = future.result()
  File "/scratch/cnt0024/hmg2840/albert7a/anaconda3/lib/python3.7/site-packages/tornado/gen.py", line 742, in run
    yielded = self.gen.throw(*exc_info)  # type: ignore
  File "/scratch/cnt0024/hmg2840/albert7a/anaconda3/lib/python3.7/site-packages/distributed/core.py", line 864, in connect
    connection_args=self.connection_args,
  File "/scratch/cnt0024/hmg2840/albert7a/anaconda3/lib/python3.7/site-packages/tornado/gen.py", line 735, in run
    value = future.result()
  File "/scratch/cnt0024/hmg2840/albert7a/anaconda3/lib/python3.7/site-packages/tornado/gen.py", line 742, in run
    yielded = self.gen.throw(*exc_info)  # type: ignore
  File "/scratch/cnt0024/hmg2840/albert7a/anaconda3/lib/python3.7/site-packages/distributed/comm/core.py", line 230, in connect
    _raise(error)
  File "/scratch/cnt0024/hmg2840/albert7a/anaconda3/lib/python3.7/site-packages/distributed/comm/core.py", line 207, in _raise
    raise IOError(msg)
OSError: Timed out trying to connect to 'tcp://172.30.100.1:39168' after 10 s: connect() didn't finish in time
tornado.application - ERROR - Exception in callback functools.partial(<bound method IOLoop._discard_future_result of <tornado.platform.asyncio.AsyncIOLoop object at 0x2ba6398a6208>>, <Future finished exception=OSError("Timed out trying to connect to 'tcp://172.30.100.1:39168' after 10 s: connect() didn't finish in time")>)
Traceback (most recent call last):
  File "/scratch/cnt0024/hmg2840/albert7a/anaconda3/lib/python3.7/site-packages/distributed/comm/core.py", line 218, in connect
    quiet_exceptions=EnvironmentError,
  File "/scratch/cnt0024/hmg2840/albert7a/anaconda3/lib/python3.7/site-packages/tornado/gen.py", line 735, in run
    value = future.result()
tornado.util.TimeoutError: Timeout

During handling of the above exception, another exception occurred:

Traceback (most recent call last):
  File "/scratch/cnt0024/hmg2840/albert7a/anaconda3/lib/python3.7/site-packages/tornado/ioloop.py", line 743, in _run_callback
    ret = callback()
  File "/scratch/cnt0024/hmg2840/albert7a/anaconda3/lib/python3.7/site-packages/tornado/ioloop.py", line 767, in _discard_future_result
    future.result()
  File "/scratch/cnt0024/hmg2840/albert7a/anaconda3/lib/python3.7/site-packages/tornado/gen.py", line 742, in run
    yielded = self.gen.throw(*exc_info)  # type: ignore
  File "/scratch/cnt0024/hmg2840/albert7a/anaconda3/lib/python3.7/site-packages/distributed/worker.py", line 748, in heartbeat
    address=self.contact_address, now=time(), metrics=self.get_metrics()
  File "/scratch/cnt0024/hmg2840/albert7a/anaconda3/lib/python3.7/site-packages/tornado/gen.py", line 735, in run
    value = future.result()
  File "/scratch/cnt0024/hmg2840/albert7a/anaconda3/lib/python3.7/site-packages/tornado/gen.py", line 742, in run
    yielded = self.gen.throw(*exc_info)  # type: ignore
  File "/scratch/cnt0024/hmg2840/albert7a/anaconda3/lib/python3.7/site-packages/distributed/core.py", line 736, in send_recv_from_rpc
    comm = yield self.pool.connect(self.addr)
  File "/scratch/cnt0024/hmg2840/albert7a/anaconda3/lib/python3.7/site-packages/tornado/gen.py", line 735, in run
    value = future.result()
  File "/scratch/cnt0024/hmg2840/albert7a/anaconda3/lib/python3.7/site-packages/tornado/gen.py", line 742, in run
    yielded = self.gen.throw(*exc_info)  # type: ignore
  File "/scratch/cnt0024/hmg2840/albert7a/anaconda3/lib/python3.7/site-packages/distributed/core.py", line 864, in connect
    connection_args=self.connection_args,
  File "/scratch/cnt0024/hmg2840/albert7a/anaconda3/lib/python3.7/site-packages/tornado/gen.py", line 735, in run
    value = future.result()
  File "/scratch/cnt0024/hmg2840/albert7a/anaconda3/lib/python3.7/site-packages/tornado/gen.py", line 742, in run
    yielded = self.gen.throw(*exc_info)  # type: ignore
  File "/scratch/cnt0024/hmg2840/albert7a/anaconda3/lib/python3.7/site-packages/distributed/comm/core.py", line 230, in connect
    _raise(error)
  File "/scratch/cnt0024/hmg2840/albert7a/anaconda3/lib/python3.7/site-packages/distributed/comm/core.py", line 207, in _raise
    raise IOError(msg)
OSError: Timed out trying to connect to 'tcp://172.30.100.1:39168' after 10 s: connect() didn't finish in time
tornado.application - ERROR - Exception in callback functools.partial(<bound method IOLoop._discard_future_result of <tornado.platform.asyncio.AsyncIOLoop object at 0x2ba6398a6208>>, <Future finished exception=OSError("Timed out trying to connect to 'tcp://172.30.100.1:39168' after 10 s: connect() didn't finish in time")>)
Traceback (most recent call last):
  File "/scratch/cnt0024/hmg2840/albert7a/anaconda3/lib/python3.7/site-packages/distributed/comm/core.py", line 218, in connect
    quiet_exceptions=EnvironmentError,
  File "/scratch/cnt0024/hmg2840/albert7a/anaconda3/lib/python3.7/site-packages/tornado/gen.py", line 735, in run
    value = future.result()
tornado.util.TimeoutError: Timeout

During handling of the above exception, another exception occurred:

Traceback (most recent call last):
  File "/scratch/cnt0024/hmg2840/albert7a/anaconda3/lib/python3.7/site-packages/tornado/ioloop.py", line 743, in _run_callback
    ret = callback()
  File "/scratch/cnt0024/hmg2840/albert7a/anaconda3/lib/python3.7/site-packages/tornado/ioloop.py", line 767, in _discard_future_result
    future.result()
  File "/scratch/cnt0024/hmg2840/albert7a/anaconda3/lib/python3.7/site-packages/tornado/gen.py", line 742, in run
    yielded = self.gen.throw(*exc_info)  # type: ignore
  File "/scratch/cnt0024/hmg2840/albert7a/anaconda3/lib/python3.7/site-packages/distributed/worker.py", line 748, in heartbeat
    address=self.contact_address, now=time(), metrics=self.get_metrics()
  File "/scratch/cnt0024/hmg2840/albert7a/anaconda3/lib/python3.7/site-packages/tornado/gen.py", line 735, in run
    value = future.result()
  File "/scratch/cnt0024/hmg2840/albert7a/anaconda3/lib/python3.7/site-packages/tornado/gen.py", line 742, in run
    yielded = self.gen.throw(*exc_info)  # type: ignore
  File "/scratch/cnt0024/hmg2840/albert7a/anaconda3/lib/python3.7/site-packages/distributed/core.py", line 736, in send_recv_from_rpc
    comm = yield self.pool.connect(self.addr)
  File "/scratch/cnt0024/hmg2840/albert7a/anaconda3/lib/python3.7/site-packages/tornado/gen.py", line 735, in run
    value = future.result()
  File "/scratch/cnt0024/hmg2840/albert7a/anaconda3/lib/python3.7/site-packages/tornado/gen.py", line 742, in run
    yielded = self.gen.throw(*exc_info)  # type: ignore
  File "/scratch/cnt0024/hmg2840/albert7a/anaconda3/lib/python3.7/site-packages/distributed/core.py", line 864, in connect
    connection_args=self.connection_args,
  File "/scratch/cnt0024/hmg2840/albert7a/anaconda3/lib/python3.7/site-packages/tornado/gen.py", line 735, in run
    value = future.result()
  File "/scratch/cnt0024/hmg2840/albert7a/anaconda3/lib/python3.7/site-packages/tornado/gen.py", line 742, in run
    yielded = self.gen.throw(*exc_info)  # type: ignore
  File "/scratch/cnt0024/hmg2840/albert7a/anaconda3/lib/python3.7/site-packages/distributed/comm/core.py", line 230, in connect
    _raise(error)
  File "/scratch/cnt0024/hmg2840/albert7a/anaconda3/lib/python3.7/site-packages/distributed/comm/core.py", line 207, in _raise
    raise IOError(msg)
OSError: Timed out trying to connect to 'tcp://172.30.100.1:39168' after 10 s: connect() didn't finish in time
tornado.application - ERROR - Exception in callback functools.partial(<bound method IOLoop._discard_future_result of <tornado.platform.asyncio.AsyncIOLoop object at 0x2ba6398a6208>>, <Future finished exception=OSError("Timed out trying to connect to 'tcp://172.30.100.1:39168' after 10 s: connect() didn't finish in time")>)
Traceback (most recent call last):
  File "/scratch/cnt0024/hmg2840/albert7a/anaconda3/lib/python3.7/site-packages/distributed/comm/core.py", line 218, in connect
    quiet_exceptions=EnvironmentError,
  File "/scratch/cnt0024/hmg2840/albert7a/anaconda3/lib/python3.7/site-packages/tornado/gen.py", line 735, in run
    value = future.result()
tornado.util.TimeoutError: Timeout

During handling of the above exception, another exception occurred:

Traceback (most recent call last):
  File "/scratch/cnt0024/hmg2840/albert7a/anaconda3/lib/python3.7/site-packages/tornado/ioloop.py", line 743, in _run_callback
    ret = callback()
  File "/scratch/cnt0024/hmg2840/albert7a/anaconda3/lib/python3.7/site-packages/tornado/ioloop.py", line 767, in _discard_future_result
    future.result()
  File "/scratch/cnt0024/hmg2840/albert7a/anaconda3/lib/python3.7/site-packages/tornado/gen.py", line 742, in run
    yielded = self.gen.throw(*exc_info)  # type: ignore
  File "/scratch/cnt0024/hmg2840/albert7a/anaconda3/lib/python3.7/site-packages/distributed/worker.py", line 748, in heartbeat
    address=self.contact_address, now=time(), metrics=self.get_metrics()
  File "/scratch/cnt0024/hmg2840/albert7a/anaconda3/lib/python3.7/site-packages/tornado/gen.py", line 735, in run
    value = future.result()
  File "/scratch/cnt0024/hmg2840/albert7a/anaconda3/lib/python3.7/site-packages/tornado/gen.py", line 742, in run
    yielded = self.gen.throw(*exc_info)  # type: ignore
  File "/scratch/cnt0024/hmg2840/albert7a/anaconda3/lib/python3.7/site-packages/distributed/core.py", line 736, in send_recv_from_rpc
    comm = yield self.pool.connect(self.addr)
  File "/scratch/cnt0024/hmg2840/albert7a/anaconda3/lib/python3.7/site-packages/tornado/gen.py", line 735, in run
    value = future.result()
  File "/scratch/cnt0024/hmg2840/albert7a/anaconda3/lib/python3.7/site-packages/tornado/gen.py", line 742, in run
    yielded = self.gen.throw(*exc_info)  # type: ignore
  File "/scratch/cnt0024/hmg2840/albert7a/anaconda3/lib/python3.7/site-packages/distributed/core.py", line 864, in connect
    connection_args=self.connection_args,
  File "/scratch/cnt0024/hmg2840/albert7a/anaconda3/lib/python3.7/site-packages/tornado/gen.py", line 735, in run
    value = future.result()
  File "/scratch/cnt0024/hmg2840/albert7a/anaconda3/lib/python3.7/site-packages/tornado/gen.py", line 742, in run
    yielded = self.gen.throw(*exc_info)  # type: ignore
  File "/scratch/cnt0024/hmg2840/albert7a/anaconda3/lib/python3.7/site-packages/distributed/comm/core.py", line 230, in connect
    _raise(error)
  File "/scratch/cnt0024/hmg2840/albert7a/anaconda3/lib/python3.7/site-packages/distributed/comm/core.py", line 207, in _raise
    raise IOError(msg)
OSError: Timed out trying to connect to 'tcp://172.30.100.1:39168' after 10 s: connect() didn't finish in time
tornado.application - ERROR - Exception in callback functools.partial(<bound method IOLoop._discard_future_result of <tornado.platform.asyncio.AsyncIOLoop object at 0x2ba6398a6208>>, <Future finished exception=OSError("Timed out trying to connect to 'tcp://172.30.100.1:39168' after 10 s: connect() didn't finish in time")>)
Traceback (most recent call last):
  File "/scratch/cnt0024/hmg2840/albert7a/anaconda3/lib/python3.7/site-packages/distributed/comm/core.py", line 218, in connect
    quiet_exceptions=EnvironmentError,
  File "/scratch/cnt0024/hmg2840/albert7a/anaconda3/lib/python3.7/site-packages/tornado/gen.py", line 735, in run
    value = future.result()
tornado.util.TimeoutError: Timeout

During handling of the above exception, another exception occurred:

Traceback (most recent call last):
  File "/scratch/cnt0024/hmg2840/albert7a/anaconda3/lib/python3.7/site-packages/tornado/ioloop.py", line 743, in _run_callback
    ret = callback()
  File "/scratch/cnt0024/hmg2840/albert7a/anaconda3/lib/python3.7/site-packages/tornado/ioloop.py", line 767, in _discard_future_result
    future.result()
  File "/scratch/cnt0024/hmg2840/albert7a/anaconda3/lib/python3.7/site-packages/tornado/gen.py", line 742, in run
    yielded = self.gen.throw(*exc_info)  # type: ignore
  File "/scratch/cnt0024/hmg2840/albert7a/anaconda3/lib/python3.7/site-packages/distributed/worker.py", line 748, in heartbeat
    address=self.contact_address, now=time(), metrics=self.get_metrics()
  File "/scratch/cnt0024/hmg2840/albert7a/anaconda3/lib/python3.7/site-packages/tornado/gen.py", line 735, in run
    value = future.result()
  File "/scratch/cnt0024/hmg2840/albert7a/anaconda3/lib/python3.7/site-packages/tornado/gen.py", line 742, in run
    yielded = self.gen.throw(*exc_info)  # type: ignore
  File "/scratch/cnt0024/hmg2840/albert7a/anaconda3/lib/python3.7/site-packages/distributed/core.py", line 736, in send_recv_from_rpc
    comm = yield self.pool.connect(self.addr)
  File "/scratch/cnt0024/hmg2840/albert7a/anaconda3/lib/python3.7/site-packages/tornado/gen.py", line 735, in run
    value = future.result()
  File "/scratch/cnt0024/hmg2840/albert7a/anaconda3/lib/python3.7/site-packages/tornado/gen.py", line 742, in run
    yielded = self.gen.throw(*exc_info)  # type: ignore
  File "/scratch/cnt0024/hmg2840/albert7a/anaconda3/lib/python3.7/site-packages/distributed/core.py", line 864, in connect
    connection_args=self.connection_args,
  File "/scratch/cnt0024/hmg2840/albert7a/anaconda3/lib/python3.7/site-packages/tornado/gen.py", line 735, in run
    value = future.result()
  File "/scratch/cnt0024/hmg2840/albert7a/anaconda3/lib/python3.7/site-packages/tornado/gen.py", line 742, in run
    yielded = self.gen.throw(*exc_info)  # type: ignore
  File "/scratch/cnt0024/hmg2840/albert7a/anaconda3/lib/python3.7/site-packages/distributed/comm/core.py", line 230, in connect
    _raise(error)
  File "/scratch/cnt0024/hmg2840/albert7a/anaconda3/lib/python3.7/site-packages/distributed/comm/core.py", line 207, in _raise
    raise IOError(msg)
OSError: Timed out trying to connect to 'tcp://172.30.100.1:39168' after 10 s: connect() didn't finish in time
tornado.application - ERROR - Exception in callback functools.partial(<bound method IOLoop._discard_future_result of <tornado.platform.asyncio.AsyncIOLoop object at 0x2ba6398a6208>>, <Future finished exception=OSError("Timed out trying to connect to 'tcp://172.30.100.1:39168' after 10 s: connect() didn't finish in time")>)
Traceback (most recent call last):
  File "/scratch/cnt0024/hmg2840/albert7a/anaconda3/lib/python3.7/site-packages/distributed/comm/core.py", line 218, in connect
    quiet_exceptions=EnvironmentError,
  File "/scratch/cnt0024/hmg2840/albert7a/anaconda3/lib/python3.7/site-packages/tornado/gen.py", line 735, in run
    value = future.result()
tornado.util.TimeoutError: Timeout

During handling of the above exception, another exception occurred:

Traceback (most recent call last):
  File "/scratch/cnt0024/hmg2840/albert7a/anaconda3/lib/python3.7/site-packages/tornado/ioloop.py", line 743, in _run_callback
    ret = callback()
  File "/scratch/cnt0024/hmg2840/albert7a/anaconda3/lib/python3.7/site-packages/tornado/ioloop.py", line 767, in _discard_future_result
    future.result()
  File "/scratch/cnt0024/hmg2840/albert7a/anaconda3/lib/python3.7/site-packages/tornado/gen.py", line 742, in run
    yielded = self.gen.throw(*exc_info)  # type: ignore
  File "/scratch/cnt0024/hmg2840/albert7a/anaconda3/lib/python3.7/site-packages/distributed/worker.py", line 748, in heartbeat
    address=self.contact_address, now=time(), metrics=self.get_metrics()
  File "/scratch/cnt0024/hmg2840/albert7a/anaconda3/lib/python3.7/site-packages/tornado/gen.py", line 735, in run
    value = future.result()
  File "/scratch/cnt0024/hmg2840/albert7a/anaconda3/lib/python3.7/site-packages/tornado/gen.py", line 742, in run
    yielded = self.gen.throw(*exc_info)  # type: ignore
  File "/scratch/cnt0024/hmg2840/albert7a/anaconda3/lib/python3.7/site-packages/distributed/core.py", line 736, in send_recv_from_rpc
    comm = yield self.pool.connect(self.addr)
  File "/scratch/cnt0024/hmg2840/albert7a/anaconda3/lib/python3.7/site-packages/tornado/gen.py", line 735, in run
    value = future.result()
  File "/scratch/cnt0024/hmg2840/albert7a/anaconda3/lib/python3.7/site-packages/tornado/gen.py", line 742, in run
    yielded = self.gen.throw(*exc_info)  # type: ignore
  File "/scratch/cnt0024/hmg2840/albert7a/anaconda3/lib/python3.7/site-packages/distributed/core.py", line 864, in connect
    connection_args=self.connection_args,
  File "/scratch/cnt0024/hmg2840/albert7a/anaconda3/lib/python3.7/site-packages/tornado/gen.py", line 735, in run
    value = future.result()
  File "/scratch/cnt0024/hmg2840/albert7a/anaconda3/lib/python3.7/site-packages/tornado/gen.py", line 742, in run
    yielded = self.gen.throw(*exc_info)  # type: ignore
  File "/scratch/cnt0024/hmg2840/albert7a/anaconda3/lib/python3.7/site-packages/distributed/comm/core.py", line 230, in connect
    _raise(error)
  File "/scratch/cnt0024/hmg2840/albert7a/anaconda3/lib/python3.7/site-packages/distributed/comm/core.py", line 207, in _raise
    raise IOError(msg)
OSError: Timed out trying to connect to 'tcp://172.30.100.1:39168' after 10 s: connect() didn't finish in time
tornado.application - ERROR - Exception in callback functools.partial(<bound method IOLoop._discard_future_result of <tornado.platform.asyncio.AsyncIOLoop object at 0x2ba6398a6208>>, <Future finished exception=OSError("Timed out trying to connect to 'tcp://172.30.100.1:39168' after 10 s: connect() didn't finish in time")>)
Traceback (most recent call last):
  File "/scratch/cnt0024/hmg2840/albert7a/anaconda3/lib/python3.7/site-packages/distributed/comm/core.py", line 218, in connect
    quiet_exceptions=EnvironmentError,
  File "/scratch/cnt0024/hmg2840/albert7a/anaconda3/lib/python3.7/site-packages/tornado/gen.py", line 735, in run
    value = future.result()
tornado.util.TimeoutError: Timeout

During handling of the above exception, another exception occurred:

Traceback (most recent call last):
  File "/scratch/cnt0024/hmg2840/albert7a/anaconda3/lib/python3.7/site-packages/tornado/ioloop.py", line 743, in _run_callback
    ret = callback()
  File "/scratch/cnt0024/hmg2840/albert7a/anaconda3/lib/python3.7/site-packages/tornado/ioloop.py", line 767, in _discard_future_result
    future.result()
  File "/scratch/cnt0024/hmg2840/albert7a/anaconda3/lib/python3.7/site-packages/tornado/gen.py", line 742, in run
    yielded = self.gen.throw(*exc_info)  # type: ignore
  File "/scratch/cnt0024/hmg2840/albert7a/anaconda3/lib/python3.7/site-packages/distributed/worker.py", line 748, in heartbeat
    address=self.contact_address, now=time(), metrics=self.get_metrics()
  File "/scratch/cnt0024/hmg2840/albert7a/anaconda3/lib/python3.7/site-packages/tornado/gen.py", line 735, in run
    value = future.result()
  File "/scratch/cnt0024/hmg2840/albert7a/anaconda3/lib/python3.7/site-packages/tornado/gen.py", line 742, in run
    yielded = self.gen.throw(*exc_info)  # type: ignore
  File "/scratch/cnt0024/hmg2840/albert7a/anaconda3/lib/python3.7/site-packages/distributed/core.py", line 736, in send_recv_from_rpc
    comm = yield self.pool.connect(self.addr)
  File "/scratch/cnt0024/hmg2840/albert7a/anaconda3/lib/python3.7/site-packages/tornado/gen.py", line 735, in run
    value = future.result()
  File "/scratch/cnt0024/hmg2840/albert7a/anaconda3/lib/python3.7/site-packages/tornado/gen.py", line 742, in run
    yielded = self.gen.throw(*exc_info)  # type: ignore
  File "/scratch/cnt0024/hmg2840/albert7a/anaconda3/lib/python3.7/site-packages/distributed/core.py", line 864, in connect
    connection_args=self.connection_args,
  File "/scratch/cnt0024/hmg2840/albert7a/anaconda3/lib/python3.7/site-packages/tornado/gen.py", line 735, in run
    value = future.result()
  File "/scratch/cnt0024/hmg2840/albert7a/anaconda3/lib/python3.7/site-packages/tornado/gen.py", line 742, in run
    yielded = self.gen.throw(*exc_info)  # type: ignore
  File "/scratch/cnt0024/hmg2840/albert7a/anaconda3/lib/python3.7/site-packages/distributed/comm/core.py", line 230, in connect
    _raise(error)
  File "/scratch/cnt0024/hmg2840/albert7a/anaconda3/lib/python3.7/site-packages/distributed/comm/core.py", line 207, in _raise
    raise IOError(msg)
OSError: Timed out trying to connect to 'tcp://172.30.100.1:39168' after 10 s: connect() didn't finish in time
tornado.application - ERROR - Exception in callback functools.partial(<bound method IOLoop._discard_future_result of <tornado.platform.asyncio.AsyncIOLoop object at 0x2ba6398a6208>>, <Future finished exception=OSError("Timed out trying to connect to 'tcp://172.30.100.1:39168' after 10 s: connect() didn't finish in time")>)
Traceback (most recent call last):
  File "/scratch/cnt0024/hmg2840/albert7a/anaconda3/lib/python3.7/site-packages/distributed/comm/core.py", line 218, in connect
    quiet_exceptions=EnvironmentError,
  File "/scratch/cnt0024/hmg2840/albert7a/anaconda3/lib/python3.7/site-packages/tornado/gen.py", line 735, in run
    value = future.result()
tornado.util.TimeoutError: Timeout

During handling of the above exception, another exception occurred:

Traceback (most recent call last):
  File "/scratch/cnt0024/hmg2840/albert7a/anaconda3/lib/python3.7/site-packages/tornado/ioloop.py", line 743, in _run_callback
    ret = callback()
  File "/scratch/cnt0024/hmg2840/albert7a/anaconda3/lib/python3.7/site-packages/tornado/ioloop.py", line 767, in _discard_future_result
    future.result()
  File "/scratch/cnt0024/hmg2840/albert7a/anaconda3/lib/python3.7/site-packages/tornado/gen.py", line 742, in run
    yielded = self.gen.throw(*exc_info)  # type: ignore
  File "/scratch/cnt0024/hmg2840/albert7a/anaconda3/lib/python3.7/site-packages/distributed/worker.py", line 748, in heartbeat
    address=self.contact_address, now=time(), metrics=self.get_metrics()
  File "/scratch/cnt0024/hmg2840/albert7a/anaconda3/lib/python3.7/site-packages/tornado/gen.py", line 735, in run
    value = future.result()
  File "/scratch/cnt0024/hmg2840/albert7a/anaconda3/lib/python3.7/site-packages/tornado/gen.py", line 742, in run
    yielded = self.gen.throw(*exc_info)  # type: ignore
  File "/scratch/cnt0024/hmg2840/albert7a/anaconda3/lib/python3.7/site-packages/distributed/core.py", line 736, in send_recv_from_rpc
    comm = yield self.pool.connect(self.addr)
  File "/scratch/cnt0024/hmg2840/albert7a/anaconda3/lib/python3.7/site-packages/tornado/gen.py", line 735, in run
    value = future.result()
  File "/scratch/cnt0024/hmg2840/albert7a/anaconda3/lib/python3.7/site-packages/tornado/gen.py", line 742, in run
    yielded = self.gen.throw(*exc_info)  # type: ignore
  File "/scratch/cnt0024/hmg2840/albert7a/anaconda3/lib/python3.7/site-packages/distributed/core.py", line 864, in connect
    connection_args=self.connection_args,
  File "/scratch/cnt0024/hmg2840/albert7a/anaconda3/lib/python3.7/site-packages/tornado/gen.py", line 735, in run
    value = future.result()
  File "/scratch/cnt0024/hmg2840/albert7a/anaconda3/lib/python3.7/site-packages/tornado/gen.py", line 742, in run
    yielded = self.gen.throw(*exc_info)  # type: ignore
  File "/scratch/cnt0024/hmg2840/albert7a/anaconda3/lib/python3.7/site-packages/distributed/comm/core.py", line 230, in connect
    _raise(error)
  File "/scratch/cnt0024/hmg2840/albert7a/anaconda3/lib/python3.7/site-packages/distributed/comm/core.py", line 207, in _raise
    raise IOError(msg)
OSError: Timed out trying to connect to 'tcp://172.30.100.1:39168' after 10 s: connect() didn't finish in time
tornado.application - ERROR - Exception in callback functools.partial(<bound method IOLoop._discard_future_result of <tornado.platform.asyncio.AsyncIOLoop object at 0x2ba6398a6208>>, <Future finished exception=OSError("Timed out trying to connect to 'tcp://172.30.100.1:39168' after 10 s: connect() didn't finish in time")>)
Traceback (most recent call last):
  File "/scratch/cnt0024/hmg2840/albert7a/anaconda3/lib/python3.7/site-packages/distributed/comm/core.py", line 218, in connect
    quiet_exceptions=EnvironmentError,
  File "/scratch/cnt0024/hmg2840/albert7a/anaconda3/lib/python3.7/site-packages/tornado/gen.py", line 735, in run
    value = future.result()
tornado.util.TimeoutError: Timeout

During handling of the above exception, another exception occurred:

Traceback (most recent call last):
  File "/scratch/cnt0024/hmg2840/albert7a/anaconda3/lib/python3.7/site-packages/tornado/ioloop.py", line 743, in _run_callback
    ret = callback()
  File "/scratch/cnt0024/hmg2840/albert7a/anaconda3/lib/python3.7/site-packages/tornado/ioloop.py", line 767, in _discard_future_result
    future.result()
  File "/scratch/cnt0024/hmg2840/albert7a/anaconda3/lib/python3.7/site-packages/tornado/gen.py", line 742, in run
    yielded = self.gen.throw(*exc_info)  # type: ignore
  File "/scratch/cnt0024/hmg2840/albert7a/anaconda3/lib/python3.7/site-packages/distributed/worker.py", line 748, in heartbeat
    address=self.contact_address, now=time(), metrics=self.get_metrics()
  File "/scratch/cnt0024/hmg2840/albert7a/anaconda3/lib/python3.7/site-packages/tornado/gen.py", line 735, in run
    value = future.result()
  File "/scratch/cnt0024/hmg2840/albert7a/anaconda3/lib/python3.7/site-packages/tornado/gen.py", line 742, in run
    yielded = self.gen.throw(*exc_info)  # type: ignore
  File "/scratch/cnt0024/hmg2840/albert7a/anaconda3/lib/python3.7/site-packages/distributed/core.py", line 736, in send_recv_from_rpc
    comm = yield self.pool.connect(self.addr)
  File "/scratch/cnt0024/hmg2840/albert7a/anaconda3/lib/python3.7/site-packages/tornado/gen.py", line 735, in run
    value = future.result()
  File "/scratch/cnt0024/hmg2840/albert7a/anaconda3/lib/python3.7/site-packages/tornado/gen.py", line 742, in run
    yielded = self.gen.throw(*exc_info)  # type: ignore
  File "/scratch/cnt0024/hmg2840/albert7a/anaconda3/lib/python3.7/site-packages/distributed/core.py", line 864, in connect
    connection_args=self.connection_args,
  File "/scratch/cnt0024/hmg2840/albert7a/anaconda3/lib/python3.7/site-packages/tornado/gen.py", line 735, in run
    value = future.result()
  File "/scratch/cnt0024/hmg2840/albert7a/anaconda3/lib/python3.7/site-packages/tornado/gen.py", line 742, in run
    yielded = self.gen.throw(*exc_info)  # type: ignore
  File "/scratch/cnt0024/hmg2840/albert7a/anaconda3/lib/python3.7/site-packages/distributed/comm/core.py", line 230, in connect
    _raise(error)
  File "/scratch/cnt0024/hmg2840/albert7a/anaconda3/lib/python3.7/site-packages/distributed/comm/core.py", line 207, in _raise
    raise IOError(msg)
OSError: Timed out trying to connect to 'tcp://172.30.100.1:39168' after 10 s: connect() didn't finish in time
tornado.application - ERROR - Exception in callback functools.partial(<bound method IOLoop._discard_future_result of <tornado.platform.asyncio.AsyncIOLoop object at 0x2ba6398a6208>>, <Future finished exception=OSError("Timed out trying to connect to 'tcp://172.30.100.1:39168' after 10 s: connect() didn't finish in time")>)
Traceback (most recent call last):
  File "/scratch/cnt0024/hmg2840/albert7a/anaconda3/lib/python3.7/site-packages/distributed/comm/core.py", line 218, in connect
    quiet_exceptions=EnvironmentError,
  File "/scratch/cnt0024/hmg2840/albert7a/anaconda3/lib/python3.7/site-packages/tornado/gen.py", line 735, in run
    value = future.result()
tornado.util.TimeoutError: Timeout

During handling of the above exception, another exception occurred:

Traceback (most recent call last):
  File "/scratch/cnt0024/hmg2840/albert7a/anaconda3/lib/python3.7/site-packages/tornado/ioloop.py", line 743, in _run_callback
    ret = callback()
  File "/scratch/cnt0024/hmg2840/albert7a/anaconda3/lib/python3.7/site-packages/tornado/ioloop.py", line 767, in _discard_future_result
    future.result()
  File "/scratch/cnt0024/hmg2840/albert7a/anaconda3/lib/python3.7/site-packages/tornado/gen.py", line 742, in run
    yielded = self.gen.throw(*exc_info)  # type: ignore
  File "/scratch/cnt0024/hmg2840/albert7a/anaconda3/lib/python3.7/site-packages/distributed/worker.py", line 748, in heartbeat
    address=self.contact_address, now=time(), metrics=self.get_metrics()
  File "/scratch/cnt0024/hmg2840/albert7a/anaconda3/lib/python3.7/site-packages/tornado/gen.py", line 735, in run
    value = future.result()
  File "/scratch/cnt0024/hmg2840/albert7a/anaconda3/lib/python3.7/site-packages/tornado/gen.py", line 742, in run
    yielded = self.gen.throw(*exc_info)  # type: ignore
  File "/scratch/cnt0024/hmg2840/albert7a/anaconda3/lib/python3.7/site-packages/distributed/core.py", line 736, in send_recv_from_rpc
    comm = yield self.pool.connect(self.addr)
  File "/scratch/cnt0024/hmg2840/albert7a/anaconda3/lib/python3.7/site-packages/tornado/gen.py", line 735, in run
    value = future.result()
  File "/scratch/cnt0024/hmg2840/albert7a/anaconda3/lib/python3.7/site-packages/tornado/gen.py", line 742, in run
    yielded = self.gen.throw(*exc_info)  # type: ignore
  File "/scratch/cnt0024/hmg2840/albert7a/anaconda3/lib/python3.7/site-packages/distributed/core.py", line 864, in connect
    connection_args=self.connection_args,
  File "/scratch/cnt0024/hmg2840/albert7a/anaconda3/lib/python3.7/site-packages/tornado/gen.py", line 735, in run
    value = future.result()
  File "/scratch/cnt0024/hmg2840/albert7a/anaconda3/lib/python3.7/site-packages/tornado/gen.py", line 742, in run
    yielded = self.gen.throw(*exc_info)  # type: ignore
  File "/scratch/cnt0024/hmg2840/albert7a/anaconda3/lib/python3.7/site-packages/distributed/comm/core.py", line 230, in connect
    _raise(error)
  File "/scratch/cnt0024/hmg2840/albert7a/anaconda3/lib/python3.7/site-packages/distributed/comm/core.py", line 207, in _raise
    raise IOError(msg)
OSError: Timed out trying to connect to 'tcp://172.30.100.1:39168' after 10 s: connect() didn't finish in time
tornado.application - ERROR - Exception in callback functools.partial(<bound method IOLoop._discard_future_result of <tornado.platform.asyncio.AsyncIOLoop object at 0x2ba6398a6208>>, <Future finished exception=OSError("Timed out trying to connect to 'tcp://172.30.100.1:39168' after 10 s: connect() didn't finish in time")>)
Traceback (most recent call last):
  File "/scratch/cnt0024/hmg2840/albert7a/anaconda3/lib/python3.7/site-packages/distributed/comm/core.py", line 218, in connect
    quiet_exceptions=EnvironmentError,
  File "/scratch/cnt0024/hmg2840/albert7a/anaconda3/lib/python3.7/site-packages/tornado/gen.py", line 735, in run
    value = future.result()
tornado.util.TimeoutError: Timeout

During handling of the above exception, another exception occurred:

Traceback (most recent call last):
  File "/scratch/cnt0024/hmg2840/albert7a/anaconda3/lib/python3.7/site-packages/tornado/ioloop.py", line 743, in _run_callback
    ret = callback()
  File "/scratch/cnt0024/hmg2840/albert7a/anaconda3/lib/python3.7/site-packages/tornado/ioloop.py", line 767, in _discard_future_result
    future.result()
  File "/scratch/cnt0024/hmg2840/albert7a/anaconda3/lib/python3.7/site-packages/tornado/gen.py", line 742, in run
    yielded = self.gen.throw(*exc_info)  # type: ignore
  File "/scratch/cnt0024/hmg2840/albert7a/anaconda3/lib/python3.7/site-packages/distributed/worker.py", line 748, in heartbeat
    address=self.contact_address, now=time(), metrics=self.get_metrics()
  File "/scratch/cnt0024/hmg2840/albert7a/anaconda3/lib/python3.7/site-packages/tornado/gen.py", line 735, in run
    value = future.result()
  File "/scratch/cnt0024/hmg2840/albert7a/anaconda3/lib/python3.7/site-packages/tornado/gen.py", line 742, in run
    yielded = self.gen.throw(*exc_info)  # type: ignore
  File "/scratch/cnt0024/hmg2840/albert7a/anaconda3/lib/python3.7/site-packages/distributed/core.py", line 736, in send_recv_from_rpc
    comm = yield self.pool.connect(self.addr)
  File "/scratch/cnt0024/hmg2840/albert7a/anaconda3/lib/python3.7/site-packages/tornado/gen.py", line 735, in run
    value = future.result()
  File "/scratch/cnt0024/hmg2840/albert7a/anaconda3/lib/python3.7/site-packages/tornado/gen.py", line 742, in run
    yielded = self.gen.throw(*exc_info)  # type: ignore
  File "/scratch/cnt0024/hmg2840/albert7a/anaconda3/lib/python3.7/site-packages/distributed/core.py", line 864, in connect
    connection_args=self.connection_args,
  File "/scratch/cnt0024/hmg2840/albert7a/anaconda3/lib/python3.7/site-packages/tornado/gen.py", line 735, in run
    value = future.result()
  File "/scratch/cnt0024/hmg2840/albert7a/anaconda3/lib/python3.7/site-packages/tornado/gen.py", line 742, in run
    yielded = self.gen.throw(*exc_info)  # type: ignore
  File "/scratch/cnt0024/hmg2840/albert7a/anaconda3/lib/python3.7/site-packages/distributed/comm/core.py", line 230, in connect
    _raise(error)
  File "/scratch/cnt0024/hmg2840/albert7a/anaconda3/lib/python3.7/site-packages/distributed/comm/core.py", line 207, in _raise
    raise IOError(msg)
OSError: Timed out trying to connect to 'tcp://172.30.100.1:39168' after 10 s: connect() didn't finish in time
/scratch/cnt0024/hmg2840/albert7a/anaconda3/lib/python3.7/site-packages/dask/array/numpy_compat.py:28: RuntimeWarning: invalid value encountered in true_divide
  x = np.divide(x1, x2, out)
tornado.application - ERROR - Exception in callback functools.partial(<bound method IOLoop._discard_future_result of <tornado.platform.asyncio.AsyncIOLoop object at 0x2ba6398a6208>>, <Future finished exception=OSError("Timed out trying to connect to 'tcp://172.30.100.1:39168' after 10 s: connect() didn't finish in time")>)
Traceback (most recent call last):
  File "/scratch/cnt0024/hmg2840/albert7a/anaconda3/lib/python3.7/site-packages/distributed/comm/core.py", line 218, in connect
    quiet_exceptions=EnvironmentError,
  File "/scratch/cnt0024/hmg2840/albert7a/anaconda3/lib/python3.7/site-packages/tornado/gen.py", line 735, in run
    value = future.result()
tornado.util.TimeoutError: Timeout

During handling of the above exception, another exception occurred:

Traceback (most recent call last):
  File "/scratch/cnt0024/hmg2840/albert7a/anaconda3/lib/python3.7/site-packages/tornado/ioloop.py", line 743, in _run_callback
    ret = callback()
  File "/scratch/cnt0024/hmg2840/albert7a/anaconda3/lib/python3.7/site-packages/tornado/ioloop.py", line 767, in _discard_future_result
    future.result()
  File "/scratch/cnt0024/hmg2840/albert7a/anaconda3/lib/python3.7/site-packages/tornado/gen.py", line 742, in run
    yielded = self.gen.throw(*exc_info)  # type: ignore
  File "/scratch/cnt0024/hmg2840/albert7a/anaconda3/lib/python3.7/site-packages/distributed/worker.py", line 748, in heartbeat
    address=self.contact_address, now=time(), metrics=self.get_metrics()
  File "/scratch/cnt0024/hmg2840/albert7a/anaconda3/lib/python3.7/site-packages/tornado/gen.py", line 735, in run
    value = future.result()
  File "/scratch/cnt0024/hmg2840/albert7a/anaconda3/lib/python3.7/site-packages/tornado/gen.py", line 742, in run
    yielded = self.gen.throw(*exc_info)  # type: ignore
  File "/scratch/cnt0024/hmg2840/albert7a/anaconda3/lib/python3.7/site-packages/distributed/core.py", line 736, in send_recv_from_rpc
    comm = yield self.pool.connect(self.addr)
  File "/scratch/cnt0024/hmg2840/albert7a/anaconda3/lib/python3.7/site-packages/tornado/gen.py", line 735, in run
    value = future.result()
  File "/scratch/cnt0024/hmg2840/albert7a/anaconda3/lib/python3.7/site-packages/tornado/gen.py", line 742, in run
    yielded = self.gen.throw(*exc_info)  # type: ignore
  File "/scratch/cnt0024/hmg2840/albert7a/anaconda3/lib/python3.7/site-packages/distributed/core.py", line 864, in connect
    connection_args=self.connection_args,
  File "/scratch/cnt0024/hmg2840/albert7a/anaconda3/lib/python3.7/site-packages/tornado/gen.py", line 735, in run
    value = future.result()
  File "/scratch/cnt0024/hmg2840/albert7a/anaconda3/lib/python3.7/site-packages/tornado/gen.py", line 742, in run
    yielded = self.gen.throw(*exc_info)  # type: ignore
  File "/scratch/cnt0024/hmg2840/albert7a/anaconda3/lib/python3.7/site-packages/distributed/comm/core.py", line 230, in connect
    _raise(error)
  File "/scratch/cnt0024/hmg2840/albert7a/anaconda3/lib/python3.7/site-packages/distributed/comm/core.py", line 207, in _raise
    raise IOError(msg)
OSError: Timed out trying to connect to 'tcp://172.30.100.1:39168' after 10 s: connect() didn't finish in time
tornado.application - ERROR - Exception in callback functools.partial(<bound method IOLoop._discard_future_result of <tornado.platform.asyncio.AsyncIOLoop object at 0x2ba6398a6208>>, <Future finished exception=OSError("Timed out trying to connect to 'tcp://172.30.100.1:39168' after 10 s: connect() didn't finish in time")>)
Traceback (most recent call last):
  File "/scratch/cnt0024/hmg2840/albert7a/anaconda3/lib/python3.7/site-packages/distributed/comm/core.py", line 218, in connect
    quiet_exceptions=EnvironmentError,
  File "/scratch/cnt0024/hmg2840/albert7a/anaconda3/lib/python3.7/site-packages/tornado/gen.py", line 735, in run
    value = future.result()
tornado.util.TimeoutError: Timeout

During handling of the above exception, another exception occurred:

Traceback (most recent call last):
  File "/scratch/cnt0024/hmg2840/albert7a/anaconda3/lib/python3.7/site-packages/tornado/ioloop.py", line 743, in _run_callback
    ret = callback()
  File "/scratch/cnt0024/hmg2840/albert7a/anaconda3/lib/python3.7/site-packages/tornado/ioloop.py", line 767, in _discard_future_result
    future.result()
  File "/scratch/cnt0024/hmg2840/albert7a/anaconda3/lib/python3.7/site-packages/tornado/gen.py", line 742, in run
    yielded = self.gen.throw(*exc_info)  # type: ignore
  File "/scratch/cnt0024/hmg2840/albert7a/anaconda3/lib/python3.7/site-packages/distributed/worker.py", line 748, in heartbeat
    address=self.contact_address, now=time(), metrics=self.get_metrics()
  File "/scratch/cnt0024/hmg2840/albert7a/anaconda3/lib/python3.7/site-packages/tornado/gen.py", line 735, in run
    value = future.result()
  File "/scratch/cnt0024/hmg2840/albert7a/anaconda3/lib/python3.7/site-packages/tornado/gen.py", line 742, in run
    yielded = self.gen.throw(*exc_info)  # type: ignore
  File "/scratch/cnt0024/hmg2840/albert7a/anaconda3/lib/python3.7/site-packages/distributed/core.py", line 736, in send_recv_from_rpc
    comm = yield self.pool.connect(self.addr)
  File "/scratch/cnt0024/hmg2840/albert7a/anaconda3/lib/python3.7/site-packages/tornado/gen.py", line 735, in run
    value = future.result()
  File "/scratch/cnt0024/hmg2840/albert7a/anaconda3/lib/python3.7/site-packages/tornado/gen.py", line 742, in run
    yielded = self.gen.throw(*exc_info)  # type: ignore
  File "/scratch/cnt0024/hmg2840/albert7a/anaconda3/lib/python3.7/site-packages/distributed/core.py", line 864, in connect
    connection_args=self.connection_args,
  File "/scratch/cnt0024/hmg2840/albert7a/anaconda3/lib/python3.7/site-packages/tornado/gen.py", line 735, in run
    value = future.result()
  File "/scratch/cnt0024/hmg2840/albert7a/anaconda3/lib/python3.7/site-packages/tornado/gen.py", line 742, in run
    yielded = self.gen.throw(*exc_info)  # type: ignore
  File "/scratch/cnt0024/hmg2840/albert7a/anaconda3/lib/python3.7/site-packages/distributed/comm/core.py", line 230, in connect
    _raise(error)
  File "/scratch/cnt0024/hmg2840/albert7a/anaconda3/lib/python3.7/site-packages/distributed/comm/core.py", line 207, in _raise
    raise IOError(msg)
OSError: Timed out trying to connect to 'tcp://172.30.100.1:39168' after 10 s: connect() didn't finish in time
distributed.comm.tcp - WARNING - Closing dangling stream in <TCP  local=tcp://172.30.6.161:51902 remote=tcp://172.30.100.1:39168>
distributed.comm.tcp - WARNING - Closing dangling stream in <TCP  local=tcp://172.30.6.161:52006 remote=tcp://172.30.100.1:39168>
distributed.comm.tcp - WARNING - Closing dangling stream in <TCP  local=tcp://172.30.6.161:51904 remote=tcp://172.30.100.1:39168>
distributed.comm.tcp - WARNING - Closing dangling stream in <TCP  local=tcp://172.30.6.161:51880 remote=tcp://172.30.100.1:39168>
distributed.comm.tcp - WARNING - Closing dangling stream in <TCP  local=tcp://172.30.6.161:52000 remote=tcp://172.30.100.1:39168>
distributed.comm.tcp - WARNING - Closing dangling stream in <TCP  local=tcp://172.30.6.161:51938 remote=tcp://172.30.100.1:39168>
distributed.utils_perf - INFO - full garbage collection released 21.02 MB from 498 reference cycles (threshold: 10.00 MB)
distributed.comm.tcp - WARNING - Closing dangling stream in <TCP  local=tcp://172.30.6.161:51874 remote=tcp://172.30.100.1:39168>
distributed.worker - INFO - Stopping worker at tcp://172.30.6.161:34634
distributed.worker - INFO - Stopping worker at tcp://172.30.6.161:35610
distributed.worker - INFO - Stopping worker at tcp://172.30.6.161:35869
/scratch/cnt0024/hmg2840/albert7a/anaconda3/lib/python3.7/site-packages/dask/array/numpy_compat.py:28: RuntimeWarning: invalid value encountered in true_divide
  x = np.divide(x1, x2, out)
distributed.worker - INFO - Stopping worker at tcp://172.30.6.161:34478
distributed.worker - INFO - Stopping worker at tcp://172.30.6.161:36673
distributed.worker - INFO - Stopping worker at tcp://172.30.6.161:37297
distributed.worker - INFO - Stopping worker at tcp://172.30.6.161:38258
distributed.worker - INFO - Stopping worker at tcp://172.30.6.161:33642
distributed.worker - INFO - Stopping worker at tcp://172.30.6.161:38483
/scratch/cnt0024/hmg2840/albert7a/anaconda3/lib/python3.7/site-packages/dask/array/numpy_compat.py:28: RuntimeWarning: invalid value encountered in true_divide
  x = np.divide(x1, x2, out)
distributed.worker - INFO - Stopping worker at tcp://172.30.6.161:37722
distributed.worker - INFO - Stopping worker at tcp://172.30.6.161:36542
distributed.worker - INFO - Stopping worker at tcp://172.30.6.161:39291
distributed.worker - INFO - Stopping worker at tcp://172.30.6.161:38872
distributed.worker - INFO - Stopping worker at tcp://172.30.6.161:39387
distributed.worker - INFO - Stopping worker at tcp://172.30.6.161:39987
distributed.worker - INFO - Stopping worker at tcp://172.30.6.161:40803
distributed.worker - INFO - Stopping worker at tcp://172.30.6.161:41337
distributed.worker - INFO - Stopping worker at tcp://172.30.6.161:44589
distributed.worker - INFO - Stopping worker at tcp://172.30.6.161:42037
distributed.worker - INFO - Stopping worker at tcp://172.30.6.161:43533
distributed.worker - INFO - Stopping worker at tcp://172.30.6.161:40828
distributed.worker - INFO - Stopping worker at tcp://172.30.6.161:45083
distributed.worker - INFO - Stopping worker at tcp://172.30.6.161:41028
distributed.worker - INFO - Stopping worker at tcp://172.30.6.161:42855
distributed.worker - INFO - Stopping worker at tcp://172.30.6.161:45426
distributed.worker - INFO - Stopping worker at tcp://172.30.6.161:42713
distributed.worker - INFO - Stopping worker at tcp://172.30.6.161:44269
distributed.worker - INFO - Stopping worker at tcp://172.30.6.161:46646
distributed.worker - INFO - Connection to scheduler broken.  Reconnecting...
distributed.worker - INFO - -------------------------------------------------
distributed.worker - INFO - Connection to scheduler broken.  Reconnecting...
distributed.worker - INFO - -------------------------------------------------
distributed.nanny - INFO - Closing Nanny at 'tcp://172.30.6.161:37750'
distributed.worker - INFO - Connection to scheduler broken.  Reconnecting...
distributed.worker - INFO - -------------------------------------------------
distributed.nanny - INFO - Closing Nanny at 'tcp://172.30.6.161:40182'
distributed.nanny - INFO - Closing Nanny at 'tcp://172.30.6.161:35340'
distributed.worker - INFO - Connection to scheduler broken.  Reconnecting...
distributed.worker - INFO - -------------------------------------------------
distributed.worker - INFO - Connection to scheduler broken.  Reconnecting...
distributed.worker - INFO - -------------------------------------------------
distributed.worker - INFO - Connection to scheduler broken.  Reconnecting...
distributed.worker - INFO - -------------------------------------------------
distributed.worker - INFO - Connection to scheduler broken.  Reconnecting...
distributed.worker - INFO - -------------------------------------------------
distributed.worker - INFO - Connection to scheduler broken.  Reconnecting...
distributed.worker - INFO - -------------------------------------------------
distributed.worker - INFO - Connection to scheduler broken.  Reconnecting...
distributed.worker - INFO - Connection to scheduler broken.  Reconnecting...
distributed.worker - INFO - -------------------------------------------------
distributed.worker - INFO - -------------------------------------------------
distributed.worker - INFO - Connection to scheduler broken.  Reconnecting...
distributed.worker - INFO - -------------------------------------------------
distributed.worker - INFO - Connection to scheduler broken.  Reconnecting...
distributed.worker - INFO - -------------------------------------------------
distributed.worker - INFO - Connection to scheduler broken.  Reconnecting...
distributed.worker - INFO - -------------------------------------------------
distributed.worker - INFO - Connection to scheduler broken.  Reconnecting...
distributed.worker - INFO - Connection to scheduler broken.  Reconnecting...
distributed.worker - INFO - -------------------------------------------------
distributed.worker - INFO - -------------------------------------------------
distributed.worker - INFO - Connection to scheduler broken.  Reconnecting...
distributed.worker - INFO - Connection to scheduler broken.  Reconnecting...
distributed.worker - INFO - -------------------------------------------------
distributed.worker - INFO - -------------------------------------------------
distributed.worker - INFO - Connection to scheduler broken.  Reconnecting...
distributed.worker - INFO - -------------------------------------------------
distributed.worker - INFO - Connection to scheduler broken.  Reconnecting...
distributed.worker - INFO - -------------------------------------------------
distributed.worker - INFO - Connection to scheduler broken.  Reconnecting...
distributed.worker - INFO - -------------------------------------------------
distributed.worker - INFO - Connection to scheduler broken.  Reconnecting...
distributed.worker - INFO - Connection to scheduler broken.  Reconnecting...
distributed.worker - INFO - -------------------------------------------------
distributed.worker - INFO - -------------------------------------------------
distributed.worker - INFO - Connection to scheduler broken.  Reconnecting...
distributed.worker - INFO - -------------------------------------------------
distributed.worker - INFO - Connection to scheduler broken.  Reconnecting...
distributed.worker - INFO - -------------------------------------------------
distributed.worker - INFO - Connection to scheduler broken.  Reconnecting...
distributed.worker - INFO - -------------------------------------------------
distributed.worker - INFO - Connection to scheduler broken.  Reconnecting...
distributed.worker - INFO - -------------------------------------------------
distributed.nanny - INFO - Closing Nanny at 'tcp://172.30.6.161:45583'
distributed.worker - INFO - Connection to scheduler broken.  Reconnecting...
distributed.worker - INFO - -------------------------------------------------
distributed.nanny - INFO - Closing Nanny at 'tcp://172.30.6.161:46060'
distributed.worker - INFO - Connection to scheduler broken.  Reconnecting...
distributed.worker - INFO - -------------------------------------------------
distributed.nanny - INFO - Closing Nanny at 'tcp://172.30.6.161:34724'
distributed.nanny - INFO - Closing Nanny at 'tcp://172.30.6.161:43509'
distributed.nanny - INFO - Closing Nanny at 'tcp://172.30.6.161:38443'
distributed.nanny - INFO - Closing Nanny at 'tcp://172.30.6.161:43513'
distributed.nanny - INFO - Closing Nanny at 'tcp://172.30.6.161:37836'
distributed.nanny - INFO - Closing Nanny at 'tcp://172.30.6.161:36084'
distributed.nanny - INFO - Closing Nanny at 'tcp://172.30.6.161:39858'
distributed.nanny - INFO - Closing Nanny at 'tcp://172.30.6.161:41607'
distributed.nanny - INFO - Closing Nanny at 'tcp://172.30.6.161:44605'
distributed.nanny - INFO - Closing Nanny at 'tcp://172.30.6.161:36365'
distributed.nanny - INFO - Closing Nanny at 'tcp://172.30.6.161:34269'
distributed.nanny - INFO - Closing Nanny at 'tcp://172.30.6.161:33209'
distributed.nanny - INFO - Closing Nanny at 'tcp://172.30.6.161:37110'
distributed.nanny - INFO - Closing Nanny at 'tcp://172.30.6.161:42262'
distributed.nanny - INFO - Closing Nanny at 'tcp://172.30.6.161:36431'
distributed.nanny - INFO - Closing Nanny at 'tcp://172.30.6.161:34750'
distributed.nanny - INFO - Closing Nanny at 'tcp://172.30.6.161:35116'
distributed.nanny - INFO - Closing Nanny at 'tcp://172.30.6.161:46498'
distributed.nanny - INFO - Closing Nanny at 'tcp://172.30.6.161:34452'
distributed.nanny - INFO - Closing Nanny at 'tcp://172.30.6.161:46241'
distributed.nanny - INFO - Closing Nanny at 'tcp://172.30.6.161:33479'
distributed.nanny - INFO - Closing Nanny at 'tcp://172.30.6.161:40222'
distributed.nanny - INFO - Closing Nanny at 'tcp://172.30.6.161:36736'
distributed.dask_worker - INFO - End worker
/scratch/cnt0024/hmg2840/albert7a/anaconda3/lib/python3.7/site-packages/dask/config.py:168: YAMLLoadWarning: calling yaml.load() without Loader=... is deprecated, as the default Loader is unsafe. Please read https://msg.pyyaml.org/load for full details.
  data = yaml.load(f.read()) or {}
/scratch/cnt0024/hmg2840/albert7a/anaconda3/lib/python3.7/site-packages/distributed/utils.py:136: RuntimeWarning: Couldn't detect a suitable IP address for reaching '8.8.8.8', defaulting to '127.0.0.1': [Errno 101] Network is unreachable
  RuntimeWarning,
