/scratch/cnt0024/hmg2840/albert7a/anaconda3/lib/python3.7/site-packages/dask/config.py:168: YAMLLoadWarning: calling yaml.load() without Loader=... is deprecated, as the default Loader is unsafe. Please read https://msg.pyyaml.org/load for full details.
  data = yaml.load(f.read()) or {}
/scratch/cnt0024/hmg2840/albert7a/anaconda3/lib/python3.7/site-packages/distributed/utils.py:136: RuntimeWarning: Couldn't detect a suitable IP address for reaching '8.8.8.8', defaulting to '127.0.0.1': [Errno 101] Network is unreachable
  RuntimeWarning,
distributed.nanny - INFO -         Start Nanny at: 'tcp://172.30.6.158:36775'
distributed.nanny - INFO -         Start Nanny at: 'tcp://172.30.6.158:35237'
distributed.nanny - INFO -         Start Nanny at: 'tcp://172.30.6.158:37505'
distributed.nanny - INFO -         Start Nanny at: 'tcp://172.30.6.158:46145'
distributed.nanny - INFO -         Start Nanny at: 'tcp://172.30.6.158:46722'
distributed.nanny - INFO -         Start Nanny at: 'tcp://172.30.6.158:43776'
distributed.nanny - INFO -         Start Nanny at: 'tcp://172.30.6.158:38025'
distributed.nanny - INFO -         Start Nanny at: 'tcp://172.30.6.158:44135'
distributed.nanny - INFO -         Start Nanny at: 'tcp://172.30.6.158:44800'
distributed.nanny - INFO -         Start Nanny at: 'tcp://172.30.6.158:39630'
distributed.nanny - INFO -         Start Nanny at: 'tcp://172.30.6.158:41327'
distributed.nanny - INFO -         Start Nanny at: 'tcp://172.30.6.158:43913'
distributed.nanny - INFO -         Start Nanny at: 'tcp://172.30.6.158:43973'
distributed.nanny - INFO -         Start Nanny at: 'tcp://172.30.6.158:40248'
distributed.nanny - INFO -         Start Nanny at: 'tcp://172.30.6.158:34789'
distributed.nanny - INFO -         Start Nanny at: 'tcp://172.30.6.158:34144'
distributed.nanny - INFO -         Start Nanny at: 'tcp://172.30.6.158:38610'
distributed.nanny - INFO -         Start Nanny at: 'tcp://172.30.6.158:39324'
distributed.nanny - INFO -         Start Nanny at: 'tcp://172.30.6.158:38181'
distributed.nanny - INFO -         Start Nanny at: 'tcp://172.30.6.158:38294'
distributed.nanny - INFO -         Start Nanny at: 'tcp://172.30.6.158:44107'
distributed.nanny - INFO -         Start Nanny at: 'tcp://172.30.6.158:40275'
distributed.nanny - INFO -         Start Nanny at: 'tcp://172.30.6.158:44860'
distributed.nanny - INFO -         Start Nanny at: 'tcp://172.30.6.158:40119'
distributed.nanny - INFO -         Start Nanny at: 'tcp://172.30.6.158:34167'
distributed.nanny - INFO -         Start Nanny at: 'tcp://172.30.6.158:43798'
distributed.nanny - INFO -         Start Nanny at: 'tcp://172.30.6.158:33563'
distributed.nanny - INFO -         Start Nanny at: 'tcp://172.30.6.158:36124'
/scratch/cnt0024/hmg2840/albert7a/anaconda3/lib/python3.7/site-packages/dask/config.py:168: YAMLLoadWarning: calling yaml.load() without Loader=... is deprecated, as the default Loader is unsafe. Please read https://msg.pyyaml.org/load for full details.
  data = yaml.load(f.read()) or {}
/scratch/cnt0024/hmg2840/albert7a/anaconda3/lib/python3.7/site-packages/distributed/utils.py:136: RuntimeWarning: Couldn't detect a suitable IP address for reaching '8.8.8.8', defaulting to '127.0.0.1': [Errno 101] Network is unreachable
  RuntimeWarning,
distributed.worker - INFO -       Start worker at:   tcp://172.30.6.158:38341
distributed.worker - INFO -          Listening to:   tcp://172.30.6.158:38341
distributed.worker - INFO -              nanny at:         172.30.6.158:40119
distributed.worker - INFO -              bokeh at:         172.30.6.158:42848
distributed.worker - INFO - Waiting to connect to:   tcp://172.30.100.1:39168
distributed.worker - INFO - -------------------------------------------------
distributed.worker - INFO -               Threads:                          1
distributed.worker - INFO -                Memory:                    4.29 GB
distributed.worker - INFO -       Local Directory: /scratch/cnt0024/hmg2840/albert7a/daskjobqueue/worker-p02epmea
distributed.worker - INFO - -------------------------------------------------
/scratch/cnt0024/hmg2840/albert7a/anaconda3/lib/python3.7/site-packages/dask/config.py:168: YAMLLoadWarning: calling yaml.load() without Loader=... is deprecated, as the default Loader is unsafe. Please read https://msg.pyyaml.org/load for full details.
  data = yaml.load(f.read()) or {}
/scratch/cnt0024/hmg2840/albert7a/anaconda3/lib/python3.7/site-packages/distributed/utils.py:136: RuntimeWarning: Couldn't detect a suitable IP address for reaching '8.8.8.8', defaulting to '127.0.0.1': [Errno 101] Network is unreachable
  RuntimeWarning,
distributed.worker - INFO -       Start worker at:   tcp://172.30.6.158:40482
distributed.worker - INFO -          Listening to:   tcp://172.30.6.158:40482
distributed.worker - INFO -              nanny at:         172.30.6.158:38025
/scratch/cnt0024/hmg2840/albert7a/anaconda3/lib/python3.7/site-packages/dask/config.py:168: YAMLLoadWarning: calling yaml.load() without Loader=... is deprecated, as the default Loader is unsafe. Please read https://msg.pyyaml.org/load for full details.
  data = yaml.load(f.read()) or {}
/scratch/cnt0024/hmg2840/albert7a/anaconda3/lib/python3.7/site-packages/distributed/utils.py:136: RuntimeWarning: Couldn't detect a suitable IP address for reaching '8.8.8.8', defaulting to '127.0.0.1': [Errno 101] Network is unreachable
  RuntimeWarning,
distributed.worker - INFO -       Start worker at:   tcp://172.30.6.158:34429
distributed.worker - INFO -              bokeh at:         172.30.6.158:46869
distributed.worker - INFO -          Listening to:   tcp://172.30.6.158:34429
distributed.worker - INFO - Waiting to connect to:   tcp://172.30.100.1:39168
distributed.worker - INFO -              nanny at:         172.30.6.158:37505
distributed.worker - INFO -              bokeh at:         172.30.6.158:38122
distributed.worker - INFO - -------------------------------------------------
distributed.worker - INFO - Waiting to connect to:   tcp://172.30.100.1:39168
distributed.worker - INFO - -------------------------------------------------
distributed.worker - INFO -               Threads:                          1
distributed.worker - INFO -                Memory:                    4.29 GB
distributed.worker - INFO -       Local Directory: /scratch/cnt0024/hmg2840/albert7a/daskjobqueue/worker-_zbu3qlj
distributed.worker - INFO - -------------------------------------------------
distributed.worker - INFO -               Threads:                          1
distributed.worker - INFO -                Memory:                    4.29 GB
/scratch/cnt0024/hmg2840/albert7a/anaconda3/lib/python3.7/site-packages/dask/config.py:168: YAMLLoadWarning: calling yaml.load() without Loader=... is deprecated, as the default Loader is unsafe. Please read https://msg.pyyaml.org/load for full details.
  data = yaml.load(f.read()) or {}
/scratch/cnt0024/hmg2840/albert7a/anaconda3/lib/python3.7/site-packages/distributed/utils.py:136: RuntimeWarning: Couldn't detect a suitable IP address for reaching '8.8.8.8', defaulting to '127.0.0.1': [Errno 101] Network is unreachable
  RuntimeWarning,
distributed.worker - INFO -       Start worker at:   tcp://172.30.6.158:43903
distributed.worker - INFO -          Listening to:   tcp://172.30.6.158:43903
distributed.worker - INFO -       Local Directory: /scratch/cnt0024/hmg2840/albert7a/daskjobqueue/worker-2slee7mw
distributed.worker - INFO -              nanny at:         172.30.6.158:36775
distributed.worker - INFO -              bokeh at:         172.30.6.158:32887
distributed.worker - INFO - -------------------------------------------------
distributed.worker - INFO - Waiting to connect to:   tcp://172.30.100.1:39168
distributed.worker - INFO - -------------------------------------------------
distributed.worker - INFO -               Threads:                          1
distributed.worker - INFO -                Memory:                    4.29 GB
distributed.worker - INFO -       Local Directory: /scratch/cnt0024/hmg2840/albert7a/daskjobqueue/worker-hpjrg4fj
distributed.worker - INFO - -------------------------------------------------
/scratch/cnt0024/hmg2840/albert7a/anaconda3/lib/python3.7/site-packages/dask/config.py:168: YAMLLoadWarning: calling yaml.load() without Loader=... is deprecated, as the default Loader is unsafe. Please read https://msg.pyyaml.org/load for full details.
  data = yaml.load(f.read()) or {}
/scratch/cnt0024/hmg2840/albert7a/anaconda3/lib/python3.7/site-packages/distributed/utils.py:136: RuntimeWarning: Couldn't detect a suitable IP address for reaching '8.8.8.8', defaulting to '127.0.0.1': [Errno 101] Network is unreachable
  RuntimeWarning,
distributed.worker - INFO -       Start worker at:   tcp://172.30.6.158:35514
distributed.worker - INFO -          Listening to:   tcp://172.30.6.158:35514
distributed.worker - INFO -              nanny at:         172.30.6.158:44800
distributed.worker - INFO -              bokeh at:         172.30.6.158:40840
distributed.worker - INFO - Waiting to connect to:   tcp://172.30.100.1:39168
distributed.worker - INFO - -------------------------------------------------
distributed.worker - INFO -               Threads:                          1
distributed.worker - INFO -                Memory:                    4.29 GB
distributed.worker - INFO -       Local Directory: /scratch/cnt0024/hmg2840/albert7a/daskjobqueue/worker-sox7annm
distributed.worker - INFO - -------------------------------------------------
/scratch/cnt0024/hmg2840/albert7a/anaconda3/lib/python3.7/site-packages/dask/config.py:168: YAMLLoadWarning: calling yaml.load() without Loader=... is deprecated, as the default Loader is unsafe. Please read https://msg.pyyaml.org/load for full details.
  data = yaml.load(f.read()) or {}
/scratch/cnt0024/hmg2840/albert7a/anaconda3/lib/python3.7/site-packages/distributed/utils.py:136: RuntimeWarning: Couldn't detect a suitable IP address for reaching '8.8.8.8', defaulting to '127.0.0.1': [Errno 101] Network is unreachable
  RuntimeWarning,
distributed.worker - INFO -       Start worker at:   tcp://172.30.6.158:42520
distributed.worker - INFO -          Listening to:   tcp://172.30.6.158:42520
distributed.worker - INFO -              nanny at:         172.30.6.158:44107
distributed.worker - INFO -              bokeh at:         172.30.6.158:46561
distributed.worker - INFO - Waiting to connect to:   tcp://172.30.100.1:39168
distributed.worker - INFO - -------------------------------------------------
distributed.worker - INFO -               Threads:                          1
distributed.worker - INFO -                Memory:                    4.29 GB
distributed.worker - INFO -       Local Directory: /scratch/cnt0024/hmg2840/albert7a/daskjobqueue/worker-4qcuaj35
distributed.worker - INFO - -------------------------------------------------
/scratch/cnt0024/hmg2840/albert7a/anaconda3/lib/python3.7/site-packages/dask/config.py:168: YAMLLoadWarning: calling yaml.load() without Loader=... is deprecated, as the default Loader is unsafe. Please read https://msg.pyyaml.org/load for full details.
  data = yaml.load(f.read()) or {}
/scratch/cnt0024/hmg2840/albert7a/anaconda3/lib/python3.7/site-packages/distributed/utils.py:136: RuntimeWarning: Couldn't detect a suitable IP address for reaching '8.8.8.8', defaulting to '127.0.0.1': [Errno 101] Network is unreachable
  RuntimeWarning,
distributed.worker - INFO -       Start worker at:   tcp://172.30.6.158:43263
distributed.worker - INFO -          Listening to:   tcp://172.30.6.158:43263
distributed.worker - INFO -              nanny at:         172.30.6.158:34144
distributed.worker - INFO -              bokeh at:         172.30.6.158:44757
distributed.worker - INFO - Waiting to connect to:   tcp://172.30.100.1:39168
distributed.worker - INFO - -------------------------------------------------
distributed.worker - INFO -               Threads:                          1
distributed.worker - INFO -                Memory:                    4.29 GB
distributed.worker - INFO -       Local Directory: /scratch/cnt0024/hmg2840/albert7a/daskjobqueue/worker-imnn6vak
distributed.worker - INFO - -------------------------------------------------
/scratch/cnt0024/hmg2840/albert7a/anaconda3/lib/python3.7/site-packages/dask/config.py:168: YAMLLoadWarning: calling yaml.load() without Loader=... is deprecated, as the default Loader is unsafe. Please read https://msg.pyyaml.org/load for full details.
  data = yaml.load(f.read()) or {}
/scratch/cnt0024/hmg2840/albert7a/anaconda3/lib/python3.7/site-packages/distributed/utils.py:136: RuntimeWarning: Couldn't detect a suitable IP address for reaching '8.8.8.8', defaulting to '127.0.0.1': [Errno 101] Network is unreachable
  RuntimeWarning,
distributed.worker - INFO -       Start worker at:   tcp://172.30.6.158:41206
distributed.worker - INFO -          Listening to:   tcp://172.30.6.158:41206
distributed.worker - INFO -              nanny at:         172.30.6.158:38294
distributed.worker - INFO -              bokeh at:         172.30.6.158:36248
distributed.worker - INFO - Waiting to connect to:   tcp://172.30.100.1:39168
distributed.worker - INFO - -------------------------------------------------
distributed.worker - INFO -               Threads:                          1
distributed.worker - INFO -                Memory:                    4.29 GB
distributed.worker - INFO -       Local Directory: /scratch/cnt0024/hmg2840/albert7a/daskjobqueue/worker-nwior99d
distributed.worker - INFO - -------------------------------------------------
/scratch/cnt0024/hmg2840/albert7a/anaconda3/lib/python3.7/site-packages/dask/config.py:168: YAMLLoadWarning: calling yaml.load() without Loader=... is deprecated, as the default Loader is unsafe. Please read https://msg.pyyaml.org/load for full details.
  data = yaml.load(f.read()) or {}
/scratch/cnt0024/hmg2840/albert7a/anaconda3/lib/python3.7/site-packages/distributed/utils.py:136: RuntimeWarning: Couldn't detect a suitable IP address for reaching '8.8.8.8', defaulting to '127.0.0.1': [Errno 101] Network is unreachable
  RuntimeWarning,
distributed.worker - INFO -       Start worker at:   tcp://172.30.6.158:46340
distributed.worker - INFO -          Listening to:   tcp://172.30.6.158:46340
distributed.worker - INFO -              nanny at:         172.30.6.158:38181
distributed.worker - INFO -              bokeh at:         172.30.6.158:37438
distributed.worker - INFO - Waiting to connect to:   tcp://172.30.100.1:39168
distributed.worker - INFO - -------------------------------------------------
distributed.worker - INFO -               Threads:                          1
distributed.worker - INFO -                Memory:                    4.29 GB
distributed.worker - INFO -       Local Directory: /scratch/cnt0024/hmg2840/albert7a/daskjobqueue/worker-u2hdtbj_
distributed.worker - INFO - -------------------------------------------------
/scratch/cnt0024/hmg2840/albert7a/anaconda3/lib/python3.7/site-packages/dask/config.py:168: YAMLLoadWarning: calling yaml.load() without Loader=... is deprecated, as the default Loader is unsafe. Please read https://msg.pyyaml.org/load for full details.
  data = yaml.load(f.read()) or {}
/scratch/cnt0024/hmg2840/albert7a/anaconda3/lib/python3.7/site-packages/distributed/utils.py:136: RuntimeWarning: Couldn't detect a suitable IP address for reaching '8.8.8.8', defaulting to '127.0.0.1': [Errno 101] Network is unreachable
  RuntimeWarning,
distributed.worker - INFO -       Start worker at:   tcp://172.30.6.158:44676
distributed.worker - INFO -          Listening to:   tcp://172.30.6.158:44676
distributed.worker - INFO -              nanny at:         172.30.6.158:40275
distributed.worker - INFO -              bokeh at:         172.30.6.158:44985
distributed.worker - INFO - Waiting to connect to:   tcp://172.30.100.1:39168
distributed.worker - INFO - -------------------------------------------------
distributed.worker - INFO -               Threads:                          1
distributed.worker - INFO -                Memory:                    4.29 GB
distributed.worker - INFO -       Local Directory: /scratch/cnt0024/hmg2840/albert7a/daskjobqueue/worker-g6j1fkbc
distributed.worker - INFO - -------------------------------------------------
/scratch/cnt0024/hmg2840/albert7a/anaconda3/lib/python3.7/site-packages/dask/config.py:168: YAMLLoadWarning: calling yaml.load() without Loader=... is deprecated, as the default Loader is unsafe. Please read https://msg.pyyaml.org/load for full details.
  data = yaml.load(f.read()) or {}
/scratch/cnt0024/hmg2840/albert7a/anaconda3/lib/python3.7/site-packages/distributed/utils.py:136: RuntimeWarning: Couldn't detect a suitable IP address for reaching '8.8.8.8', defaulting to '127.0.0.1': [Errno 101] Network is unreachable
  RuntimeWarning,
distributed.worker - INFO -       Start worker at:   tcp://172.30.6.158:43809
distributed.worker - INFO -          Listening to:   tcp://172.30.6.158:43809
distributed.worker - INFO -              nanny at:         172.30.6.158:36124
distributed.worker - INFO -              bokeh at:         172.30.6.158:38159
distributed.worker - INFO - Waiting to connect to:   tcp://172.30.100.1:39168
distributed.worker - INFO - -------------------------------------------------
distributed.worker - INFO -               Threads:                          1
distributed.worker - INFO -                Memory:                    4.29 GB
distributed.worker - INFO -       Local Directory: /scratch/cnt0024/hmg2840/albert7a/daskjobqueue/worker-uvva7398
distributed.worker - INFO - -------------------------------------------------
/scratch/cnt0024/hmg2840/albert7a/anaconda3/lib/python3.7/site-packages/dask/config.py:168: YAMLLoadWarning: calling yaml.load() without Loader=... is deprecated, as the default Loader is unsafe. Please read https://msg.pyyaml.org/load for full details.
  data = yaml.load(f.read()) or {}
/scratch/cnt0024/hmg2840/albert7a/anaconda3/lib/python3.7/site-packages/distributed/utils.py:136: RuntimeWarning: Couldn't detect a suitable IP address for reaching '8.8.8.8', defaulting to '127.0.0.1': [Errno 101] Network is unreachable
  RuntimeWarning,
distributed.worker - INFO -       Start worker at:   tcp://172.30.6.158:39114
distributed.worker - INFO -          Listening to:   tcp://172.30.6.158:39114
distributed.worker - INFO -              nanny at:         172.30.6.158:46722
distributed.worker - INFO -              bokeh at:         172.30.6.158:39394
distributed.worker - INFO - Waiting to connect to:   tcp://172.30.100.1:39168
distributed.worker - INFO - -------------------------------------------------
distributed.worker - INFO -               Threads:                          1
distributed.worker - INFO -                Memory:                    4.29 GB
distributed.worker - INFO -       Local Directory: /scratch/cnt0024/hmg2840/albert7a/daskjobqueue/worker-mbex6dpi
distributed.worker - INFO - -------------------------------------------------
/scratch/cnt0024/hmg2840/albert7a/anaconda3/lib/python3.7/site-packages/dask/config.py:168: YAMLLoadWarning: calling yaml.load() without Loader=... is deprecated, as the default Loader is unsafe. Please read https://msg.pyyaml.org/load for full details.
  data = yaml.load(f.read()) or {}
/scratch/cnt0024/hmg2840/albert7a/anaconda3/lib/python3.7/site-packages/distributed/utils.py:136: RuntimeWarning: Couldn't detect a suitable IP address for reaching '8.8.8.8', defaulting to '127.0.0.1': [Errno 101] Network is unreachable
  RuntimeWarning,
distributed.worker - INFO -       Start worker at:   tcp://172.30.6.158:39120
distributed.worker - INFO -          Listening to:   tcp://172.30.6.158:39120
distributed.worker - INFO -              nanny at:         172.30.6.158:43776
distributed.worker - INFO -              bokeh at:         172.30.6.158:37800
distributed.worker - INFO - Waiting to connect to:   tcp://172.30.100.1:39168
distributed.worker - INFO - -------------------------------------------------
distributed.worker - INFO -               Threads:                          1
distributed.worker - INFO -                Memory:                    4.29 GB
distributed.worker - INFO -       Local Directory: /scratch/cnt0024/hmg2840/albert7a/daskjobqueue/worker-mzjtq5d5
distributed.worker - INFO - -------------------------------------------------
/scratch/cnt0024/hmg2840/albert7a/anaconda3/lib/python3.7/site-packages/dask/config.py:168: YAMLLoadWarning: calling yaml.load() without Loader=... is deprecated, as the default Loader is unsafe. Please read https://msg.pyyaml.org/load for full details.
  data = yaml.load(f.read()) or {}
/scratch/cnt0024/hmg2840/albert7a/anaconda3/lib/python3.7/site-packages/distributed/utils.py:136: RuntimeWarning: Couldn't detect a suitable IP address for reaching '8.8.8.8', defaulting to '127.0.0.1': [Errno 101] Network is unreachable
  RuntimeWarning,
distributed.worker - INFO -       Start worker at:   tcp://172.30.6.158:35608
distributed.worker - INFO -          Listening to:   tcp://172.30.6.158:35608
distributed.worker - INFO -              nanny at:         172.30.6.158:39630
distributed.worker - INFO -              bokeh at:         172.30.6.158:43685
distributed.worker - INFO - Waiting to connect to:   tcp://172.30.100.1:39168
distributed.worker - INFO - -------------------------------------------------
distributed.worker - INFO -               Threads:                          1
distributed.worker - INFO -                Memory:                    4.29 GB
distributed.worker - INFO -       Local Directory: /scratch/cnt0024/hmg2840/albert7a/daskjobqueue/worker-1p2ravxo
distributed.worker - INFO - -------------------------------------------------
/scratch/cnt0024/hmg2840/albert7a/anaconda3/lib/python3.7/site-packages/dask/config.py:168: YAMLLoadWarning: calling yaml.load() without Loader=... is deprecated, as the default Loader is unsafe. Please read https://msg.pyyaml.org/load for full details.
  data = yaml.load(f.read()) or {}
/scratch/cnt0024/hmg2840/albert7a/anaconda3/lib/python3.7/site-packages/distributed/utils.py:136: RuntimeWarning: Couldn't detect a suitable IP address for reaching '8.8.8.8', defaulting to '127.0.0.1': [Errno 101] Network is unreachable
  RuntimeWarning,
distributed.worker - INFO -       Start worker at:   tcp://172.30.6.158:34188
distributed.worker - INFO -          Listening to:   tcp://172.30.6.158:34188
distributed.worker - INFO -              nanny at:         172.30.6.158:46145
distributed.worker - INFO -              bokeh at:         172.30.6.158:34128
distributed.worker - INFO - Waiting to connect to:   tcp://172.30.100.1:39168
distributed.worker - INFO - -------------------------------------------------
distributed.worker - INFO -               Threads:                          1
distributed.worker - INFO -                Memory:                    4.29 GB
distributed.worker - INFO -       Local Directory: /scratch/cnt0024/hmg2840/albert7a/daskjobqueue/worker-wi95lvgx
distributed.worker - INFO - -------------------------------------------------
/scratch/cnt0024/hmg2840/albert7a/anaconda3/lib/python3.7/site-packages/dask/config.py:168: YAMLLoadWarning: calling yaml.load() without Loader=... is deprecated, as the default Loader is unsafe. Please read https://msg.pyyaml.org/load for full details.
  data = yaml.load(f.read()) or {}
/scratch/cnt0024/hmg2840/albert7a/anaconda3/lib/python3.7/site-packages/distributed/utils.py:136: RuntimeWarning: Couldn't detect a suitable IP address for reaching '8.8.8.8', defaulting to '127.0.0.1': [Errno 101] Network is unreachable
  RuntimeWarning,
distributed.worker - INFO -       Start worker at:   tcp://172.30.6.158:35313
distributed.worker - INFO -          Listening to:   tcp://172.30.6.158:35313
distributed.worker - INFO -              nanny at:         172.30.6.158:43973
distributed.worker - INFO -              bokeh at:         172.30.6.158:42264
distributed.worker - INFO - Waiting to connect to:   tcp://172.30.100.1:39168
distributed.worker - INFO - -------------------------------------------------
distributed.worker - INFO -               Threads:                          1
distributed.worker - INFO -                Memory:                    4.29 GB
distributed.worker - INFO -       Local Directory: /scratch/cnt0024/hmg2840/albert7a/daskjobqueue/worker-0jeahbwn
distributed.worker - INFO - -------------------------------------------------
/scratch/cnt0024/hmg2840/albert7a/anaconda3/lib/python3.7/site-packages/dask/config.py:168: YAMLLoadWarning: calling yaml.load() without Loader=... is deprecated, as the default Loader is unsafe. Please read https://msg.pyyaml.org/load for full details.
  data = yaml.load(f.read()) or {}
/scratch/cnt0024/hmg2840/albert7a/anaconda3/lib/python3.7/site-packages/distributed/utils.py:136: RuntimeWarning: Couldn't detect a suitable IP address for reaching '8.8.8.8', defaulting to '127.0.0.1': [Errno 101] Network is unreachable
  RuntimeWarning,
distributed.worker - INFO -       Start worker at:   tcp://172.30.6.158:36401
distributed.worker - INFO -          Listening to:   tcp://172.30.6.158:36401
distributed.worker - INFO -              nanny at:         172.30.6.158:43913
distributed.worker - INFO -              bokeh at:         172.30.6.158:33580
distributed.worker - INFO - Waiting to connect to:   tcp://172.30.100.1:39168
distributed.worker - INFO - -------------------------------------------------
distributed.worker - INFO -               Threads:                          1
distributed.worker - INFO -                Memory:                    4.29 GB
distributed.worker - INFO -       Local Directory: /scratch/cnt0024/hmg2840/albert7a/daskjobqueue/worker-e15k0v9z
distributed.worker - INFO - -------------------------------------------------
/scratch/cnt0024/hmg2840/albert7a/anaconda3/lib/python3.7/site-packages/dask/config.py:168: YAMLLoadWarning: calling yaml.load() without Loader=... is deprecated, as the default Loader is unsafe. Please read https://msg.pyyaml.org/load for full details.
  data = yaml.load(f.read()) or {}
/scratch/cnt0024/hmg2840/albert7a/anaconda3/lib/python3.7/site-packages/distributed/utils.py:136: RuntimeWarning: Couldn't detect a suitable IP address for reaching '8.8.8.8', defaulting to '127.0.0.1': [Errno 101] Network is unreachable
  RuntimeWarning,
distributed.worker - INFO -       Start worker at:   tcp://172.30.6.158:36354
distributed.worker - INFO -          Listening to:   tcp://172.30.6.158:36354
distributed.worker - INFO -              nanny at:         172.30.6.158:44860
distributed.worker - INFO -              bokeh at:         172.30.6.158:39786
distributed.worker - INFO - Waiting to connect to:   tcp://172.30.100.1:39168
distributed.worker - INFO - -------------------------------------------------
distributed.worker - INFO -               Threads:                          1
distributed.worker - INFO -                Memory:                    4.29 GB
distributed.worker - INFO -       Local Directory: /scratch/cnt0024/hmg2840/albert7a/daskjobqueue/worker-k9vswyg3
distributed.worker - INFO - -------------------------------------------------
/scratch/cnt0024/hmg2840/albert7a/anaconda3/lib/python3.7/site-packages/dask/config.py:168: YAMLLoadWarning: calling yaml.load() without Loader=... is deprecated, as the default Loader is unsafe. Please read https://msg.pyyaml.org/load for full details.
  data = yaml.load(f.read()) or {}
/scratch/cnt0024/hmg2840/albert7a/anaconda3/lib/python3.7/site-packages/distributed/utils.py:136: RuntimeWarning: Couldn't detect a suitable IP address for reaching '8.8.8.8', defaulting to '127.0.0.1': [Errno 101] Network is unreachable
  RuntimeWarning,
distributed.worker - INFO -       Start worker at:   tcp://172.30.6.158:36436
/scratch/cnt0024/hmg2840/albert7a/anaconda3/lib/python3.7/site-packages/dask/config.py:168: YAMLLoadWarning: calling yaml.load() without Loader=... is deprecated, as the default Loader is unsafe. Please read https://msg.pyyaml.org/load for full details.
  data = yaml.load(f.read()) or {}
/scratch/cnt0024/hmg2840/albert7a/anaconda3/lib/python3.7/site-packages/distributed/utils.py:136: RuntimeWarning: Couldn't detect a suitable IP address for reaching '8.8.8.8', defaulting to '127.0.0.1': [Errno 101] Network is unreachable
  RuntimeWarning,
distributed.worker - INFO -       Start worker at:   tcp://172.30.6.158:40212
distributed.worker - INFO -          Listening to:   tcp://172.30.6.158:36436
distributed.worker - INFO -          Listening to:   tcp://172.30.6.158:40212
distributed.worker - INFO -              nanny at:         172.30.6.158:33563
distributed.worker - INFO -              nanny at:         172.30.6.158:40248
distributed.worker - INFO -              bokeh at:         172.30.6.158:34597
distributed.worker - INFO -              bokeh at:         172.30.6.158:38378
distributed.worker - INFO - Waiting to connect to:   tcp://172.30.100.1:39168
distributed.worker - INFO - Waiting to connect to:   tcp://172.30.100.1:39168
distributed.worker - INFO - -------------------------------------------------
distributed.worker - INFO - -------------------------------------------------
distributed.worker - INFO -               Threads:                          1
distributed.worker - INFO -               Threads:                          1
distributed.worker - INFO -                Memory:                    4.29 GB
distributed.worker - INFO -                Memory:                    4.29 GB
distributed.worker - INFO -       Local Directory: /scratch/cnt0024/hmg2840/albert7a/daskjobqueue/worker-s22d4cxj
distributed.worker - INFO -       Local Directory: /scratch/cnt0024/hmg2840/albert7a/daskjobqueue/worker-su409a2a
distributed.worker - INFO - -------------------------------------------------
distributed.worker - INFO - -------------------------------------------------
/scratch/cnt0024/hmg2840/albert7a/anaconda3/lib/python3.7/site-packages/dask/config.py:168: YAMLLoadWarning: calling yaml.load() without Loader=... is deprecated, as the default Loader is unsafe. Please read https://msg.pyyaml.org/load for full details.
  data = yaml.load(f.read()) or {}
/scratch/cnt0024/hmg2840/albert7a/anaconda3/lib/python3.7/site-packages/distributed/utils.py:136: RuntimeWarning: Couldn't detect a suitable IP address for reaching '8.8.8.8', defaulting to '127.0.0.1': [Errno 101] Network is unreachable
  RuntimeWarning,
distributed.worker - INFO -       Start worker at:   tcp://172.30.6.158:39536
distributed.worker - INFO -          Listening to:   tcp://172.30.6.158:39536
distributed.worker - INFO -              nanny at:         172.30.6.158:43798
distributed.worker - INFO -              bokeh at:         172.30.6.158:42934
distributed.worker - INFO - Waiting to connect to:   tcp://172.30.100.1:39168
distributed.worker - INFO - -------------------------------------------------
distributed.worker - INFO -               Threads:                          1
distributed.worker - INFO -                Memory:                    4.29 GB
distributed.worker - INFO -       Local Directory: /scratch/cnt0024/hmg2840/albert7a/daskjobqueue/worker-t7mxp9zw
distributed.worker - INFO - -------------------------------------------------
/scratch/cnt0024/hmg2840/albert7a/anaconda3/lib/python3.7/site-packages/dask/config.py:168: YAMLLoadWarning: calling yaml.load() without Loader=... is deprecated, as the default Loader is unsafe. Please read https://msg.pyyaml.org/load for full details.
  data = yaml.load(f.read()) or {}
/scratch/cnt0024/hmg2840/albert7a/anaconda3/lib/python3.7/site-packages/distributed/utils.py:136: RuntimeWarning: Couldn't detect a suitable IP address for reaching '8.8.8.8', defaulting to '127.0.0.1': [Errno 101] Network is unreachable
  RuntimeWarning,
distributed.worker - INFO -       Start worker at:   tcp://172.30.6.158:33078
distributed.worker - INFO -          Listening to:   tcp://172.30.6.158:33078
distributed.worker - INFO -              nanny at:         172.30.6.158:38610
distributed.worker - INFO -              bokeh at:         172.30.6.158:36025
distributed.worker - INFO - Waiting to connect to:   tcp://172.30.100.1:39168
distributed.worker - INFO - -------------------------------------------------
distributed.worker - INFO -               Threads:                          1
distributed.worker - INFO -                Memory:                    4.29 GB
/scratch/cnt0024/hmg2840/albert7a/anaconda3/lib/python3.7/site-packages/dask/config.py:168: YAMLLoadWarning: calling yaml.load() without Loader=... is deprecated, as the default Loader is unsafe. Please read https://msg.pyyaml.org/load for full details.
  data = yaml.load(f.read()) or {}
/scratch/cnt0024/hmg2840/albert7a/anaconda3/lib/python3.7/site-packages/distributed/utils.py:136: RuntimeWarning: Couldn't detect a suitable IP address for reaching '8.8.8.8', defaulting to '127.0.0.1': [Errno 101] Network is unreachable
  RuntimeWarning,
distributed.worker - INFO -       Start worker at:   tcp://172.30.6.158:45270
distributed.worker - INFO -       Local Directory: /scratch/cnt0024/hmg2840/albert7a/daskjobqueue/worker-7nhcq3kd
distributed.worker - INFO -          Listening to:   tcp://172.30.6.158:45270
distributed.worker - INFO - -------------------------------------------------
distributed.worker - INFO -              nanny at:         172.30.6.158:34789
distributed.worker - INFO -              bokeh at:         172.30.6.158:39707
distributed.worker - INFO - Waiting to connect to:   tcp://172.30.100.1:39168
distributed.worker - INFO - -------------------------------------------------
distributed.worker - INFO -               Threads:                          1
distributed.worker - INFO -                Memory:                    4.29 GB
/scratch/cnt0024/hmg2840/albert7a/anaconda3/lib/python3.7/site-packages/dask/config.py:168: YAMLLoadWarning: calling yaml.load() without Loader=... is deprecated, as the default Loader is unsafe. Please read https://msg.pyyaml.org/load for full details.
  data = yaml.load(f.read()) or {}
/scratch/cnt0024/hmg2840/albert7a/anaconda3/lib/python3.7/site-packages/distributed/utils.py:136: RuntimeWarning: Couldn't detect a suitable IP address for reaching '8.8.8.8', defaulting to '127.0.0.1': [Errno 101] Network is unreachable
  RuntimeWarning,
distributed.worker - INFO -       Start worker at:   tcp://172.30.6.158:44449
distributed.worker - INFO -          Listening to:   tcp://172.30.6.158:44449
distributed.worker - INFO -              nanny at:         172.30.6.158:34167
distributed.worker - INFO -       Local Directory: /scratch/cnt0024/hmg2840/albert7a/daskjobqueue/worker-go4ukh82
distributed.worker - INFO -              bokeh at:         172.30.6.158:42177
distributed.worker - INFO - -------------------------------------------------
distributed.worker - INFO - Waiting to connect to:   tcp://172.30.100.1:39168
distributed.worker - INFO - -------------------------------------------------
distributed.worker - INFO -               Threads:                          1
distributed.worker - INFO -                Memory:                    4.29 GB
distributed.worker - INFO -       Local Directory: /scratch/cnt0024/hmg2840/albert7a/daskjobqueue/worker-b3wpwg_e
distributed.worker - INFO - -------------------------------------------------
/scratch/cnt0024/hmg2840/albert7a/anaconda3/lib/python3.7/site-packages/dask/config.py:168: YAMLLoadWarning: calling yaml.load() without Loader=... is deprecated, as the default Loader is unsafe. Please read https://msg.pyyaml.org/load for full details.
  data = yaml.load(f.read()) or {}
/scratch/cnt0024/hmg2840/albert7a/anaconda3/lib/python3.7/site-packages/distributed/utils.py:136: RuntimeWarning: Couldn't detect a suitable IP address for reaching '8.8.8.8', defaulting to '127.0.0.1': [Errno 101] Network is unreachable
  RuntimeWarning,
distributed.worker - INFO -       Start worker at:   tcp://172.30.6.158:36917
distributed.worker - INFO -          Listening to:   tcp://172.30.6.158:36917
distributed.worker - INFO -              nanny at:         172.30.6.158:39324
distributed.worker - INFO -              bokeh at:         172.30.6.158:46223
distributed.worker - INFO - Waiting to connect to:   tcp://172.30.100.1:39168
distributed.worker - INFO - -------------------------------------------------
distributed.worker - INFO -               Threads:                          1
distributed.worker - INFO -                Memory:                    4.29 GB
distributed.worker - INFO -       Local Directory: /scratch/cnt0024/hmg2840/albert7a/daskjobqueue/worker-r9zh_mwx
distributed.worker - INFO - -------------------------------------------------
/scratch/cnt0024/hmg2840/albert7a/anaconda3/lib/python3.7/site-packages/dask/config.py:168: YAMLLoadWarning: calling yaml.load() without Loader=... is deprecated, as the default Loader is unsafe. Please read https://msg.pyyaml.org/load for full details.
  data = yaml.load(f.read()) or {}
/scratch/cnt0024/hmg2840/albert7a/anaconda3/lib/python3.7/site-packages/distributed/utils.py:136: RuntimeWarning: Couldn't detect a suitable IP address for reaching '8.8.8.8', defaulting to '127.0.0.1': [Errno 101] Network is unreachable
  RuntimeWarning,
distributed.worker - INFO -       Start worker at:   tcp://172.30.6.158:32841
/scratch/cnt0024/hmg2840/albert7a/anaconda3/lib/python3.7/site-packages/dask/config.py:168: YAMLLoadWarning: calling yaml.load() without Loader=... is deprecated, as the default Loader is unsafe. Please read https://msg.pyyaml.org/load for full details.
  data = yaml.load(f.read()) or {}
/scratch/cnt0024/hmg2840/albert7a/anaconda3/lib/python3.7/site-packages/distributed/utils.py:136: RuntimeWarning: Couldn't detect a suitable IP address for reaching '8.8.8.8', defaulting to '127.0.0.1': [Errno 101] Network is unreachable
  RuntimeWarning,
distributed.worker - INFO -       Start worker at:   tcp://172.30.6.158:43927
distributed.worker - INFO -          Listening to:   tcp://172.30.6.158:32841
distributed.worker - INFO -          Listening to:   tcp://172.30.6.158:43927
distributed.worker - INFO -              nanny at:         172.30.6.158:44135
distributed.worker - INFO -              nanny at:         172.30.6.158:41327
distributed.worker - INFO -              bokeh at:         172.30.6.158:34636
distributed.worker - INFO -              bokeh at:         172.30.6.158:40396
distributed.worker - INFO - Waiting to connect to:   tcp://172.30.100.1:39168
distributed.worker - INFO - Waiting to connect to:   tcp://172.30.100.1:39168
distributed.worker - INFO - -------------------------------------------------
distributed.worker - INFO - -------------------------------------------------
distributed.worker - INFO -               Threads:                          1
distributed.worker - INFO -               Threads:                          1
distributed.worker - INFO -                Memory:                    4.29 GB
distributed.worker - INFO -                Memory:                    4.29 GB
distributed.worker - INFO -       Local Directory: /scratch/cnt0024/hmg2840/albert7a/daskjobqueue/worker-gr4pghkg
distributed.worker - INFO -       Local Directory: /scratch/cnt0024/hmg2840/albert7a/daskjobqueue/worker-la8zzj5v
distributed.worker - INFO - -------------------------------------------------
distributed.worker - INFO - -------------------------------------------------
/scratch/cnt0024/hmg2840/albert7a/anaconda3/lib/python3.7/site-packages/dask/config.py:168: YAMLLoadWarning: calling yaml.load() without Loader=... is deprecated, as the default Loader is unsafe. Please read https://msg.pyyaml.org/load for full details.
  data = yaml.load(f.read()) or {}
/scratch/cnt0024/hmg2840/albert7a/anaconda3/lib/python3.7/site-packages/distributed/utils.py:136: RuntimeWarning: Couldn't detect a suitable IP address for reaching '8.8.8.8', defaulting to '127.0.0.1': [Errno 101] Network is unreachable
  RuntimeWarning,
distributed.worker - INFO -       Start worker at:   tcp://172.30.6.158:33518
distributed.worker - INFO -          Listening to:   tcp://172.30.6.158:33518
distributed.worker - INFO -              nanny at:         172.30.6.158:35237
distributed.worker - INFO -              bokeh at:         172.30.6.158:43272
distributed.worker - INFO - Waiting to connect to:   tcp://172.30.100.1:39168
distributed.worker - INFO - -------------------------------------------------
distributed.worker - INFO -               Threads:                          1
distributed.worker - INFO -                Memory:                    4.29 GB
distributed.worker - INFO -       Local Directory: /scratch/cnt0024/hmg2840/albert7a/daskjobqueue/worker-ralyv9zt
distributed.worker - INFO - -------------------------------------------------
distributed.worker - INFO -         Registered to:   tcp://172.30.100.1:39168
distributed.worker - INFO -         Registered to:   tcp://172.30.100.1:39168
distributed.worker - INFO -         Registered to:   tcp://172.30.100.1:39168
distributed.worker - INFO -         Registered to:   tcp://172.30.100.1:39168
distributed.worker - INFO -         Registered to:   tcp://172.30.100.1:39168
distributed.worker - INFO - -------------------------------------------------
distributed.worker - INFO -         Registered to:   tcp://172.30.100.1:39168
distributed.worker - INFO -         Registered to:   tcp://172.30.100.1:39168
distributed.worker - INFO - -------------------------------------------------
distributed.worker - INFO - -------------------------------------------------
distributed.worker - INFO - -------------------------------------------------
distributed.worker - INFO - -------------------------------------------------
distributed.worker - INFO - -------------------------------------------------
distributed.worker - INFO -         Registered to:   tcp://172.30.100.1:39168
distributed.worker - INFO - -------------------------------------------------
distributed.worker - INFO -         Registered to:   tcp://172.30.100.1:39168
distributed.worker - INFO -         Registered to:   tcp://172.30.100.1:39168
distributed.core - INFO - Starting established connection
distributed.worker - INFO - -------------------------------------------------
distributed.worker - INFO -         Registered to:   tcp://172.30.100.1:39168
distributed.worker - INFO -         Registered to:   tcp://172.30.100.1:39168
distributed.worker - INFO - -------------------------------------------------
distributed.worker - INFO - -------------------------------------------------
distributed.core - INFO - Starting established connection
distributed.core - INFO - Starting established connection
distributed.worker - INFO - -------------------------------------------------
distributed.worker - INFO - -------------------------------------------------
distributed.core - INFO - Starting established connection
distributed.core - INFO - Starting established connection
distributed.worker - INFO -         Registered to:   tcp://172.30.100.1:39168
distributed.core - INFO - Starting established connection
distributed.worker - INFO -         Registered to:   tcp://172.30.100.1:39168
distributed.worker - INFO -         Registered to:   tcp://172.30.100.1:39168
distributed.core - INFO - Starting established connection
distributed.core - INFO - Starting established connection
distributed.core - INFO - Starting established connection
distributed.worker - INFO -         Registered to:   tcp://172.30.100.1:39168
distributed.worker - INFO - -------------------------------------------------
distributed.core - INFO - Starting established connection
distributed.worker - INFO - -------------------------------------------------
distributed.core - INFO - Starting established connection
distributed.worker - INFO -         Registered to:   tcp://172.30.100.1:39168
distributed.worker - INFO - -------------------------------------------------
distributed.core - INFO - Starting established connection
distributed.worker - INFO - -------------------------------------------------
distributed.worker - INFO -         Registered to:   tcp://172.30.100.1:39168
distributed.worker - INFO -         Registered to:   tcp://172.30.100.1:39168
distributed.worker - INFO - -------------------------------------------------
distributed.worker - INFO -         Registered to:   tcp://172.30.100.1:39168
distributed.worker - INFO -         Registered to:   tcp://172.30.100.1:39168
distributed.worker - INFO - -------------------------------------------------
distributed.worker - INFO -         Registered to:   tcp://172.30.100.1:39168
distributed.core - INFO - Starting established connection
distributed.worker - INFO - -------------------------------------------------
distributed.worker - INFO -         Registered to:   tcp://172.30.100.1:39168
distributed.worker - INFO - -------------------------------------------------
distributed.worker - INFO - -------------------------------------------------
distributed.core - INFO - Starting established connection
distributed.worker - INFO - -------------------------------------------------
distributed.worker - INFO -         Registered to:   tcp://172.30.100.1:39168
distributed.core - INFO - Starting established connection
distributed.core - INFO - Starting established connection
distributed.core - INFO - Starting established connection
distributed.worker - INFO -         Registered to:   tcp://172.30.100.1:39168
distributed.worker - INFO - -------------------------------------------------
distributed.worker - INFO -         Registered to:   tcp://172.30.100.1:39168
distributed.core - INFO - Starting established connection
distributed.worker - INFO - -------------------------------------------------
distributed.core - INFO - Starting established connection
distributed.core - INFO - Starting established connection
distributed.worker - INFO - -------------------------------------------------
distributed.core - INFO - Starting established connection
distributed.core - INFO - Starting established connection
distributed.worker - INFO -         Registered to:   tcp://172.30.100.1:39168
distributed.worker - INFO - -------------------------------------------------
distributed.worker - INFO -         Registered to:   tcp://172.30.100.1:39168
distributed.core - INFO - Starting established connection
distributed.worker - INFO - -------------------------------------------------
distributed.worker - INFO - -------------------------------------------------
distributed.core - INFO - Starting established connection
distributed.core - INFO - Starting established connection
distributed.core - INFO - Starting established connection
distributed.core - INFO - Starting established connection
distributed.core - INFO - Starting established connection
tornado.application - ERROR - Exception in callback functools.partial(<bound method IOLoop._discard_future_result of <tornado.platform.asyncio.AsyncIOLoop object at 0x2b1b8b721208>>, <Future finished exception=OSError("Timed out trying to connect to 'tcp://172.30.100.1:39168' after 10 s: connect() didn't finish in time")>)
Traceback (most recent call last):
  File "/scratch/cnt0024/hmg2840/albert7a/anaconda3/lib/python3.7/site-packages/distributed/comm/core.py", line 218, in connect
    quiet_exceptions=EnvironmentError,
  File "/scratch/cnt0024/hmg2840/albert7a/anaconda3/lib/python3.7/site-packages/tornado/gen.py", line 735, in run
    value = future.result()
tornado.util.TimeoutError: Timeout

During handling of the above exception, another exception occurred:

Traceback (most recent call last):
  File "/scratch/cnt0024/hmg2840/albert7a/anaconda3/lib/python3.7/site-packages/tornado/ioloop.py", line 743, in _run_callback
    ret = callback()
  File "/scratch/cnt0024/hmg2840/albert7a/anaconda3/lib/python3.7/site-packages/tornado/ioloop.py", line 767, in _discard_future_result
    future.result()
  File "/scratch/cnt0024/hmg2840/albert7a/anaconda3/lib/python3.7/site-packages/tornado/gen.py", line 742, in run
    yielded = self.gen.throw(*exc_info)  # type: ignore
  File "/scratch/cnt0024/hmg2840/albert7a/anaconda3/lib/python3.7/site-packages/distributed/worker.py", line 748, in heartbeat
    address=self.contact_address, now=time(), metrics=self.get_metrics()
  File "/scratch/cnt0024/hmg2840/albert7a/anaconda3/lib/python3.7/site-packages/tornado/gen.py", line 735, in run
    value = future.result()
  File "/scratch/cnt0024/hmg2840/albert7a/anaconda3/lib/python3.7/site-packages/tornado/gen.py", line 742, in run
    yielded = self.gen.throw(*exc_info)  # type: ignore
  File "/scratch/cnt0024/hmg2840/albert7a/anaconda3/lib/python3.7/site-packages/distributed/core.py", line 736, in send_recv_from_rpc
    comm = yield self.pool.connect(self.addr)
  File "/scratch/cnt0024/hmg2840/albert7a/anaconda3/lib/python3.7/site-packages/tornado/gen.py", line 735, in run
    value = future.result()
  File "/scratch/cnt0024/hmg2840/albert7a/anaconda3/lib/python3.7/site-packages/tornado/gen.py", line 742, in run
    yielded = self.gen.throw(*exc_info)  # type: ignore
  File "/scratch/cnt0024/hmg2840/albert7a/anaconda3/lib/python3.7/site-packages/distributed/core.py", line 864, in connect
    connection_args=self.connection_args,
  File "/scratch/cnt0024/hmg2840/albert7a/anaconda3/lib/python3.7/site-packages/tornado/gen.py", line 735, in run
    value = future.result()
  File "/scratch/cnt0024/hmg2840/albert7a/anaconda3/lib/python3.7/site-packages/tornado/gen.py", line 742, in run
    yielded = self.gen.throw(*exc_info)  # type: ignore
  File "/scratch/cnt0024/hmg2840/albert7a/anaconda3/lib/python3.7/site-packages/distributed/comm/core.py", line 230, in connect
    _raise(error)
  File "/scratch/cnt0024/hmg2840/albert7a/anaconda3/lib/python3.7/site-packages/distributed/comm/core.py", line 207, in _raise
    raise IOError(msg)
OSError: Timed out trying to connect to 'tcp://172.30.100.1:39168' after 10 s: connect() didn't finish in time
tornado.application - ERROR - Exception in callback functools.partial(<bound method IOLoop._discard_future_result of <tornado.platform.asyncio.AsyncIOLoop object at 0x2b1b8b721208>>, <Future finished exception=OSError("Timed out trying to connect to 'tcp://172.30.100.1:39168' after 10 s: connect() didn't finish in time")>)
Traceback (most recent call last):
  File "/scratch/cnt0024/hmg2840/albert7a/anaconda3/lib/python3.7/site-packages/distributed/comm/core.py", line 218, in connect
    quiet_exceptions=EnvironmentError,
  File "/scratch/cnt0024/hmg2840/albert7a/anaconda3/lib/python3.7/site-packages/tornado/gen.py", line 735, in run
    value = future.result()
tornado.util.TimeoutError: Timeout

During handling of the above exception, another exception occurred:

Traceback (most recent call last):
  File "/scratch/cnt0024/hmg2840/albert7a/anaconda3/lib/python3.7/site-packages/tornado/ioloop.py", line 743, in _run_callback
    ret = callback()
  File "/scratch/cnt0024/hmg2840/albert7a/anaconda3/lib/python3.7/site-packages/tornado/ioloop.py", line 767, in _discard_future_result
    future.result()
  File "/scratch/cnt0024/hmg2840/albert7a/anaconda3/lib/python3.7/site-packages/tornado/gen.py", line 742, in run
    yielded = self.gen.throw(*exc_info)  # type: ignore
  File "/scratch/cnt0024/hmg2840/albert7a/anaconda3/lib/python3.7/site-packages/distributed/worker.py", line 748, in heartbeat
    address=self.contact_address, now=time(), metrics=self.get_metrics()
  File "/scratch/cnt0024/hmg2840/albert7a/anaconda3/lib/python3.7/site-packages/tornado/gen.py", line 735, in run
    value = future.result()
  File "/scratch/cnt0024/hmg2840/albert7a/anaconda3/lib/python3.7/site-packages/tornado/gen.py", line 742, in run
    yielded = self.gen.throw(*exc_info)  # type: ignore
  File "/scratch/cnt0024/hmg2840/albert7a/anaconda3/lib/python3.7/site-packages/distributed/core.py", line 736, in send_recv_from_rpc
    comm = yield self.pool.connect(self.addr)
  File "/scratch/cnt0024/hmg2840/albert7a/anaconda3/lib/python3.7/site-packages/tornado/gen.py", line 735, in run
    value = future.result()
  File "/scratch/cnt0024/hmg2840/albert7a/anaconda3/lib/python3.7/site-packages/tornado/gen.py", line 742, in run
    yielded = self.gen.throw(*exc_info)  # type: ignore
  File "/scratch/cnt0024/hmg2840/albert7a/anaconda3/lib/python3.7/site-packages/distributed/core.py", line 864, in connect
    connection_args=self.connection_args,
  File "/scratch/cnt0024/hmg2840/albert7a/anaconda3/lib/python3.7/site-packages/tornado/gen.py", line 735, in run
    value = future.result()
  File "/scratch/cnt0024/hmg2840/albert7a/anaconda3/lib/python3.7/site-packages/tornado/gen.py", line 742, in run
    yielded = self.gen.throw(*exc_info)  # type: ignore
  File "/scratch/cnt0024/hmg2840/albert7a/anaconda3/lib/python3.7/site-packages/distributed/comm/core.py", line 230, in connect
    _raise(error)
  File "/scratch/cnt0024/hmg2840/albert7a/anaconda3/lib/python3.7/site-packages/distributed/comm/core.py", line 207, in _raise
    raise IOError(msg)
OSError: Timed out trying to connect to 'tcp://172.30.100.1:39168' after 10 s: connect() didn't finish in time
tornado.application - ERROR - Exception in callback functools.partial(<bound method IOLoop._discard_future_result of <tornado.platform.asyncio.AsyncIOLoop object at 0x2b1b8b721208>>, <Future finished exception=OSError("Timed out trying to connect to 'tcp://172.30.100.1:39168' after 10 s: connect() didn't finish in time")>)
Traceback (most recent call last):
  File "/scratch/cnt0024/hmg2840/albert7a/anaconda3/lib/python3.7/site-packages/distributed/comm/core.py", line 218, in connect
    quiet_exceptions=EnvironmentError,
  File "/scratch/cnt0024/hmg2840/albert7a/anaconda3/lib/python3.7/site-packages/tornado/gen.py", line 735, in run
    value = future.result()
tornado.util.TimeoutError: Timeout

During handling of the above exception, another exception occurred:

Traceback (most recent call last):
  File "/scratch/cnt0024/hmg2840/albert7a/anaconda3/lib/python3.7/site-packages/tornado/ioloop.py", line 743, in _run_callback
    ret = callback()
  File "/scratch/cnt0024/hmg2840/albert7a/anaconda3/lib/python3.7/site-packages/tornado/ioloop.py", line 767, in _discard_future_result
    future.result()
  File "/scratch/cnt0024/hmg2840/albert7a/anaconda3/lib/python3.7/site-packages/tornado/gen.py", line 742, in run
    yielded = self.gen.throw(*exc_info)  # type: ignore
  File "/scratch/cnt0024/hmg2840/albert7a/anaconda3/lib/python3.7/site-packages/distributed/worker.py", line 748, in heartbeat
    address=self.contact_address, now=time(), metrics=self.get_metrics()
  File "/scratch/cnt0024/hmg2840/albert7a/anaconda3/lib/python3.7/site-packages/tornado/gen.py", line 735, in run
    value = future.result()
  File "/scratch/cnt0024/hmg2840/albert7a/anaconda3/lib/python3.7/site-packages/tornado/gen.py", line 742, in run
    yielded = self.gen.throw(*exc_info)  # type: ignore
  File "/scratch/cnt0024/hmg2840/albert7a/anaconda3/lib/python3.7/site-packages/distributed/core.py", line 736, in send_recv_from_rpc
    comm = yield self.pool.connect(self.addr)
  File "/scratch/cnt0024/hmg2840/albert7a/anaconda3/lib/python3.7/site-packages/tornado/gen.py", line 735, in run
    value = future.result()
  File "/scratch/cnt0024/hmg2840/albert7a/anaconda3/lib/python3.7/site-packages/tornado/gen.py", line 742, in run
    yielded = self.gen.throw(*exc_info)  # type: ignore
  File "/scratch/cnt0024/hmg2840/albert7a/anaconda3/lib/python3.7/site-packages/distributed/core.py", line 864, in connect
    connection_args=self.connection_args,
  File "/scratch/cnt0024/hmg2840/albert7a/anaconda3/lib/python3.7/site-packages/tornado/gen.py", line 735, in run
    value = future.result()
  File "/scratch/cnt0024/hmg2840/albert7a/anaconda3/lib/python3.7/site-packages/tornado/gen.py", line 742, in run
    yielded = self.gen.throw(*exc_info)  # type: ignore
  File "/scratch/cnt0024/hmg2840/albert7a/anaconda3/lib/python3.7/site-packages/distributed/comm/core.py", line 230, in connect
    _raise(error)
  File "/scratch/cnt0024/hmg2840/albert7a/anaconda3/lib/python3.7/site-packages/distributed/comm/core.py", line 207, in _raise
    raise IOError(msg)
OSError: Timed out trying to connect to 'tcp://172.30.100.1:39168' after 10 s: connect() didn't finish in time
tornado.application - ERROR - Exception in callback functools.partial(<bound method IOLoop._discard_future_result of <tornado.platform.asyncio.AsyncIOLoop object at 0x2b1b8b721208>>, <Future finished exception=OSError("Timed out trying to connect to 'tcp://172.30.100.1:39168' after 10 s: connect() didn't finish in time")>)
Traceback (most recent call last):
  File "/scratch/cnt0024/hmg2840/albert7a/anaconda3/lib/python3.7/site-packages/distributed/comm/core.py", line 218, in connect
    quiet_exceptions=EnvironmentError,
  File "/scratch/cnt0024/hmg2840/albert7a/anaconda3/lib/python3.7/site-packages/tornado/gen.py", line 735, in run
    value = future.result()
tornado.util.TimeoutError: Timeout

During handling of the above exception, another exception occurred:

Traceback (most recent call last):
  File "/scratch/cnt0024/hmg2840/albert7a/anaconda3/lib/python3.7/site-packages/tornado/ioloop.py", line 743, in _run_callback
    ret = callback()
  File "/scratch/cnt0024/hmg2840/albert7a/anaconda3/lib/python3.7/site-packages/tornado/ioloop.py", line 767, in _discard_future_result
    future.result()
  File "/scratch/cnt0024/hmg2840/albert7a/anaconda3/lib/python3.7/site-packages/tornado/gen.py", line 742, in run
    yielded = self.gen.throw(*exc_info)  # type: ignore
  File "/scratch/cnt0024/hmg2840/albert7a/anaconda3/lib/python3.7/site-packages/distributed/worker.py", line 748, in heartbeat
    address=self.contact_address, now=time(), metrics=self.get_metrics()
  File "/scratch/cnt0024/hmg2840/albert7a/anaconda3/lib/python3.7/site-packages/tornado/gen.py", line 735, in run
    value = future.result()
  File "/scratch/cnt0024/hmg2840/albert7a/anaconda3/lib/python3.7/site-packages/tornado/gen.py", line 742, in run
    yielded = self.gen.throw(*exc_info)  # type: ignore
  File "/scratch/cnt0024/hmg2840/albert7a/anaconda3/lib/python3.7/site-packages/distributed/core.py", line 736, in send_recv_from_rpc
    comm = yield self.pool.connect(self.addr)
  File "/scratch/cnt0024/hmg2840/albert7a/anaconda3/lib/python3.7/site-packages/tornado/gen.py", line 735, in run
    value = future.result()
  File "/scratch/cnt0024/hmg2840/albert7a/anaconda3/lib/python3.7/site-packages/tornado/gen.py", line 742, in run
    yielded = self.gen.throw(*exc_info)  # type: ignore
  File "/scratch/cnt0024/hmg2840/albert7a/anaconda3/lib/python3.7/site-packages/distributed/core.py", line 864, in connect
    connection_args=self.connection_args,
  File "/scratch/cnt0024/hmg2840/albert7a/anaconda3/lib/python3.7/site-packages/tornado/gen.py", line 735, in run
    value = future.result()
  File "/scratch/cnt0024/hmg2840/albert7a/anaconda3/lib/python3.7/site-packages/tornado/gen.py", line 742, in run
    yielded = self.gen.throw(*exc_info)  # type: ignore
  File "/scratch/cnt0024/hmg2840/albert7a/anaconda3/lib/python3.7/site-packages/distributed/comm/core.py", line 230, in connect
    _raise(error)
  File "/scratch/cnt0024/hmg2840/albert7a/anaconda3/lib/python3.7/site-packages/distributed/comm/core.py", line 207, in _raise
    raise IOError(msg)
OSError: Timed out trying to connect to 'tcp://172.30.100.1:39168' after 10 s: connect() didn't finish in time
tornado.application - ERROR - Exception in callback functools.partial(<bound method IOLoop._discard_future_result of <tornado.platform.asyncio.AsyncIOLoop object at 0x2b1b8b721208>>, <Future finished exception=OSError("Timed out trying to connect to 'tcp://172.30.100.1:39168' after 10 s: connect() didn't finish in time")>)
Traceback (most recent call last):
  File "/scratch/cnt0024/hmg2840/albert7a/anaconda3/lib/python3.7/site-packages/distributed/comm/core.py", line 218, in connect
    quiet_exceptions=EnvironmentError,
  File "/scratch/cnt0024/hmg2840/albert7a/anaconda3/lib/python3.7/site-packages/tornado/gen.py", line 735, in run
    value = future.result()
tornado.util.TimeoutError: Timeout

During handling of the above exception, another exception occurred:

Traceback (most recent call last):
  File "/scratch/cnt0024/hmg2840/albert7a/anaconda3/lib/python3.7/site-packages/tornado/ioloop.py", line 743, in _run_callback
    ret = callback()
  File "/scratch/cnt0024/hmg2840/albert7a/anaconda3/lib/python3.7/site-packages/tornado/ioloop.py", line 767, in _discard_future_result
    future.result()
  File "/scratch/cnt0024/hmg2840/albert7a/anaconda3/lib/python3.7/site-packages/tornado/gen.py", line 742, in run
    yielded = self.gen.throw(*exc_info)  # type: ignore
  File "/scratch/cnt0024/hmg2840/albert7a/anaconda3/lib/python3.7/site-packages/distributed/worker.py", line 748, in heartbeat
    address=self.contact_address, now=time(), metrics=self.get_metrics()
  File "/scratch/cnt0024/hmg2840/albert7a/anaconda3/lib/python3.7/site-packages/tornado/gen.py", line 735, in run
    value = future.result()
  File "/scratch/cnt0024/hmg2840/albert7a/anaconda3/lib/python3.7/site-packages/tornado/gen.py", line 742, in run
    yielded = self.gen.throw(*exc_info)  # type: ignore
  File "/scratch/cnt0024/hmg2840/albert7a/anaconda3/lib/python3.7/site-packages/distributed/core.py", line 736, in send_recv_from_rpc
    comm = yield self.pool.connect(self.addr)
  File "/scratch/cnt0024/hmg2840/albert7a/anaconda3/lib/python3.7/site-packages/tornado/gen.py", line 735, in run
    value = future.result()
  File "/scratch/cnt0024/hmg2840/albert7a/anaconda3/lib/python3.7/site-packages/tornado/gen.py", line 742, in run
    yielded = self.gen.throw(*exc_info)  # type: ignore
  File "/scratch/cnt0024/hmg2840/albert7a/anaconda3/lib/python3.7/site-packages/distributed/core.py", line 864, in connect
    connection_args=self.connection_args,
  File "/scratch/cnt0024/hmg2840/albert7a/anaconda3/lib/python3.7/site-packages/tornado/gen.py", line 735, in run
    value = future.result()
  File "/scratch/cnt0024/hmg2840/albert7a/anaconda3/lib/python3.7/site-packages/tornado/gen.py", line 742, in run
    yielded = self.gen.throw(*exc_info)  # type: ignore
  File "/scratch/cnt0024/hmg2840/albert7a/anaconda3/lib/python3.7/site-packages/distributed/comm/core.py", line 230, in connect
    _raise(error)
  File "/scratch/cnt0024/hmg2840/albert7a/anaconda3/lib/python3.7/site-packages/distributed/comm/core.py", line 207, in _raise
    raise IOError(msg)
OSError: Timed out trying to connect to 'tcp://172.30.100.1:39168' after 10 s: connect() didn't finish in time
tornado.application - ERROR - Exception in callback functools.partial(<bound method IOLoop._discard_future_result of <tornado.platform.asyncio.AsyncIOLoop object at 0x2b1b8b721208>>, <Future finished exception=OSError("Timed out trying to connect to 'tcp://172.30.100.1:39168' after 10 s: connect() didn't finish in time")>)
Traceback (most recent call last):
  File "/scratch/cnt0024/hmg2840/albert7a/anaconda3/lib/python3.7/site-packages/distributed/comm/core.py", line 218, in connect
    quiet_exceptions=EnvironmentError,
  File "/scratch/cnt0024/hmg2840/albert7a/anaconda3/lib/python3.7/site-packages/tornado/gen.py", line 735, in run
    value = future.result()
tornado.util.TimeoutError: Timeout

During handling of the above exception, another exception occurred:

Traceback (most recent call last):
  File "/scratch/cnt0024/hmg2840/albert7a/anaconda3/lib/python3.7/site-packages/tornado/ioloop.py", line 743, in _run_callback
    ret = callback()
  File "/scratch/cnt0024/hmg2840/albert7a/anaconda3/lib/python3.7/site-packages/tornado/ioloop.py", line 767, in _discard_future_result
    future.result()
  File "/scratch/cnt0024/hmg2840/albert7a/anaconda3/lib/python3.7/site-packages/tornado/gen.py", line 742, in run
    yielded = self.gen.throw(*exc_info)  # type: ignore
  File "/scratch/cnt0024/hmg2840/albert7a/anaconda3/lib/python3.7/site-packages/distributed/worker.py", line 748, in heartbeat
    address=self.contact_address, now=time(), metrics=self.get_metrics()
  File "/scratch/cnt0024/hmg2840/albert7a/anaconda3/lib/python3.7/site-packages/tornado/gen.py", line 735, in run
    value = future.result()
  File "/scratch/cnt0024/hmg2840/albert7a/anaconda3/lib/python3.7/site-packages/tornado/gen.py", line 742, in run
    yielded = self.gen.throw(*exc_info)  # type: ignore
  File "/scratch/cnt0024/hmg2840/albert7a/anaconda3/lib/python3.7/site-packages/distributed/core.py", line 736, in send_recv_from_rpc
    comm = yield self.pool.connect(self.addr)
  File "/scratch/cnt0024/hmg2840/albert7a/anaconda3/lib/python3.7/site-packages/tornado/gen.py", line 735, in run
    value = future.result()
  File "/scratch/cnt0024/hmg2840/albert7a/anaconda3/lib/python3.7/site-packages/tornado/gen.py", line 742, in run
    yielded = self.gen.throw(*exc_info)  # type: ignore
  File "/scratch/cnt0024/hmg2840/albert7a/anaconda3/lib/python3.7/site-packages/distributed/core.py", line 864, in connect
    connection_args=self.connection_args,
  File "/scratch/cnt0024/hmg2840/albert7a/anaconda3/lib/python3.7/site-packages/tornado/gen.py", line 735, in run
    value = future.result()
  File "/scratch/cnt0024/hmg2840/albert7a/anaconda3/lib/python3.7/site-packages/tornado/gen.py", line 742, in run
    yielded = self.gen.throw(*exc_info)  # type: ignore
  File "/scratch/cnt0024/hmg2840/albert7a/anaconda3/lib/python3.7/site-packages/distributed/comm/core.py", line 230, in connect
    _raise(error)
  File "/scratch/cnt0024/hmg2840/albert7a/anaconda3/lib/python3.7/site-packages/distributed/comm/core.py", line 207, in _raise
    raise IOError(msg)
OSError: Timed out trying to connect to 'tcp://172.30.100.1:39168' after 10 s: connect() didn't finish in time
tornado.application - ERROR - Exception in callback functools.partial(<bound method IOLoop._discard_future_result of <tornado.platform.asyncio.AsyncIOLoop object at 0x2b1b8b721208>>, <Future finished exception=OSError("Timed out trying to connect to 'tcp://172.30.100.1:39168' after 10 s: connect() didn't finish in time")>)
Traceback (most recent call last):
  File "/scratch/cnt0024/hmg2840/albert7a/anaconda3/lib/python3.7/site-packages/distributed/comm/core.py", line 218, in connect
    quiet_exceptions=EnvironmentError,
  File "/scratch/cnt0024/hmg2840/albert7a/anaconda3/lib/python3.7/site-packages/tornado/gen.py", line 735, in run
    value = future.result()
tornado.util.TimeoutError: Timeout

During handling of the above exception, another exception occurred:

Traceback (most recent call last):
  File "/scratch/cnt0024/hmg2840/albert7a/anaconda3/lib/python3.7/site-packages/tornado/ioloop.py", line 743, in _run_callback
    ret = callback()
  File "/scratch/cnt0024/hmg2840/albert7a/anaconda3/lib/python3.7/site-packages/tornado/ioloop.py", line 767, in _discard_future_result
    future.result()
  File "/scratch/cnt0024/hmg2840/albert7a/anaconda3/lib/python3.7/site-packages/tornado/gen.py", line 742, in run
    yielded = self.gen.throw(*exc_info)  # type: ignore
  File "/scratch/cnt0024/hmg2840/albert7a/anaconda3/lib/python3.7/site-packages/distributed/worker.py", line 748, in heartbeat
    address=self.contact_address, now=time(), metrics=self.get_metrics()
  File "/scratch/cnt0024/hmg2840/albert7a/anaconda3/lib/python3.7/site-packages/tornado/gen.py", line 735, in run
    value = future.result()
  File "/scratch/cnt0024/hmg2840/albert7a/anaconda3/lib/python3.7/site-packages/tornado/gen.py", line 742, in run
    yielded = self.gen.throw(*exc_info)  # type: ignore
  File "/scratch/cnt0024/hmg2840/albert7a/anaconda3/lib/python3.7/site-packages/distributed/core.py", line 736, in send_recv_from_rpc
    comm = yield self.pool.connect(self.addr)
  File "/scratch/cnt0024/hmg2840/albert7a/anaconda3/lib/python3.7/site-packages/tornado/gen.py", line 735, in run
    value = future.result()
  File "/scratch/cnt0024/hmg2840/albert7a/anaconda3/lib/python3.7/site-packages/tornado/gen.py", line 742, in run
    yielded = self.gen.throw(*exc_info)  # type: ignore
  File "/scratch/cnt0024/hmg2840/albert7a/anaconda3/lib/python3.7/site-packages/distributed/core.py", line 864, in connect
    connection_args=self.connection_args,
  File "/scratch/cnt0024/hmg2840/albert7a/anaconda3/lib/python3.7/site-packages/tornado/gen.py", line 735, in run
    value = future.result()
  File "/scratch/cnt0024/hmg2840/albert7a/anaconda3/lib/python3.7/site-packages/tornado/gen.py", line 742, in run
    yielded = self.gen.throw(*exc_info)  # type: ignore
  File "/scratch/cnt0024/hmg2840/albert7a/anaconda3/lib/python3.7/site-packages/distributed/comm/core.py", line 230, in connect
    _raise(error)
  File "/scratch/cnt0024/hmg2840/albert7a/anaconda3/lib/python3.7/site-packages/distributed/comm/core.py", line 207, in _raise
    raise IOError(msg)
OSError: Timed out trying to connect to 'tcp://172.30.100.1:39168' after 10 s: connect() didn't finish in time
tornado.application - ERROR - Exception in callback functools.partial(<bound method IOLoop._discard_future_result of <tornado.platform.asyncio.AsyncIOLoop object at 0x2b1b8b721208>>, <Future finished exception=OSError("Timed out trying to connect to 'tcp://172.30.100.1:39168' after 10 s: connect() didn't finish in time")>)
Traceback (most recent call last):
  File "/scratch/cnt0024/hmg2840/albert7a/anaconda3/lib/python3.7/site-packages/distributed/comm/core.py", line 218, in connect
    quiet_exceptions=EnvironmentError,
  File "/scratch/cnt0024/hmg2840/albert7a/anaconda3/lib/python3.7/site-packages/tornado/gen.py", line 735, in run
    value = future.result()
tornado.util.TimeoutError: Timeout

During handling of the above exception, another exception occurred:

Traceback (most recent call last):
  File "/scratch/cnt0024/hmg2840/albert7a/anaconda3/lib/python3.7/site-packages/tornado/ioloop.py", line 743, in _run_callback
    ret = callback()
  File "/scratch/cnt0024/hmg2840/albert7a/anaconda3/lib/python3.7/site-packages/tornado/ioloop.py", line 767, in _discard_future_result
    future.result()
  File "/scratch/cnt0024/hmg2840/albert7a/anaconda3/lib/python3.7/site-packages/tornado/gen.py", line 742, in run
    yielded = self.gen.throw(*exc_info)  # type: ignore
  File "/scratch/cnt0024/hmg2840/albert7a/anaconda3/lib/python3.7/site-packages/distributed/worker.py", line 748, in heartbeat
    address=self.contact_address, now=time(), metrics=self.get_metrics()
  File "/scratch/cnt0024/hmg2840/albert7a/anaconda3/lib/python3.7/site-packages/tornado/gen.py", line 735, in run
    value = future.result()
  File "/scratch/cnt0024/hmg2840/albert7a/anaconda3/lib/python3.7/site-packages/tornado/gen.py", line 742, in run
    yielded = self.gen.throw(*exc_info)  # type: ignore
  File "/scratch/cnt0024/hmg2840/albert7a/anaconda3/lib/python3.7/site-packages/distributed/core.py", line 736, in send_recv_from_rpc
    comm = yield self.pool.connect(self.addr)
  File "/scratch/cnt0024/hmg2840/albert7a/anaconda3/lib/python3.7/site-packages/tornado/gen.py", line 735, in run
    value = future.result()
  File "/scratch/cnt0024/hmg2840/albert7a/anaconda3/lib/python3.7/site-packages/tornado/gen.py", line 742, in run
    yielded = self.gen.throw(*exc_info)  # type: ignore
  File "/scratch/cnt0024/hmg2840/albert7a/anaconda3/lib/python3.7/site-packages/distributed/core.py", line 864, in connect
    connection_args=self.connection_args,
  File "/scratch/cnt0024/hmg2840/albert7a/anaconda3/lib/python3.7/site-packages/tornado/gen.py", line 735, in run
    value = future.result()
  File "/scratch/cnt0024/hmg2840/albert7a/anaconda3/lib/python3.7/site-packages/tornado/gen.py", line 742, in run
    yielded = self.gen.throw(*exc_info)  # type: ignore
  File "/scratch/cnt0024/hmg2840/albert7a/anaconda3/lib/python3.7/site-packages/distributed/comm/core.py", line 230, in connect
    _raise(error)
  File "/scratch/cnt0024/hmg2840/albert7a/anaconda3/lib/python3.7/site-packages/distributed/comm/core.py", line 207, in _raise
    raise IOError(msg)
OSError: Timed out trying to connect to 'tcp://172.30.100.1:39168' after 10 s: connect() didn't finish in time
tornado.application - ERROR - Exception in callback functools.partial(<bound method IOLoop._discard_future_result of <tornado.platform.asyncio.AsyncIOLoop object at 0x2b1b8b721208>>, <Future finished exception=OSError("Timed out trying to connect to 'tcp://172.30.100.1:39168' after 10 s: connect() didn't finish in time")>)
Traceback (most recent call last):
  File "/scratch/cnt0024/hmg2840/albert7a/anaconda3/lib/python3.7/site-packages/distributed/comm/core.py", line 218, in connect
    quiet_exceptions=EnvironmentError,
  File "/scratch/cnt0024/hmg2840/albert7a/anaconda3/lib/python3.7/site-packages/tornado/gen.py", line 735, in run
    value = future.result()
tornado.util.TimeoutError: Timeout

During handling of the above exception, another exception occurred:

Traceback (most recent call last):
  File "/scratch/cnt0024/hmg2840/albert7a/anaconda3/lib/python3.7/site-packages/tornado/ioloop.py", line 743, in _run_callback
    ret = callback()
  File "/scratch/cnt0024/hmg2840/albert7a/anaconda3/lib/python3.7/site-packages/tornado/ioloop.py", line 767, in _discard_future_result
    future.result()
  File "/scratch/cnt0024/hmg2840/albert7a/anaconda3/lib/python3.7/site-packages/tornado/gen.py", line 742, in run
    yielded = self.gen.throw(*exc_info)  # type: ignore
  File "/scratch/cnt0024/hmg2840/albert7a/anaconda3/lib/python3.7/site-packages/distributed/worker.py", line 748, in heartbeat
    address=self.contact_address, now=time(), metrics=self.get_metrics()
  File "/scratch/cnt0024/hmg2840/albert7a/anaconda3/lib/python3.7/site-packages/tornado/gen.py", line 735, in run
    value = future.result()
  File "/scratch/cnt0024/hmg2840/albert7a/anaconda3/lib/python3.7/site-packages/tornado/gen.py", line 742, in run
    yielded = self.gen.throw(*exc_info)  # type: ignore
  File "/scratch/cnt0024/hmg2840/albert7a/anaconda3/lib/python3.7/site-packages/distributed/core.py", line 736, in send_recv_from_rpc
    comm = yield self.pool.connect(self.addr)
  File "/scratch/cnt0024/hmg2840/albert7a/anaconda3/lib/python3.7/site-packages/tornado/gen.py", line 735, in run
    value = future.result()
  File "/scratch/cnt0024/hmg2840/albert7a/anaconda3/lib/python3.7/site-packages/tornado/gen.py", line 742, in run
    yielded = self.gen.throw(*exc_info)  # type: ignore
  File "/scratch/cnt0024/hmg2840/albert7a/anaconda3/lib/python3.7/site-packages/distributed/core.py", line 864, in connect
    connection_args=self.connection_args,
  File "/scratch/cnt0024/hmg2840/albert7a/anaconda3/lib/python3.7/site-packages/tornado/gen.py", line 735, in run
    value = future.result()
  File "/scratch/cnt0024/hmg2840/albert7a/anaconda3/lib/python3.7/site-packages/tornado/gen.py", line 742, in run
    yielded = self.gen.throw(*exc_info)  # type: ignore
  File "/scratch/cnt0024/hmg2840/albert7a/anaconda3/lib/python3.7/site-packages/distributed/comm/core.py", line 230, in connect
    _raise(error)
  File "/scratch/cnt0024/hmg2840/albert7a/anaconda3/lib/python3.7/site-packages/distributed/comm/core.py", line 207, in _raise
    raise IOError(msg)
OSError: Timed out trying to connect to 'tcp://172.30.100.1:39168' after 10 s: connect() didn't finish in time
tornado.application - ERROR - Exception in callback functools.partial(<bound method IOLoop._discard_future_result of <tornado.platform.asyncio.AsyncIOLoop object at 0x2b1b8b721208>>, <Future finished exception=OSError("Timed out trying to connect to 'tcp://172.30.100.1:39168' after 10 s: connect() didn't finish in time")>)
Traceback (most recent call last):
  File "/scratch/cnt0024/hmg2840/albert7a/anaconda3/lib/python3.7/site-packages/distributed/comm/core.py", line 218, in connect
    quiet_exceptions=EnvironmentError,
  File "/scratch/cnt0024/hmg2840/albert7a/anaconda3/lib/python3.7/site-packages/tornado/gen.py", line 735, in run
    value = future.result()
tornado.util.TimeoutError: Timeout

During handling of the above exception, another exception occurred:

Traceback (most recent call last):
  File "/scratch/cnt0024/hmg2840/albert7a/anaconda3/lib/python3.7/site-packages/tornado/ioloop.py", line 743, in _run_callback
    ret = callback()
  File "/scratch/cnt0024/hmg2840/albert7a/anaconda3/lib/python3.7/site-packages/tornado/ioloop.py", line 767, in _discard_future_result
    future.result()
  File "/scratch/cnt0024/hmg2840/albert7a/anaconda3/lib/python3.7/site-packages/tornado/gen.py", line 742, in run
    yielded = self.gen.throw(*exc_info)  # type: ignore
  File "/scratch/cnt0024/hmg2840/albert7a/anaconda3/lib/python3.7/site-packages/distributed/worker.py", line 748, in heartbeat
    address=self.contact_address, now=time(), metrics=self.get_metrics()
  File "/scratch/cnt0024/hmg2840/albert7a/anaconda3/lib/python3.7/site-packages/tornado/gen.py", line 735, in run
    value = future.result()
  File "/scratch/cnt0024/hmg2840/albert7a/anaconda3/lib/python3.7/site-packages/tornado/gen.py", line 742, in run
    yielded = self.gen.throw(*exc_info)  # type: ignore
  File "/scratch/cnt0024/hmg2840/albert7a/anaconda3/lib/python3.7/site-packages/distributed/core.py", line 736, in send_recv_from_rpc
    comm = yield self.pool.connect(self.addr)
  File "/scratch/cnt0024/hmg2840/albert7a/anaconda3/lib/python3.7/site-packages/tornado/gen.py", line 735, in run
    value = future.result()
  File "/scratch/cnt0024/hmg2840/albert7a/anaconda3/lib/python3.7/site-packages/tornado/gen.py", line 742, in run
    yielded = self.gen.throw(*exc_info)  # type: ignore
  File "/scratch/cnt0024/hmg2840/albert7a/anaconda3/lib/python3.7/site-packages/distributed/core.py", line 864, in connect
    connection_args=self.connection_args,
  File "/scratch/cnt0024/hmg2840/albert7a/anaconda3/lib/python3.7/site-packages/tornado/gen.py", line 735, in run
    value = future.result()
  File "/scratch/cnt0024/hmg2840/albert7a/anaconda3/lib/python3.7/site-packages/tornado/gen.py", line 742, in run
    yielded = self.gen.throw(*exc_info)  # type: ignore
  File "/scratch/cnt0024/hmg2840/albert7a/anaconda3/lib/python3.7/site-packages/distributed/comm/core.py", line 230, in connect
    _raise(error)
  File "/scratch/cnt0024/hmg2840/albert7a/anaconda3/lib/python3.7/site-packages/distributed/comm/core.py", line 207, in _raise
    raise IOError(msg)
OSError: Timed out trying to connect to 'tcp://172.30.100.1:39168' after 10 s: connect() didn't finish in time
tornado.application - ERROR - Exception in callback functools.partial(<bound method IOLoop._discard_future_result of <tornado.platform.asyncio.AsyncIOLoop object at 0x2b1b8b721208>>, <Future finished exception=OSError("Timed out trying to connect to 'tcp://172.30.100.1:39168' after 10 s: connect() didn't finish in time")>)
Traceback (most recent call last):
  File "/scratch/cnt0024/hmg2840/albert7a/anaconda3/lib/python3.7/site-packages/distributed/comm/core.py", line 218, in connect
    quiet_exceptions=EnvironmentError,
  File "/scratch/cnt0024/hmg2840/albert7a/anaconda3/lib/python3.7/site-packages/tornado/gen.py", line 735, in run
    value = future.result()
tornado.util.TimeoutError: Timeout

During handling of the above exception, another exception occurred:

Traceback (most recent call last):
  File "/scratch/cnt0024/hmg2840/albert7a/anaconda3/lib/python3.7/site-packages/tornado/ioloop.py", line 743, in _run_callback
    ret = callback()
  File "/scratch/cnt0024/hmg2840/albert7a/anaconda3/lib/python3.7/site-packages/tornado/ioloop.py", line 767, in _discard_future_result
    future.result()
  File "/scratch/cnt0024/hmg2840/albert7a/anaconda3/lib/python3.7/site-packages/tornado/gen.py", line 742, in run
    yielded = self.gen.throw(*exc_info)  # type: ignore
  File "/scratch/cnt0024/hmg2840/albert7a/anaconda3/lib/python3.7/site-packages/distributed/worker.py", line 748, in heartbeat
    address=self.contact_address, now=time(), metrics=self.get_metrics()
  File "/scratch/cnt0024/hmg2840/albert7a/anaconda3/lib/python3.7/site-packages/tornado/gen.py", line 735, in run
    value = future.result()
  File "/scratch/cnt0024/hmg2840/albert7a/anaconda3/lib/python3.7/site-packages/tornado/gen.py", line 742, in run
    yielded = self.gen.throw(*exc_info)  # type: ignore
  File "/scratch/cnt0024/hmg2840/albert7a/anaconda3/lib/python3.7/site-packages/distributed/core.py", line 736, in send_recv_from_rpc
    comm = yield self.pool.connect(self.addr)
  File "/scratch/cnt0024/hmg2840/albert7a/anaconda3/lib/python3.7/site-packages/tornado/gen.py", line 735, in run
    value = future.result()
  File "/scratch/cnt0024/hmg2840/albert7a/anaconda3/lib/python3.7/site-packages/tornado/gen.py", line 742, in run
    yielded = self.gen.throw(*exc_info)  # type: ignore
  File "/scratch/cnt0024/hmg2840/albert7a/anaconda3/lib/python3.7/site-packages/distributed/core.py", line 864, in connect
    connection_args=self.connection_args,
  File "/scratch/cnt0024/hmg2840/albert7a/anaconda3/lib/python3.7/site-packages/tornado/gen.py", line 735, in run
    value = future.result()
  File "/scratch/cnt0024/hmg2840/albert7a/anaconda3/lib/python3.7/site-packages/tornado/gen.py", line 742, in run
    yielded = self.gen.throw(*exc_info)  # type: ignore
  File "/scratch/cnt0024/hmg2840/albert7a/anaconda3/lib/python3.7/site-packages/distributed/comm/core.py", line 230, in connect
    _raise(error)
  File "/scratch/cnt0024/hmg2840/albert7a/anaconda3/lib/python3.7/site-packages/distributed/comm/core.py", line 207, in _raise
    raise IOError(msg)
OSError: Timed out trying to connect to 'tcp://172.30.100.1:39168' after 10 s: connect() didn't finish in time
tornado.application - ERROR - Exception in callback functools.partial(<bound method IOLoop._discard_future_result of <tornado.platform.asyncio.AsyncIOLoop object at 0x2b1b8b721208>>, <Future finished exception=OSError("Timed out trying to connect to 'tcp://172.30.100.1:39168' after 10 s: connect() didn't finish in time")>)
Traceback (most recent call last):
  File "/scratch/cnt0024/hmg2840/albert7a/anaconda3/lib/python3.7/site-packages/distributed/comm/core.py", line 218, in connect
    quiet_exceptions=EnvironmentError,
  File "/scratch/cnt0024/hmg2840/albert7a/anaconda3/lib/python3.7/site-packages/tornado/gen.py", line 735, in run
    value = future.result()
tornado.util.TimeoutError: Timeout

During handling of the above exception, another exception occurred:

Traceback (most recent call last):
  File "/scratch/cnt0024/hmg2840/albert7a/anaconda3/lib/python3.7/site-packages/tornado/ioloop.py", line 743, in _run_callback
    ret = callback()
  File "/scratch/cnt0024/hmg2840/albert7a/anaconda3/lib/python3.7/site-packages/tornado/ioloop.py", line 767, in _discard_future_result
    future.result()
  File "/scratch/cnt0024/hmg2840/albert7a/anaconda3/lib/python3.7/site-packages/tornado/gen.py", line 742, in run
    yielded = self.gen.throw(*exc_info)  # type: ignore
  File "/scratch/cnt0024/hmg2840/albert7a/anaconda3/lib/python3.7/site-packages/distributed/worker.py", line 748, in heartbeat
    address=self.contact_address, now=time(), metrics=self.get_metrics()
  File "/scratch/cnt0024/hmg2840/albert7a/anaconda3/lib/python3.7/site-packages/tornado/gen.py", line 735, in run
    value = future.result()
  File "/scratch/cnt0024/hmg2840/albert7a/anaconda3/lib/python3.7/site-packages/tornado/gen.py", line 742, in run
    yielded = self.gen.throw(*exc_info)  # type: ignore
  File "/scratch/cnt0024/hmg2840/albert7a/anaconda3/lib/python3.7/site-packages/distributed/core.py", line 736, in send_recv_from_rpc
    comm = yield self.pool.connect(self.addr)
  File "/scratch/cnt0024/hmg2840/albert7a/anaconda3/lib/python3.7/site-packages/tornado/gen.py", line 735, in run
    value = future.result()
  File "/scratch/cnt0024/hmg2840/albert7a/anaconda3/lib/python3.7/site-packages/tornado/gen.py", line 742, in run
    yielded = self.gen.throw(*exc_info)  # type: ignore
  File "/scratch/cnt0024/hmg2840/albert7a/anaconda3/lib/python3.7/site-packages/distributed/core.py", line 864, in connect
    connection_args=self.connection_args,
  File "/scratch/cnt0024/hmg2840/albert7a/anaconda3/lib/python3.7/site-packages/tornado/gen.py", line 735, in run
    value = future.result()
  File "/scratch/cnt0024/hmg2840/albert7a/anaconda3/lib/python3.7/site-packages/tornado/gen.py", line 742, in run
    yielded = self.gen.throw(*exc_info)  # type: ignore
  File "/scratch/cnt0024/hmg2840/albert7a/anaconda3/lib/python3.7/site-packages/distributed/comm/core.py", line 230, in connect
    _raise(error)
  File "/scratch/cnt0024/hmg2840/albert7a/anaconda3/lib/python3.7/site-packages/distributed/comm/core.py", line 207, in _raise
    raise IOError(msg)
OSError: Timed out trying to connect to 'tcp://172.30.100.1:39168' after 10 s: connect() didn't finish in time
tornado.application - ERROR - Exception in callback functools.partial(<bound method IOLoop._discard_future_result of <tornado.platform.asyncio.AsyncIOLoop object at 0x2b1b8b721208>>, <Future finished exception=OSError("Timed out trying to connect to 'tcp://172.30.100.1:39168' after 10 s: connect() didn't finish in time")>)
Traceback (most recent call last):
  File "/scratch/cnt0024/hmg2840/albert7a/anaconda3/lib/python3.7/site-packages/distributed/comm/core.py", line 218, in connect
    quiet_exceptions=EnvironmentError,
  File "/scratch/cnt0024/hmg2840/albert7a/anaconda3/lib/python3.7/site-packages/tornado/gen.py", line 735, in run
    value = future.result()
tornado.util.TimeoutError: Timeout

During handling of the above exception, another exception occurred:

Traceback (most recent call last):
  File "/scratch/cnt0024/hmg2840/albert7a/anaconda3/lib/python3.7/site-packages/tornado/ioloop.py", line 743, in _run_callback
    ret = callback()
  File "/scratch/cnt0024/hmg2840/albert7a/anaconda3/lib/python3.7/site-packages/tornado/ioloop.py", line 767, in _discard_future_result
    future.result()
  File "/scratch/cnt0024/hmg2840/albert7a/anaconda3/lib/python3.7/site-packages/tornado/gen.py", line 742, in run
    yielded = self.gen.throw(*exc_info)  # type: ignore
  File "/scratch/cnt0024/hmg2840/albert7a/anaconda3/lib/python3.7/site-packages/distributed/worker.py", line 748, in heartbeat
    address=self.contact_address, now=time(), metrics=self.get_metrics()
  File "/scratch/cnt0024/hmg2840/albert7a/anaconda3/lib/python3.7/site-packages/tornado/gen.py", line 735, in run
    value = future.result()
  File "/scratch/cnt0024/hmg2840/albert7a/anaconda3/lib/python3.7/site-packages/tornado/gen.py", line 742, in run
    yielded = self.gen.throw(*exc_info)  # type: ignore
  File "/scratch/cnt0024/hmg2840/albert7a/anaconda3/lib/python3.7/site-packages/distributed/core.py", line 736, in send_recv_from_rpc
    comm = yield self.pool.connect(self.addr)
  File "/scratch/cnt0024/hmg2840/albert7a/anaconda3/lib/python3.7/site-packages/tornado/gen.py", line 735, in run
    value = future.result()
  File "/scratch/cnt0024/hmg2840/albert7a/anaconda3/lib/python3.7/site-packages/tornado/gen.py", line 742, in run
    yielded = self.gen.throw(*exc_info)  # type: ignore
  File "/scratch/cnt0024/hmg2840/albert7a/anaconda3/lib/python3.7/site-packages/distributed/core.py", line 864, in connect
    connection_args=self.connection_args,
  File "/scratch/cnt0024/hmg2840/albert7a/anaconda3/lib/python3.7/site-packages/tornado/gen.py", line 735, in run
    value = future.result()
  File "/scratch/cnt0024/hmg2840/albert7a/anaconda3/lib/python3.7/site-packages/tornado/gen.py", line 742, in run
    yielded = self.gen.throw(*exc_info)  # type: ignore
  File "/scratch/cnt0024/hmg2840/albert7a/anaconda3/lib/python3.7/site-packages/distributed/comm/core.py", line 230, in connect
    _raise(error)
  File "/scratch/cnt0024/hmg2840/albert7a/anaconda3/lib/python3.7/site-packages/distributed/comm/core.py", line 207, in _raise
    raise IOError(msg)
OSError: Timed out trying to connect to 'tcp://172.30.100.1:39168' after 10 s: connect() didn't finish in time
tornado.application - ERROR - Exception in callback functools.partial(<bound method IOLoop._discard_future_result of <tornado.platform.asyncio.AsyncIOLoop object at 0x2b1b8b721208>>, <Future finished exception=OSError("Timed out trying to connect to 'tcp://172.30.100.1:39168' after 10 s: connect() didn't finish in time")>)
Traceback (most recent call last):
  File "/scratch/cnt0024/hmg2840/albert7a/anaconda3/lib/python3.7/site-packages/distributed/comm/core.py", line 218, in connect
    quiet_exceptions=EnvironmentError,
  File "/scratch/cnt0024/hmg2840/albert7a/anaconda3/lib/python3.7/site-packages/tornado/gen.py", line 735, in run
    value = future.result()
tornado.util.TimeoutError: Timeout

During handling of the above exception, another exception occurred:

Traceback (most recent call last):
  File "/scratch/cnt0024/hmg2840/albert7a/anaconda3/lib/python3.7/site-packages/tornado/ioloop.py", line 743, in _run_callback
    ret = callback()
  File "/scratch/cnt0024/hmg2840/albert7a/anaconda3/lib/python3.7/site-packages/tornado/ioloop.py", line 767, in _discard_future_result
    future.result()
  File "/scratch/cnt0024/hmg2840/albert7a/anaconda3/lib/python3.7/site-packages/tornado/gen.py", line 742, in run
    yielded = self.gen.throw(*exc_info)  # type: ignore
  File "/scratch/cnt0024/hmg2840/albert7a/anaconda3/lib/python3.7/site-packages/distributed/worker.py", line 748, in heartbeat
    address=self.contact_address, now=time(), metrics=self.get_metrics()
  File "/scratch/cnt0024/hmg2840/albert7a/anaconda3/lib/python3.7/site-packages/tornado/gen.py", line 735, in run
    value = future.result()
  File "/scratch/cnt0024/hmg2840/albert7a/anaconda3/lib/python3.7/site-packages/tornado/gen.py", line 742, in run
    yielded = self.gen.throw(*exc_info)  # type: ignore
  File "/scratch/cnt0024/hmg2840/albert7a/anaconda3/lib/python3.7/site-packages/distributed/core.py", line 736, in send_recv_from_rpc
    comm = yield self.pool.connect(self.addr)
  File "/scratch/cnt0024/hmg2840/albert7a/anaconda3/lib/python3.7/site-packages/tornado/gen.py", line 735, in run
    value = future.result()
  File "/scratch/cnt0024/hmg2840/albert7a/anaconda3/lib/python3.7/site-packages/tornado/gen.py", line 742, in run
    yielded = self.gen.throw(*exc_info)  # type: ignore
  File "/scratch/cnt0024/hmg2840/albert7a/anaconda3/lib/python3.7/site-packages/distributed/core.py", line 864, in connect
    connection_args=self.connection_args,
  File "/scratch/cnt0024/hmg2840/albert7a/anaconda3/lib/python3.7/site-packages/tornado/gen.py", line 735, in run
    value = future.result()
  File "/scratch/cnt0024/hmg2840/albert7a/anaconda3/lib/python3.7/site-packages/tornado/gen.py", line 742, in run
    yielded = self.gen.throw(*exc_info)  # type: ignore
  File "/scratch/cnt0024/hmg2840/albert7a/anaconda3/lib/python3.7/site-packages/distributed/comm/core.py", line 230, in connect
    _raise(error)
  File "/scratch/cnt0024/hmg2840/albert7a/anaconda3/lib/python3.7/site-packages/distributed/comm/core.py", line 207, in _raise
    raise IOError(msg)
OSError: Timed out trying to connect to 'tcp://172.30.100.1:39168' after 10 s: connect() didn't finish in time
tornado.application - ERROR - Exception in callback functools.partial(<bound method IOLoop._discard_future_result of <tornado.platform.asyncio.AsyncIOLoop object at 0x2b1b8b721208>>, <Future finished exception=OSError("Timed out trying to connect to 'tcp://172.30.100.1:39168' after 10 s: connect() didn't finish in time")>)
Traceback (most recent call last):
  File "/scratch/cnt0024/hmg2840/albert7a/anaconda3/lib/python3.7/site-packages/distributed/comm/core.py", line 218, in connect
    quiet_exceptions=EnvironmentError,
  File "/scratch/cnt0024/hmg2840/albert7a/anaconda3/lib/python3.7/site-packages/tornado/gen.py", line 735, in run
    value = future.result()
tornado.util.TimeoutError: Timeout

During handling of the above exception, another exception occurred:

Traceback (most recent call last):
  File "/scratch/cnt0024/hmg2840/albert7a/anaconda3/lib/python3.7/site-packages/tornado/ioloop.py", line 743, in _run_callback
    ret = callback()
  File "/scratch/cnt0024/hmg2840/albert7a/anaconda3/lib/python3.7/site-packages/tornado/ioloop.py", line 767, in _discard_future_result
    future.result()
  File "/scratch/cnt0024/hmg2840/albert7a/anaconda3/lib/python3.7/site-packages/tornado/gen.py", line 742, in run
    yielded = self.gen.throw(*exc_info)  # type: ignore
  File "/scratch/cnt0024/hmg2840/albert7a/anaconda3/lib/python3.7/site-packages/distributed/worker.py", line 748, in heartbeat
    address=self.contact_address, now=time(), metrics=self.get_metrics()
  File "/scratch/cnt0024/hmg2840/albert7a/anaconda3/lib/python3.7/site-packages/tornado/gen.py", line 735, in run
    value = future.result()
  File "/scratch/cnt0024/hmg2840/albert7a/anaconda3/lib/python3.7/site-packages/tornado/gen.py", line 742, in run
    yielded = self.gen.throw(*exc_info)  # type: ignore
  File "/scratch/cnt0024/hmg2840/albert7a/anaconda3/lib/python3.7/site-packages/distributed/core.py", line 736, in send_recv_from_rpc
    comm = yield self.pool.connect(self.addr)
  File "/scratch/cnt0024/hmg2840/albert7a/anaconda3/lib/python3.7/site-packages/tornado/gen.py", line 735, in run
    value = future.result()
  File "/scratch/cnt0024/hmg2840/albert7a/anaconda3/lib/python3.7/site-packages/tornado/gen.py", line 742, in run
    yielded = self.gen.throw(*exc_info)  # type: ignore
  File "/scratch/cnt0024/hmg2840/albert7a/anaconda3/lib/python3.7/site-packages/distributed/core.py", line 864, in connect
    connection_args=self.connection_args,
  File "/scratch/cnt0024/hmg2840/albert7a/anaconda3/lib/python3.7/site-packages/tornado/gen.py", line 735, in run
    value = future.result()
  File "/scratch/cnt0024/hmg2840/albert7a/anaconda3/lib/python3.7/site-packages/tornado/gen.py", line 742, in run
    yielded = self.gen.throw(*exc_info)  # type: ignore
  File "/scratch/cnt0024/hmg2840/albert7a/anaconda3/lib/python3.7/site-packages/distributed/comm/core.py", line 230, in connect
    _raise(error)
  File "/scratch/cnt0024/hmg2840/albert7a/anaconda3/lib/python3.7/site-packages/distributed/comm/core.py", line 207, in _raise
    raise IOError(msg)
OSError: Timed out trying to connect to 'tcp://172.30.100.1:39168' after 10 s: connect() didn't finish in time
tornado.application - ERROR - Exception in callback functools.partial(<bound method IOLoop._discard_future_result of <tornado.platform.asyncio.AsyncIOLoop object at 0x2b1b8b721208>>, <Future finished exception=OSError("Timed out trying to connect to 'tcp://172.30.100.1:39168' after 10 s: connect() didn't finish in time")>)
Traceback (most recent call last):
  File "/scratch/cnt0024/hmg2840/albert7a/anaconda3/lib/python3.7/site-packages/distributed/comm/core.py", line 218, in connect
    quiet_exceptions=EnvironmentError,
  File "/scratch/cnt0024/hmg2840/albert7a/anaconda3/lib/python3.7/site-packages/tornado/gen.py", line 735, in run
    value = future.result()
tornado.util.TimeoutError: Timeout

During handling of the above exception, another exception occurred:

Traceback (most recent call last):
  File "/scratch/cnt0024/hmg2840/albert7a/anaconda3/lib/python3.7/site-packages/tornado/ioloop.py", line 743, in _run_callback
    ret = callback()
  File "/scratch/cnt0024/hmg2840/albert7a/anaconda3/lib/python3.7/site-packages/tornado/ioloop.py", line 767, in _discard_future_result
    future.result()
  File "/scratch/cnt0024/hmg2840/albert7a/anaconda3/lib/python3.7/site-packages/tornado/gen.py", line 742, in run
    yielded = self.gen.throw(*exc_info)  # type: ignore
  File "/scratch/cnt0024/hmg2840/albert7a/anaconda3/lib/python3.7/site-packages/distributed/worker.py", line 748, in heartbeat
    address=self.contact_address, now=time(), metrics=self.get_metrics()
  File "/scratch/cnt0024/hmg2840/albert7a/anaconda3/lib/python3.7/site-packages/tornado/gen.py", line 735, in run
    value = future.result()
  File "/scratch/cnt0024/hmg2840/albert7a/anaconda3/lib/python3.7/site-packages/tornado/gen.py", line 742, in run
    yielded = self.gen.throw(*exc_info)  # type: ignore
  File "/scratch/cnt0024/hmg2840/albert7a/anaconda3/lib/python3.7/site-packages/distributed/core.py", line 736, in send_recv_from_rpc
    comm = yield self.pool.connect(self.addr)
  File "/scratch/cnt0024/hmg2840/albert7a/anaconda3/lib/python3.7/site-packages/tornado/gen.py", line 735, in run
    value = future.result()
  File "/scratch/cnt0024/hmg2840/albert7a/anaconda3/lib/python3.7/site-packages/tornado/gen.py", line 742, in run
    yielded = self.gen.throw(*exc_info)  # type: ignore
  File "/scratch/cnt0024/hmg2840/albert7a/anaconda3/lib/python3.7/site-packages/distributed/core.py", line 864, in connect
    connection_args=self.connection_args,
  File "/scratch/cnt0024/hmg2840/albert7a/anaconda3/lib/python3.7/site-packages/tornado/gen.py", line 735, in run
    value = future.result()
  File "/scratch/cnt0024/hmg2840/albert7a/anaconda3/lib/python3.7/site-packages/tornado/gen.py", line 742, in run
    yielded = self.gen.throw(*exc_info)  # type: ignore
  File "/scratch/cnt0024/hmg2840/albert7a/anaconda3/lib/python3.7/site-packages/distributed/comm/core.py", line 230, in connect
    _raise(error)
  File "/scratch/cnt0024/hmg2840/albert7a/anaconda3/lib/python3.7/site-packages/distributed/comm/core.py", line 207, in _raise
    raise IOError(msg)
OSError: Timed out trying to connect to 'tcp://172.30.100.1:39168' after 10 s: connect() didn't finish in time
tornado.application - ERROR - Exception in callback functools.partial(<bound method IOLoop._discard_future_result of <tornado.platform.asyncio.AsyncIOLoop object at 0x2b1b8b721208>>, <Future finished exception=OSError("Timed out trying to connect to 'tcp://172.30.100.1:39168' after 10 s: connect() didn't finish in time")>)
Traceback (most recent call last):
  File "/scratch/cnt0024/hmg2840/albert7a/anaconda3/lib/python3.7/site-packages/distributed/comm/core.py", line 218, in connect
    quiet_exceptions=EnvironmentError,
  File "/scratch/cnt0024/hmg2840/albert7a/anaconda3/lib/python3.7/site-packages/tornado/gen.py", line 735, in run
    value = future.result()
tornado.util.TimeoutError: Timeout

During handling of the above exception, another exception occurred:

Traceback (most recent call last):
  File "/scratch/cnt0024/hmg2840/albert7a/anaconda3/lib/python3.7/site-packages/tornado/ioloop.py", line 743, in _run_callback
    ret = callback()
  File "/scratch/cnt0024/hmg2840/albert7a/anaconda3/lib/python3.7/site-packages/tornado/ioloop.py", line 767, in _discard_future_result
    future.result()
  File "/scratch/cnt0024/hmg2840/albert7a/anaconda3/lib/python3.7/site-packages/tornado/gen.py", line 742, in run
    yielded = self.gen.throw(*exc_info)  # type: ignore
  File "/scratch/cnt0024/hmg2840/albert7a/anaconda3/lib/python3.7/site-packages/distributed/worker.py", line 748, in heartbeat
    address=self.contact_address, now=time(), metrics=self.get_metrics()
  File "/scratch/cnt0024/hmg2840/albert7a/anaconda3/lib/python3.7/site-packages/tornado/gen.py", line 735, in run
    value = future.result()
  File "/scratch/cnt0024/hmg2840/albert7a/anaconda3/lib/python3.7/site-packages/tornado/gen.py", line 742, in run
    yielded = self.gen.throw(*exc_info)  # type: ignore
  File "/scratch/cnt0024/hmg2840/albert7a/anaconda3/lib/python3.7/site-packages/distributed/core.py", line 736, in send_recv_from_rpc
    comm = yield self.pool.connect(self.addr)
  File "/scratch/cnt0024/hmg2840/albert7a/anaconda3/lib/python3.7/site-packages/tornado/gen.py", line 735, in run
    value = future.result()
  File "/scratch/cnt0024/hmg2840/albert7a/anaconda3/lib/python3.7/site-packages/tornado/gen.py", line 742, in run
    yielded = self.gen.throw(*exc_info)  # type: ignore
  File "/scratch/cnt0024/hmg2840/albert7a/anaconda3/lib/python3.7/site-packages/distributed/core.py", line 864, in connect
    connection_args=self.connection_args,
  File "/scratch/cnt0024/hmg2840/albert7a/anaconda3/lib/python3.7/site-packages/tornado/gen.py", line 735, in run
    value = future.result()
  File "/scratch/cnt0024/hmg2840/albert7a/anaconda3/lib/python3.7/site-packages/tornado/gen.py", line 742, in run
    yielded = self.gen.throw(*exc_info)  # type: ignore
  File "/scratch/cnt0024/hmg2840/albert7a/anaconda3/lib/python3.7/site-packages/distributed/comm/core.py", line 230, in connect
    _raise(error)
  File "/scratch/cnt0024/hmg2840/albert7a/anaconda3/lib/python3.7/site-packages/distributed/comm/core.py", line 207, in _raise
    raise IOError(msg)
OSError: Timed out trying to connect to 'tcp://172.30.100.1:39168' after 10 s: connect() didn't finish in time
tornado.application - ERROR - Exception in callback functools.partial(<bound method IOLoop._discard_future_result of <tornado.platform.asyncio.AsyncIOLoop object at 0x2b1b8b721208>>, <Future finished exception=OSError("Timed out trying to connect to 'tcp://172.30.100.1:39168' after 10 s: connect() didn't finish in time")>)
Traceback (most recent call last):
  File "/scratch/cnt0024/hmg2840/albert7a/anaconda3/lib/python3.7/site-packages/distributed/comm/core.py", line 218, in connect
    quiet_exceptions=EnvironmentError,
  File "/scratch/cnt0024/hmg2840/albert7a/anaconda3/lib/python3.7/site-packages/tornado/gen.py", line 735, in run
    value = future.result()
tornado.util.TimeoutError: Timeout

During handling of the above exception, another exception occurred:

Traceback (most recent call last):
  File "/scratch/cnt0024/hmg2840/albert7a/anaconda3/lib/python3.7/site-packages/tornado/ioloop.py", line 743, in _run_callback
    ret = callback()
  File "/scratch/cnt0024/hmg2840/albert7a/anaconda3/lib/python3.7/site-packages/tornado/ioloop.py", line 767, in _discard_future_result
    future.result()
  File "/scratch/cnt0024/hmg2840/albert7a/anaconda3/lib/python3.7/site-packages/tornado/gen.py", line 742, in run
    yielded = self.gen.throw(*exc_info)  # type: ignore
  File "/scratch/cnt0024/hmg2840/albert7a/anaconda3/lib/python3.7/site-packages/distributed/worker.py", line 748, in heartbeat
    address=self.contact_address, now=time(), metrics=self.get_metrics()
  File "/scratch/cnt0024/hmg2840/albert7a/anaconda3/lib/python3.7/site-packages/tornado/gen.py", line 735, in run
    value = future.result()
  File "/scratch/cnt0024/hmg2840/albert7a/anaconda3/lib/python3.7/site-packages/tornado/gen.py", line 742, in run
    yielded = self.gen.throw(*exc_info)  # type: ignore
  File "/scratch/cnt0024/hmg2840/albert7a/anaconda3/lib/python3.7/site-packages/distributed/core.py", line 736, in send_recv_from_rpc
    comm = yield self.pool.connect(self.addr)
  File "/scratch/cnt0024/hmg2840/albert7a/anaconda3/lib/python3.7/site-packages/tornado/gen.py", line 735, in run
    value = future.result()
  File "/scratch/cnt0024/hmg2840/albert7a/anaconda3/lib/python3.7/site-packages/tornado/gen.py", line 742, in run
    yielded = self.gen.throw(*exc_info)  # type: ignore
  File "/scratch/cnt0024/hmg2840/albert7a/anaconda3/lib/python3.7/site-packages/distributed/core.py", line 864, in connect
    connection_args=self.connection_args,
  File "/scratch/cnt0024/hmg2840/albert7a/anaconda3/lib/python3.7/site-packages/tornado/gen.py", line 735, in run
    value = future.result()
  File "/scratch/cnt0024/hmg2840/albert7a/anaconda3/lib/python3.7/site-packages/tornado/gen.py", line 742, in run
    yielded = self.gen.throw(*exc_info)  # type: ignore
  File "/scratch/cnt0024/hmg2840/albert7a/anaconda3/lib/python3.7/site-packages/distributed/comm/core.py", line 230, in connect
    _raise(error)
  File "/scratch/cnt0024/hmg2840/albert7a/anaconda3/lib/python3.7/site-packages/distributed/comm/core.py", line 207, in _raise
    raise IOError(msg)
OSError: Timed out trying to connect to 'tcp://172.30.100.1:39168' after 10 s: connect() didn't finish in time
tornado.application - ERROR - Exception in callback functools.partial(<bound method IOLoop._discard_future_result of <tornado.platform.asyncio.AsyncIOLoop object at 0x2b1b8b721208>>, <Future finished exception=OSError("Timed out trying to connect to 'tcp://172.30.100.1:39168' after 10 s: connect() didn't finish in time")>)
Traceback (most recent call last):
  File "/scratch/cnt0024/hmg2840/albert7a/anaconda3/lib/python3.7/site-packages/distributed/comm/core.py", line 218, in connect
    quiet_exceptions=EnvironmentError,
  File "/scratch/cnt0024/hmg2840/albert7a/anaconda3/lib/python3.7/site-packages/tornado/gen.py", line 735, in run
    value = future.result()
tornado.util.TimeoutError: Timeout

During handling of the above exception, another exception occurred:

Traceback (most recent call last):
  File "/scratch/cnt0024/hmg2840/albert7a/anaconda3/lib/python3.7/site-packages/tornado/ioloop.py", line 743, in _run_callback
    ret = callback()
  File "/scratch/cnt0024/hmg2840/albert7a/anaconda3/lib/python3.7/site-packages/tornado/ioloop.py", line 767, in _discard_future_result
    future.result()
  File "/scratch/cnt0024/hmg2840/albert7a/anaconda3/lib/python3.7/site-packages/tornado/gen.py", line 742, in run
    yielded = self.gen.throw(*exc_info)  # type: ignore
  File "/scratch/cnt0024/hmg2840/albert7a/anaconda3/lib/python3.7/site-packages/distributed/worker.py", line 748, in heartbeat
    address=self.contact_address, now=time(), metrics=self.get_metrics()
  File "/scratch/cnt0024/hmg2840/albert7a/anaconda3/lib/python3.7/site-packages/tornado/gen.py", line 735, in run
    value = future.result()
  File "/scratch/cnt0024/hmg2840/albert7a/anaconda3/lib/python3.7/site-packages/tornado/gen.py", line 742, in run
    yielded = self.gen.throw(*exc_info)  # type: ignore
  File "/scratch/cnt0024/hmg2840/albert7a/anaconda3/lib/python3.7/site-packages/distributed/core.py", line 736, in send_recv_from_rpc
    comm = yield self.pool.connect(self.addr)
  File "/scratch/cnt0024/hmg2840/albert7a/anaconda3/lib/python3.7/site-packages/tornado/gen.py", line 735, in run
    value = future.result()
  File "/scratch/cnt0024/hmg2840/albert7a/anaconda3/lib/python3.7/site-packages/tornado/gen.py", line 742, in run
    yielded = self.gen.throw(*exc_info)  # type: ignore
  File "/scratch/cnt0024/hmg2840/albert7a/anaconda3/lib/python3.7/site-packages/distributed/core.py", line 864, in connect
    connection_args=self.connection_args,
  File "/scratch/cnt0024/hmg2840/albert7a/anaconda3/lib/python3.7/site-packages/tornado/gen.py", line 735, in run
    value = future.result()
  File "/scratch/cnt0024/hmg2840/albert7a/anaconda3/lib/python3.7/site-packages/tornado/gen.py", line 742, in run
    yielded = self.gen.throw(*exc_info)  # type: ignore
  File "/scratch/cnt0024/hmg2840/albert7a/anaconda3/lib/python3.7/site-packages/distributed/comm/core.py", line 230, in connect
    _raise(error)
  File "/scratch/cnt0024/hmg2840/albert7a/anaconda3/lib/python3.7/site-packages/distributed/comm/core.py", line 207, in _raise
    raise IOError(msg)
OSError: Timed out trying to connect to 'tcp://172.30.100.1:39168' after 10 s: connect() didn't finish in time
tornado.application - ERROR - Exception in callback functools.partial(<bound method IOLoop._discard_future_result of <tornado.platform.asyncio.AsyncIOLoop object at 0x2b1b8b721208>>, <Future finished exception=OSError("Timed out trying to connect to 'tcp://172.30.100.1:39168' after 10 s: connect() didn't finish in time")>)
Traceback (most recent call last):
  File "/scratch/cnt0024/hmg2840/albert7a/anaconda3/lib/python3.7/site-packages/distributed/comm/core.py", line 218, in connect
    quiet_exceptions=EnvironmentError,
  File "/scratch/cnt0024/hmg2840/albert7a/anaconda3/lib/python3.7/site-packages/tornado/gen.py", line 735, in run
    value = future.result()
tornado.util.TimeoutError: Timeout

During handling of the above exception, another exception occurred:

Traceback (most recent call last):
  File "/scratch/cnt0024/hmg2840/albert7a/anaconda3/lib/python3.7/site-packages/tornado/ioloop.py", line 743, in _run_callback
    ret = callback()
  File "/scratch/cnt0024/hmg2840/albert7a/anaconda3/lib/python3.7/site-packages/tornado/ioloop.py", line 767, in _discard_future_result
    future.result()
  File "/scratch/cnt0024/hmg2840/albert7a/anaconda3/lib/python3.7/site-packages/tornado/gen.py", line 742, in run
    yielded = self.gen.throw(*exc_info)  # type: ignore
  File "/scratch/cnt0024/hmg2840/albert7a/anaconda3/lib/python3.7/site-packages/distributed/worker.py", line 748, in heartbeat
    address=self.contact_address, now=time(), metrics=self.get_metrics()
  File "/scratch/cnt0024/hmg2840/albert7a/anaconda3/lib/python3.7/site-packages/tornado/gen.py", line 735, in run
    value = future.result()
  File "/scratch/cnt0024/hmg2840/albert7a/anaconda3/lib/python3.7/site-packages/tornado/gen.py", line 742, in run
    yielded = self.gen.throw(*exc_info)  # type: ignore
  File "/scratch/cnt0024/hmg2840/albert7a/anaconda3/lib/python3.7/site-packages/distributed/core.py", line 736, in send_recv_from_rpc
    comm = yield self.pool.connect(self.addr)
  File "/scratch/cnt0024/hmg2840/albert7a/anaconda3/lib/python3.7/site-packages/tornado/gen.py", line 735, in run
    value = future.result()
  File "/scratch/cnt0024/hmg2840/albert7a/anaconda3/lib/python3.7/site-packages/tornado/gen.py", line 742, in run
    yielded = self.gen.throw(*exc_info)  # type: ignore
  File "/scratch/cnt0024/hmg2840/albert7a/anaconda3/lib/python3.7/site-packages/distributed/core.py", line 864, in connect
    connection_args=self.connection_args,
  File "/scratch/cnt0024/hmg2840/albert7a/anaconda3/lib/python3.7/site-packages/tornado/gen.py", line 735, in run
    value = future.result()
  File "/scratch/cnt0024/hmg2840/albert7a/anaconda3/lib/python3.7/site-packages/tornado/gen.py", line 742, in run
    yielded = self.gen.throw(*exc_info)  # type: ignore
  File "/scratch/cnt0024/hmg2840/albert7a/anaconda3/lib/python3.7/site-packages/distributed/comm/core.py", line 230, in connect
    _raise(error)
  File "/scratch/cnt0024/hmg2840/albert7a/anaconda3/lib/python3.7/site-packages/distributed/comm/core.py", line 207, in _raise
    raise IOError(msg)
OSError: Timed out trying to connect to 'tcp://172.30.100.1:39168' after 10 s: connect() didn't finish in time
tornado.application - ERROR - Exception in callback functools.partial(<bound method IOLoop._discard_future_result of <tornado.platform.asyncio.AsyncIOLoop object at 0x2b1b8b721208>>, <Future finished exception=OSError("Timed out trying to connect to 'tcp://172.30.100.1:39168' after 10 s: connect() didn't finish in time")>)
Traceback (most recent call last):
  File "/scratch/cnt0024/hmg2840/albert7a/anaconda3/lib/python3.7/site-packages/distributed/comm/core.py", line 218, in connect
    quiet_exceptions=EnvironmentError,
  File "/scratch/cnt0024/hmg2840/albert7a/anaconda3/lib/python3.7/site-packages/tornado/gen.py", line 735, in run
    value = future.result()
tornado.util.TimeoutError: Timeout

During handling of the above exception, another exception occurred:

Traceback (most recent call last):
  File "/scratch/cnt0024/hmg2840/albert7a/anaconda3/lib/python3.7/site-packages/tornado/ioloop.py", line 743, in _run_callback
    ret = callback()
  File "/scratch/cnt0024/hmg2840/albert7a/anaconda3/lib/python3.7/site-packages/tornado/ioloop.py", line 767, in _discard_future_result
    future.result()
  File "/scratch/cnt0024/hmg2840/albert7a/anaconda3/lib/python3.7/site-packages/tornado/gen.py", line 742, in run
    yielded = self.gen.throw(*exc_info)  # type: ignore
  File "/scratch/cnt0024/hmg2840/albert7a/anaconda3/lib/python3.7/site-packages/distributed/worker.py", line 748, in heartbeat
    address=self.contact_address, now=time(), metrics=self.get_metrics()
  File "/scratch/cnt0024/hmg2840/albert7a/anaconda3/lib/python3.7/site-packages/tornado/gen.py", line 735, in run
    value = future.result()
  File "/scratch/cnt0024/hmg2840/albert7a/anaconda3/lib/python3.7/site-packages/tornado/gen.py", line 742, in run
    yielded = self.gen.throw(*exc_info)  # type: ignore
  File "/scratch/cnt0024/hmg2840/albert7a/anaconda3/lib/python3.7/site-packages/distributed/core.py", line 736, in send_recv_from_rpc
    comm = yield self.pool.connect(self.addr)
  File "/scratch/cnt0024/hmg2840/albert7a/anaconda3/lib/python3.7/site-packages/tornado/gen.py", line 735, in run
    value = future.result()
  File "/scratch/cnt0024/hmg2840/albert7a/anaconda3/lib/python3.7/site-packages/tornado/gen.py", line 742, in run
    yielded = self.gen.throw(*exc_info)  # type: ignore
  File "/scratch/cnt0024/hmg2840/albert7a/anaconda3/lib/python3.7/site-packages/distributed/core.py", line 864, in connect
    connection_args=self.connection_args,
  File "/scratch/cnt0024/hmg2840/albert7a/anaconda3/lib/python3.7/site-packages/tornado/gen.py", line 735, in run
    value = future.result()
  File "/scratch/cnt0024/hmg2840/albert7a/anaconda3/lib/python3.7/site-packages/tornado/gen.py", line 742, in run
    yielded = self.gen.throw(*exc_info)  # type: ignore
  File "/scratch/cnt0024/hmg2840/albert7a/anaconda3/lib/python3.7/site-packages/distributed/comm/core.py", line 230, in connect
    _raise(error)
  File "/scratch/cnt0024/hmg2840/albert7a/anaconda3/lib/python3.7/site-packages/distributed/comm/core.py", line 207, in _raise
    raise IOError(msg)
OSError: Timed out trying to connect to 'tcp://172.30.100.1:39168' after 10 s: connect() didn't finish in time
tornado.application - ERROR - Exception in callback functools.partial(<bound method IOLoop._discard_future_result of <tornado.platform.asyncio.AsyncIOLoop object at 0x2b1b8b721208>>, <Future finished exception=OSError("Timed out trying to connect to 'tcp://172.30.100.1:39168' after 10 s: connect() didn't finish in time")>)
Traceback (most recent call last):
  File "/scratch/cnt0024/hmg2840/albert7a/anaconda3/lib/python3.7/site-packages/distributed/comm/core.py", line 218, in connect
    quiet_exceptions=EnvironmentError,
  File "/scratch/cnt0024/hmg2840/albert7a/anaconda3/lib/python3.7/site-packages/tornado/gen.py", line 735, in run
    value = future.result()
tornado.util.TimeoutError: Timeout

During handling of the above exception, another exception occurred:

Traceback (most recent call last):
  File "/scratch/cnt0024/hmg2840/albert7a/anaconda3/lib/python3.7/site-packages/tornado/ioloop.py", line 743, in _run_callback
    ret = callback()
  File "/scratch/cnt0024/hmg2840/albert7a/anaconda3/lib/python3.7/site-packages/tornado/ioloop.py", line 767, in _discard_future_result
    future.result()
  File "/scratch/cnt0024/hmg2840/albert7a/anaconda3/lib/python3.7/site-packages/tornado/gen.py", line 742, in run
    yielded = self.gen.throw(*exc_info)  # type: ignore
  File "/scratch/cnt0024/hmg2840/albert7a/anaconda3/lib/python3.7/site-packages/distributed/worker.py", line 748, in heartbeat
    address=self.contact_address, now=time(), metrics=self.get_metrics()
  File "/scratch/cnt0024/hmg2840/albert7a/anaconda3/lib/python3.7/site-packages/tornado/gen.py", line 735, in run
    value = future.result()
  File "/scratch/cnt0024/hmg2840/albert7a/anaconda3/lib/python3.7/site-packages/tornado/gen.py", line 742, in run
    yielded = self.gen.throw(*exc_info)  # type: ignore
  File "/scratch/cnt0024/hmg2840/albert7a/anaconda3/lib/python3.7/site-packages/distributed/core.py", line 736, in send_recv_from_rpc
    comm = yield self.pool.connect(self.addr)
  File "/scratch/cnt0024/hmg2840/albert7a/anaconda3/lib/python3.7/site-packages/tornado/gen.py", line 735, in run
    value = future.result()
  File "/scratch/cnt0024/hmg2840/albert7a/anaconda3/lib/python3.7/site-packages/tornado/gen.py", line 742, in run
    yielded = self.gen.throw(*exc_info)  # type: ignore
  File "/scratch/cnt0024/hmg2840/albert7a/anaconda3/lib/python3.7/site-packages/distributed/core.py", line 864, in connect
    connection_args=self.connection_args,
  File "/scratch/cnt0024/hmg2840/albert7a/anaconda3/lib/python3.7/site-packages/tornado/gen.py", line 735, in run
    value = future.result()
  File "/scratch/cnt0024/hmg2840/albert7a/anaconda3/lib/python3.7/site-packages/tornado/gen.py", line 742, in run
    yielded = self.gen.throw(*exc_info)  # type: ignore
  File "/scratch/cnt0024/hmg2840/albert7a/anaconda3/lib/python3.7/site-packages/distributed/comm/core.py", line 230, in connect
    _raise(error)
  File "/scratch/cnt0024/hmg2840/albert7a/anaconda3/lib/python3.7/site-packages/distributed/comm/core.py", line 207, in _raise
    raise IOError(msg)
OSError: Timed out trying to connect to 'tcp://172.30.100.1:39168' after 10 s: connect() didn't finish in time
distributed.comm.tcp - WARNING - Closing dangling stream in <TCP  local=tcp://172.30.6.158:51908 remote=tcp://172.30.100.1:39168>
distributed.comm.tcp - WARNING - Closing dangling stream in <TCP  local=tcp://172.30.6.158:51858 remote=tcp://172.30.100.1:39168>
distributed.comm.tcp - WARNING - Closing dangling stream in <TCP  local=tcp://172.30.6.158:51856 remote=tcp://172.30.100.1:39168>
distributed.comm.tcp - WARNING - Closing dangling stream in <TCP  local=tcp://172.30.6.158:51890 remote=tcp://172.30.100.1:39168>
distributed.comm.tcp - WARNING - Closing dangling stream in <TCP  local=tcp://172.30.6.158:51880 remote=tcp://172.30.100.1:39168>
distributed.comm.tcp - WARNING - Closing dangling stream in <TCP  local=tcp://172.30.6.158:51982 remote=tcp://172.30.100.1:39168>
distributed.utils_perf - INFO - full garbage collection released 85.99 MB from 797 reference cycles (threshold: 10.00 MB)
distributed.comm.tcp - WARNING - Closing dangling stream in <TCP  local=tcp://172.30.6.158:51876 remote=tcp://172.30.100.1:39168>
distributed.comm.tcp - WARNING - Closing dangling stream in <TCP  local=tcp://172.30.6.158:51976 remote=tcp://172.30.100.1:39168>
distributed.worker - INFO - Stopping worker at tcp://172.30.6.158:33078
distributed.worker - INFO - Stopping worker at tcp://172.30.6.158:35313
distributed.worker - INFO - Stopping worker at tcp://172.30.6.158:36354
distributed.worker - INFO - Stopping worker at tcp://172.30.6.158:36401
distributed.worker - INFO - Stopping worker at tcp://172.30.6.158:33518
distributed.worker - INFO - Stopping worker at tcp://172.30.6.158:34429
distributed.worker - INFO - Stopping worker at tcp://172.30.6.158:34188
/scratch/cnt0024/hmg2840/albert7a/anaconda3/lib/python3.7/site-packages/dask/array/numpy_compat.py:28: RuntimeWarning: invalid value encountered in true_divide
  x = np.divide(x1, x2, out)
distributed.worker - INFO - Stopping worker at tcp://172.30.6.158:32841
distributed.worker - INFO - Stopping worker at tcp://172.30.6.158:36917
distributed.worker - INFO - Stopping worker at tcp://172.30.6.158:36436
distributed.worker - INFO - Stopping worker at tcp://172.30.6.158:39114
distributed.worker - INFO - Stopping worker at tcp://172.30.6.158:35514
distributed.worker - INFO - Stopping worker at tcp://172.30.6.158:40212
distributed.worker - INFO - Stopping worker at tcp://172.30.6.158:38341
distributed.worker - INFO - Stopping worker at tcp://172.30.6.158:35608
distributed.worker - INFO - Stopping worker at tcp://172.30.6.158:39120
distributed.worker - INFO - Stopping worker at tcp://172.30.6.158:40482
distributed.worker - INFO - Stopping worker at tcp://172.30.6.158:43263
distributed.worker - INFO - Stopping worker at tcp://172.30.6.158:39536
distributed.worker - INFO - Stopping worker at tcp://172.30.6.158:41206
distributed.worker - INFO - Stopping worker at tcp://172.30.6.158:43809
distributed.worker - INFO - Stopping worker at tcp://172.30.6.158:42520
distributed.worker - INFO - Stopping worker at tcp://172.30.6.158:43927
distributed.worker - INFO - Stopping worker at tcp://172.30.6.158:43903
distributed.worker - INFO - Stopping worker at tcp://172.30.6.158:45270
distributed.worker - INFO - Stopping worker at tcp://172.30.6.158:44449
distributed.worker - INFO - Stopping worker at tcp://172.30.6.158:44676
distributed.worker - INFO - Stopping worker at tcp://172.30.6.158:46340
distributed.worker - INFO - Connection to scheduler broken.  Reconnecting...
distributed.worker - INFO - -------------------------------------------------
distributed.nanny - INFO - Closing Nanny at 'tcp://172.30.6.158:44800'
distributed.worker - INFO - Connection to scheduler broken.  Reconnecting...
distributed.worker - INFO - -------------------------------------------------
distributed.worker - INFO - Connection to scheduler broken.  Reconnecting...
distributed.worker - INFO - -------------------------------------------------
distributed.worker - INFO - Connection to scheduler broken.  Reconnecting...
distributed.worker - INFO - -------------------------------------------------
distributed.worker - INFO - Connection to scheduler broken.  Reconnecting...
distributed.worker - INFO - -------------------------------------------------
distributed.worker - INFO - Connection to scheduler broken.  Reconnecting...
distributed.worker - INFO - -------------------------------------------------
distributed.worker - INFO - Connection to scheduler broken.  Reconnecting...
distributed.worker - INFO - -------------------------------------------------
distributed.worker - INFO - Connection to scheduler broken.  Reconnecting...
distributed.worker - INFO - -------------------------------------------------
distributed.worker - INFO - Connection to scheduler broken.  Reconnecting...
distributed.worker - INFO - -------------------------------------------------
distributed.worker - INFO - Connection to scheduler broken.  Reconnecting...
distributed.worker - INFO - -------------------------------------------------
distributed.worker - INFO - Connection to scheduler broken.  Reconnecting...
distributed.worker - INFO - -------------------------------------------------
distributed.worker - INFO - Connection to scheduler broken.  Reconnecting...
distributed.worker - INFO - -------------------------------------------------
distributed.worker - INFO - Connection to scheduler broken.  Reconnecting...
distributed.worker - INFO - Connection to scheduler broken.  Reconnecting...
distributed.worker - INFO - -------------------------------------------------
distributed.worker - INFO - Connection to scheduler broken.  Reconnecting...
distributed.worker - INFO - -------------------------------------------------
distributed.worker - INFO - -------------------------------------------------
distributed.worker - INFO - Connection to scheduler broken.  Reconnecting...
distributed.worker - INFO - Connection to scheduler broken.  Reconnecting...
distributed.worker - INFO - -------------------------------------------------
distributed.worker - INFO - -------------------------------------------------
distributed.worker - INFO - Connection to scheduler broken.  Reconnecting...
distributed.worker - INFO - -------------------------------------------------
distributed.worker - INFO - Connection to scheduler broken.  Reconnecting...
distributed.worker - INFO - Connection to scheduler broken.  Reconnecting...
distributed.worker - INFO - -------------------------------------------------
distributed.worker - INFO - -------------------------------------------------
distributed.worker - INFO - Connection to scheduler broken.  Reconnecting...
distributed.worker - INFO - -------------------------------------------------
distributed.nanny - INFO - Closing Nanny at 'tcp://172.30.6.158:38610'
distributed.worker - INFO - Connection to scheduler broken.  Reconnecting...
distributed.worker - INFO - -------------------------------------------------
distributed.nanny - INFO - Closing Nanny at 'tcp://172.30.6.158:43798'
distributed.worker - INFO - Connection to scheduler broken.  Reconnecting...
distributed.worker - INFO - -------------------------------------------------
distributed.nanny - INFO - Closing Nanny at 'tcp://172.30.6.158:46722'
distributed.worker - INFO - Connection to scheduler broken.  Reconnecting...
distributed.nanny - INFO - Closing Nanny at 'tcp://172.30.6.158:36775'
distributed.worker - INFO - -------------------------------------------------
distributed.nanny - INFO - Closing Nanny at 'tcp://172.30.6.158:37505'
distributed.nanny - INFO - Closing Nanny at 'tcp://172.30.6.158:38181'
distributed.worker - INFO - Connection to scheduler broken.  Reconnecting...
distributed.worker - INFO - -------------------------------------------------
distributed.nanny - INFO - Closing Nanny at 'tcp://172.30.6.158:40275'
distributed.worker - INFO - Connection to scheduler broken.  Reconnecting...
distributed.worker - INFO - -------------------------------------------------
distributed.nanny - INFO - Closing Nanny at 'tcp://172.30.6.158:44860'
distributed.nanny - INFO - Closing Nanny at 'tcp://172.30.6.158:38025'
distributed.nanny - INFO - Closing Nanny at 'tcp://172.30.6.158:35237'
distributed.worker - INFO - Connection to scheduler broken.  Reconnecting...
distributed.worker - INFO - Connection to scheduler broken.  Reconnecting...
distributed.worker - INFO - -------------------------------------------------
distributed.worker - INFO - -------------------------------------------------
distributed.nanny - INFO - Closing Nanny at 'tcp://172.30.6.158:40119'
distributed.nanny - INFO - Closing Nanny at 'tcp://172.30.6.158:46145'
distributed.nanny - INFO - Closing Nanny at 'tcp://172.30.6.158:43776'
distributed.nanny - INFO - Closing Nanny at 'tcp://172.30.6.158:40248'
distributed.nanny - INFO - Closing Nanny at 'tcp://172.30.6.158:39324'
distributed.nanny - INFO - Closing Nanny at 'tcp://172.30.6.158:38294'
distributed.nanny - INFO - Closing Nanny at 'tcp://172.30.6.158:34167'
distributed.nanny - INFO - Closing Nanny at 'tcp://172.30.6.158:41327'
distributed.nanny - INFO - Closing Nanny at 'tcp://172.30.6.158:44107'
distributed.nanny - INFO - Closing Nanny at 'tcp://172.30.6.158:44135'
distributed.nanny - INFO - Closing Nanny at 'tcp://172.30.6.158:33563'
distributed.nanny - INFO - Closing Nanny at 'tcp://172.30.6.158:34144'
distributed.nanny - INFO - Closing Nanny at 'tcp://172.30.6.158:39630'
distributed.nanny - INFO - Closing Nanny at 'tcp://172.30.6.158:43913'
distributed.nanny - INFO - Closing Nanny at 'tcp://172.30.6.158:34789'
distributed.nanny - INFO - Closing Nanny at 'tcp://172.30.6.158:43973'
distributed.nanny - INFO - Closing Nanny at 'tcp://172.30.6.158:36124'
distributed.dask_worker - INFO - End worker
/scratch/cnt0024/hmg2840/albert7a/anaconda3/lib/python3.7/site-packages/dask/config.py:168: YAMLLoadWarning: calling yaml.load() without Loader=... is deprecated, as the default Loader is unsafe. Please read https://msg.pyyaml.org/load for full details.
  data = yaml.load(f.read()) or {}
/scratch/cnt0024/hmg2840/albert7a/anaconda3/lib/python3.7/site-packages/distributed/utils.py:136: RuntimeWarning: Couldn't detect a suitable IP address for reaching '8.8.8.8', defaulting to '127.0.0.1': [Errno 101] Network is unreachable
  RuntimeWarning,
